30661829 R ut 100
30676408 R ot 1100
30677490 R rr 700
30677580 A vt S 44.18 700
30678270 R gt 61
30678270 R gt 139
30678568 R vt 50
30679623 A wt S 44.18 100
30683544 R rs 200
30684128 A xt B 44.14 100
30684577 R wt 100
30684846 A yt S 44.16 300
30686813 R ht 200
30688574 R yt 300
30691203 R nl 100
30696218 A zt S 44.18 300
30696577 A au B 44.15 100
30697745 R zt 300
30704521 A bu B 44.04 700
30718190 A cu S 44.17 100
30719580 A du S 44.16 100
30719766 R du 100
30720363 R cu 100
30724876 A eu S 44.17 100
30725246 R eu 100
30726397 R au 100
30727961 R xt 100
30735257 A fu B 44.14 100
30735813 A gu S 44.16 300
30736803 R fu 100
30736893 A hu B 44.09 100
30737085 A iu B 44.09 100
30739585 R gu 300
30741208 R es 100
30741608 A ju B 44.13 100
30745174 R ju 100
30750434 R cs 600
30755219 R jo 100
30762848 A ku S 44.27 100
30771521 R hu 100
30771522 R iu 100
30773239 A lu B 44.12 100
30782070 A mu B 44.12 300
30784685 R po 200
30784764 A nu B 44.01 200
30798238 A ou B 44.04 100
30820683 R mu 300
30841205 R lu 100
30843913 A pu S 44.14 100
30862962 R pu 100
30863347 A qu S 44.14 100
30869373 R or 100
30869399 A ru B 44.07 100
30869416 R ru 100
30871646 R qu 100
30871649 A su S 44.14 100
30871731 A tu S 44.13 100
30871732 R su 100
30885727 A uu B 44.04 800
30886501 A vu B 44.07 100
30886505 R vu 100
30886648 A wu S 44.13 100
30887906 A xu B 44.08 100
30901373 R tu 100
30901374 R wu 100
30901375 R xu 100
30901377 A yu S 44.13 100
30901405 R yu 100
30903077 A zu B 44.08 100
30907182 A av S 44.11 100
30908512 R zu 100
30937443 A bv S 44.22 200
30965397 R ou 100
30965473 A cv B 44.08 100
30969802 R av 100
30974348 A dv B 44.08 100
30974348 A ev S 44.18 100
30979158 A fv S 44.13 100
30979177 R fv 100
30979179 A gv S 44.13 100
30981012 R dv 100
30981013 A hv B 44.04 100
30981013 R ev 100
30981013 A iv S 44.13 100
30981416 R hv 100
30981416 A jv B 44.08 100
30981526 R jv 3
30981998 R gv 100
30985996 R jv 97
30985996 A kv B 44.04 100
30988221 A lv S 44.12 400
30988222 R iv 100
30988222 A mv S 44.12 3
30988223 R lv 400
30989501 A nv S 44.11 100
30989501 R mv 3
30989502 A ov S 44.11 3
30997721 R nv 100
30997742 A pv S 44.12 200
30997796 R pv 200
30998460 A qv S 44.11 100
30998461 R ov 3
30998461 A rv S 44.11 3
31000121 R qv 100
31000651 A sv S 44.10 100
31000652 R rv 3
31000653 A tv S 44.10 3
31001160 R sv 100
31001694 A uv S 44.10 100
31001694 R tv 3
31001695 A vv S 44.10 3
31002191 R uv 100
31002739 A wv S 44.10 100
31002740 R vv 3
31002740 A xv S 44.10 3
31003294 R wv 100
31003860 A yv S 44.10 100
31003861 R xv 3
31003861 A zv S 44.10 3
31004222 R yv 100
31004235 R zv 3
31004235 A aw S 44.18 3
31005978 A bw S 44.11 100
31005979 R aw 3
31005979 A cw S 44.10 3
31013621 R cv 50
31019940 R bw 100
31022501 A dw S 44.11 100
31030267 R dw 100
31033164 R cv 50
31034427 A ew B 44.06 100
31039197 A fw S 44.08 566
31039704 R fw 566
31042874 A gw S 44.08 566
31044102 A hw S 44.16 400
31044102 R cw 3
31044103 A iw S 44.07 3
31044847 R ew 100
31045360 R gw 566
31045361 R iw 3
31045361 A jw S 44.16 3
31049327 A kw B 44.06 100
31049328 R kv 100
31049328 A lw B 44.06 100
31049330 R kw 100
31051162 A mw B 44.03 100
31059422 R lw 100
31059423 A nw B 44.04 100
31068558 R mw 100
31068563 A ow B 44.03 100
31072722 A pw B 44.06 745
31078726 R pw 745
31078729 A qw B 44.06 100
31078853 A rw B 44.07 100
31078854 R nw 100
31078854 A sw B 44.06 100
31078855 R qw 100
31083128 R hw 400
31083188 A tw S 44.11 400
31084326 R sw 100
31084326 A uw B 44.04 100
31084326 R jw 3
31084327 A vw S 44.11 100
31084583 A ww B 44.02 100
31086250 R rw 100
31090717 R ow 100
31090722 A xw B 44.03 100
31092565 A yw S 44.10 100
31092566 R vw 100
31092566 A zw S 44.10 3
31094315 R yw 100
31094317 A ax S 44.10 100
31094319 R zw 3
31094319 A bx S 44.10 3
31095325 R ax 100
31106672 A cx B 44.04 500
31116629 R tw 400
31122297 R cx 500
31124633 A dx B 44.04 100
31124816 A ex B 44.04 100
31124816 R uw 100
31124817 A fx B 44.04 100
31124819 A gx B 44.05 100
31131407 A hx B 44.05 100
31131408 R fx 100
31131408 A ix B 44.05 100
31131409 R gx 100
31137936 A jx B 44.04 500
31140881 R dx 100
31140881 R ex 100
31140881 R hx 100
31145056 R ix 100
31145056 A kx B 44.04 100
31145058 A lx S 44.09 100
31145059 R bx 3
31145059 A mx S 44.09 100
31145115 A nx S 45.36 1000
31149917 A ox B 44.06 100
31154516 R ox 100
31154517 R lx 100
31154517 R kx 100
31154517 A px B 44.03 100
31160562 A qx B 44.06 900
31160563 R px 100
31160563 A rx B 44.04 100
31160590 R xw 100
31160596 A sx B 44.03 100
31161615 R rx 100
31161616 A tx B 44.06 100
31167004 R qx 900
31171613 R tx 100
31171613 A ux S 44.05 290
31171613 R ux 290
31171614 A vx B 44.03 100
31171625 R vx 100
31172140 A wx B 44.05 100
31173104 A xx B 44.05 100
31175301 A yx S 44.08 100
31175302 R mx 100
31175302 A zx S 44.08 100
31175315 R xx 100
31175316 A ay B 44.04 100
31175610 R sx 100
31175611 R wx 100
31175615 A by B 44.03 100
31180640 R yx 100
31181517 A cy S 44.08 100
31186710 R cy 100
31187493 A dy B 44.05 100
31190816 R dy 100
31191897 A ey B 44.05 100
31196687 R by 100
31196688 R ay 100
31196688 A fy B 44.05 100
31196689 R ey 100
31196693 A gy B 44.05 100
31197839 A hy S 44.08 100
31198548 R hy 100
31198549 R fy 100
31198549 A iy B 44.06 100
31199106 R iy 100
31199106 A jy B 44.04 100
31199605 R jy 100
31199606 A ky B 44.06 100
31200216 R ky 100
31200216 A ly B 44.04 100
31202156 R ly 100
31202156 A my B 44.06 100
31202165 R zx 100
31202166 A ny S 44.18 3
31205910 A oy B 44.06 100
31208286 A py S 48.60 500
31210554 R oy 100
31211011 A qy B 42.12 15
31211177 A ry B 44.06 100
31212886 R ry 100
31217900 A sy B 44.07 100
31223385 R sy 100
31232773 R uu 800
31235907 A ty B 44.06 800
31235907 R my 100
31235908 A uy B 44.07 100
31257516 R uy 100
31257516 A vy B 44.06 100
31263238 R ty 100
31273185 R vy 100
31273185 A wy B 44.07 100
31274653 A xy B 44.07 100
31275566 R xy 100
31276325 R wy 100
31276325 A yy B 44.06 100
31277891 A zy S 44.08 1500
31277892 R yy 100
31277892 R ny 3
31277893 A az B 44.04 100
31277893 A bz S 44.07 3
31282571 R gy 100
31282702 R bz 3
31282702 R zy 1342
31282703 A cz S 44.18 3
31283212 R zy 100
31283919 R zy 58
31283920 R az 100
31283920 A dz B 44.07 100
31284554 A ez B 44.07 100
31285701 R vg 15
31288972 A fz B 44.07 50
31294210 R ez 100
31303042 R jx 500
31304640 A gz B 44.06 100
31314121 A hz B 43.32 500
31320766 A iz B 44.07 200
31320767 R dz 100
31320767 A jz B 44.07 100
31320769 R iz 200
31345152 A kz B 44.07 200
31362067 A lz S 44.10 100
31370746 R lz 100
31374426 A mz B 44.09 20
31375176 R mz 20
31381630 A nz B 44.07 100
31382908 R nz 100
31393278 A oz S 44.28 100
31395589 A pz S 44.10 100
31404832 R cz 3
31404833 A qz S 44.09 100
31404834 R jz 100
31404834 A rz B 44.07 100
31411759 R pz 100
31411760 R rz 100
31411760 A sz B 44.07 100
31411761 R qz 100
31411761 A tz S 44.18 100
31467900 A uz B 44.01 100
31468318 A vz S 44.17 100
31468319 R tz 100
31468319 A wz S 44.17 100
31471235 R vz 100
31471265 A xz S 44.17 100
31473126 A yz S 44.17 100
31473126 R xz 100
31474555 R yz 100
31474585 A zz S 44.17 100
31504806 R zz 100
31504835 A aab S 44.18 100
31508052 A bab B 44.09 100
31508066 A cab B 44.02 100
31508066 R uz 100
31516797 R bab 100
31516826 A dab B 44.03 100
31516826 R cab 100
31517605 R aab 100
31517635 A eab S 44.30 100
31524816 R dab 100
31524846 A fab B 44.02 100
31525007 A gab B 44.07 100
31525008 R sz 100
31525008 A hab B 44.07 100
31525010 R gab 100
31525036 R fab 100
31525066 A iab B 44.01 100
31525265 R iab 100
31525295 A jab B 44.01 100
31525555 R jab 100
31525585 A kab B 43.97 100
31525757 R hab 100
31526297 R kz 200
31528346 A lab S 44.20 100
31528346 R eab 100
31530904 A mab B 44.07 100
31530945 A nab B 43.99 100
31530946 R kab 100
31530956 A oab S 44.19 100
31530956 R lab 100
31533430 A pab B 44.07 100
31533466 R nab 100
31533496 A qab B 43.97 100
31534586 A rab S 44.19 100
31534586 R oab 100
31535815 R rab 100
31535845 A sab S 44.19 100
31536315 A tab S 44.12 100
31536905 R tab 100
31537765 A uab S 44.19 100
31537766 R sab 100
31538332 A vab S 44.12 100
31538406 A wab S 44.19 100
31538406 R uab 100
31538407 R wz 100
31538407 A xab S 44.12 100
31538760 R vab 100
31539171 A yab S 44.12 100
31539625 A zab S 44.19 100
31539625 R wab 100
31539626 R xab 100
31539626 A abb S 44.12 100
31539655 A bbb S 44.19 100
31539656 R zab 100
31540158 R yab 100
31540166 R abb 100
31540166 A cbb S 44.18 100
31540205 R bbb 100
31540234 A dbb S 44.26 100
31540529 A ebb S 44.14 100
31540755 A fbb S 44.21 100
31540756 R dbb 100
31540756 R cbb 100
31540756 A gbb S 44.14 100
31540786 A hbb S 44.21 100
31540786 R fbb 100
31540838 R pab 100
31540896 A ibb B 43.99 100
31540896 R qab 100
31541124 A jbb S 44.14 100
31541124 R gbb 100
31541125 A kbb S 44.14 100
31541286 A lbb S 44.21 100
31541286 R hbb 100
31541583 R ebb 100
31541584 R jbb 100
31541586 A mbb S 44.21 100
31541586 R lbb 100
31541986 A nbb S 44.13 100
31541987 R kbb 100
31541987 A obb S 44.13 100
31542126 A pbb S 44.20 100
31542126 R mbb 100
31542157 A qbb S 44.20 100
31542157 R pbb 100
31542334 R nbb 100
31542666 A rbb S 44.13 100
31542667 R obb 100
31542667 A sbb S 44.13 100
31542766 A tbb S 44.20 100
31542766 R qbb 100
31542796 A ubb S 44.20 100
31542796 R tbb 100
31542989 R rbb 100
31543281 A vbb S 44.13 100
31543281 R sbb 100
31543282 A wbb S 44.12 100
31543336 A xbb S 44.19 100
31543336 R ubb 100
31543367 A ybb S 44.19 100
31543367 R xbb 100
31543558 R vbb 100
31543803 A zbb S 44.12 100
31543804 R wbb 100
31543804 A acb S 44.12 100
31543886 A bcb S 44.19 100
31543886 R ybb 100
31543917 A ccb S 44.19 100
31543917 R bcb 100
31544149 A dcb B 44.07 100
31544185 R ibb 100
31544202 R zbb 100
31544215 A ecb B 43.97 100
31544305 A fcb S 44.12 100
31544356 A gcb S 44.19 100
31544356 R ccb 100
31544356 R acb 100
31544357 A hcb S 44.12 100
31544387 A icb S 44.19 100
31544387 R gcb 100
31544549 R fcb 100
31544556 R hcb 100
31544556 A jcb S 44.18 100
31544595 R icb 100
31544625 A kcb S 44.26 100
31544761 A lcb S 44.14 100
31544806 A mcb S 44.21 100
31544806 R kcb 100
31544806 R jcb 100
31544806 A ncb S 44.14 100
31544838 A ocb S 44.21 100
31544838 R mcb 100
31544998 R lcb 100
31545208 A pcb S 44.14 100
31545209 R ncb 100
31545209 A qcb S 44.14 100
31545255 A rcb S 44.21 100
31545256 R ocb 100
31545286 A scb S 44.21 100
31545286 R rcb 100
31545429 R pcb 100
31545650 A tcb S 44.14 100
31545651 R qcb 100
31545651 A ucb S 44.13 100
31545695 A vcb S 44.21 100
31545696 R scb 100
31545726 A wcb S 44.21 100
31545727 R vcb 100
31545893 R tcb 100
31546144 A xcb S 44.13 100
31546145 R ucb 100
31546145 A ycb S 44.13 100
31546186 A zcb S 44.21 100
31546186 R wcb 100
31546217 A adb S 44.20 100
31546217 R zcb 100
31546397 R xcb 100
31546616 A bdb S 44.13 100
31546617 R ycb 100
31546617 A cdb S 44.13 100
31546656 A ddb S 44.20 100
31546656 R adb 100
31546686 A edb S 44.20 100
31546687 R ddb 100
31546857 R bdb 100
31546903 A fdb S 44.14 100
31547088 A gdb S 44.13 100
31547135 A hdb S 44.20 100
31547136 R edb 100
31547136 R cdb 100
31547136 A idb S 44.13 100
31547166 A jdb S 44.20 100
31547166 R hdb 100
31547341 R gdb 100
31547578 A kdb S 44.13 100
31547828 R kdb 100
31548064 A ldb S 44.13 100
31548136 A mdb B 44.00 100
31548136 R ecb 100
31548155 A ndb S 44.20 100
31548156 R jdb 100
31548156 R idb 100
31548156 A odb S 44.13 100
31548193 A pdb S 44.20 100
31548193 R ndb 100
31548340 R ldb 100
31548553 A qdb S 44.12 100
31548596 A rdb S 44.19 100
31548596 R pdb 100
31548596 R odb 100
31548597 A sdb S 44.12 100
31548626 A tdb S 44.19 100
31548627 R rdb 100
31548780 R qdb 100
31548986 A udb S 44.12 100
31549026 A vdb S 44.19 100
31549026 R tdb 100
31549027 R sdb 100
31549027 A wdb S 44.12 100
31549036 R mdb 100
31549056 A xdb S 44.19 100
31549057 R vdb 100
31549083 A ydb B 43.99 100
31549212 R udb 100
31549416 A zdb S 44.12 100
31549895 A aeb S 44.19 100
31549896 R xdb 100
31549896 R wdb 100
31549896 A beb S 44.12 100
31549976 A ceb S 44.19 100
31549976 R aeb 100
31550049 A deb S 44.12 100
31550050 R beb 100
31550050 A eeb S 44.11 100
31550106 A feb S 44.19 100
31550106 R ceb 100
31550136 A geb S 44.19 100
31550137 R feb 100
31550264 A heb S 44.11 100
31550306 A ieb S 44.18 100
31550306 R geb 100
31550336 A jeb S 44.18 100
31550336 R ieb 100
31550474 A keb S 44.11 100
31550475 R eeb 100
31550475 A leb S 44.11 100
31550515 A meb S 44.18 100
31550516 R jeb 100
31550546 A neb S 44.18 100
31550546 R meb 100
31550644 A oeb S 44.11 100
31550818 R zdb 100
31550819 R deb 100
31550820 R leb 100
31550820 A peb S 44.11 100
31550820 R heb 100
31550820 R keb 100
31550821 R oeb 100
31551356 A qeb S 44.10 100
31551357 R peb 100
31551357 A reb S 44.10 100
31551366 A seb S 44.18 100
31551366 R neb 100
31551397 A teb S 44.18 100
31551397 R seb 100
31551511 A ueb S 44.10 100
31551681 A veb S 44.10 100
31551682 R reb 100
31551682 A web S 44.10 100
31551831 A xeb S 44.10 97
31551833 A yeb S 44.10 100
31551833 R web 100
31551834 A zeb S 44.10 100
31552026 A afb S 44.17 100
31552026 R teb 100
31552032 R qeb 100
31552033 R ueb 100
31552033 R veb 100
31552033 R yeb 100
31552034 R xeb 97
31552046 R zeb 100
31552046 A bfb S 44.14 100
31552056 A cfb S 44.17 100
31552056 R afb 100
31552088 R cfb 100
31552117 A dfb S 44.24 100
31552767 A efb S 44.14 100
31553026 A ffb S 44.21 100
31553026 R dfb 100
31553027 R bfb 100
31553027 A gfb S 44.14 100
31553056 A hfb S 44.21 100
31553057 R ffb 100
31553129 A ifb S 44.14 100
31553130 R gfb 100
31553130 A jfb S 44.13 100
31553287 A kfb S 44.13 100
31553455 A lfb S 44.13 100
31553455 R jfb 100
31553456 A mfb S 44.13 100
31553704 R efb 100
31553705 R ifb 100
31553705 R kfb 100
31553705 R lfb 100
31554079 A nfb S 44.13 100
31554126 A ofb S 44.20 100
31554126 R hfb 100
31554126 R mfb 100
31554127 A pfb S 44.13 100
31554156 A qfb S 44.20 100
31554156 R ofb 100
31554256 A rfb S 44.13 100
31554257 R pfb 100
31554257 A sfb S 44.13 100
31554446 A tfb S 44.13 100
31554617 A ufb S 44.12 100
31554618 R sfb 100
31554618 A vfb S 44.12 100
31554794 A wfb S 44.12 100
31555016 R nfb 100
31555017 R rfb 100
31555017 R tfb 100
31555018 R vfb 100
31555018 A xfb S 44.12 100
31555018 R ufb 100
31555019 R wfb 100
31555026 A yfb S 44.20 100
31555026 R qfb 100
31555057 A zfb S 44.19 100
31555057 R yfb 100
31555375 A agb S 44.12 100
31555375 R xfb 100
31555376 A bgb S 44.12 100
31555562 A cgb S 44.12 100
31556026 A dgb S 44.19 100
31556026 R zfb 100
31556916 R agb 100
31556916 R cgb 100
31556917 R bgb 100
31556917 A egb S 44.12 100
31556955 R dgb 100
31556985 A fgb S 44.19 100
31557174 A ggb S 44.11 100
31557175 R egb 100
31557175 A hgb S 44.11 100
31557216 A igb S 44.19 100
31557216 R fgb 100
31557256 A jgb S 44.19 100
31557256 R igb 100
31557400 A kgb S 44.11 100
31558025 A lgb S 44.18 100
31558026 R jgb 100
31558056 A mgb S 44.18 100
31558057 R lgb 100
31558102 A ngb S 44.11 100
31558103 R hgb 100
31558103 A ogb S 44.11 100
31558662 A pgb S 44.11 100
31559026 A qgb S 44.18 100
31559026 R mgb 100
31559056 A rgb S 44.18 100
31559057 R qgb 100
31559358 R ggb 100
31559359 R kgb 100
31559359 R ogb 100
31559359 A sgb S 44.11 100
31559359 R ngb 100
31559360 R pgb 100
31559366 R sgb 100
31559366 A tgb S 44.14 100
31559406 R rgb 100
31559435 A ugb S 44.25 100
31559875 R ydb 100
31559904 A vgb B 43.97 100
31562876 A wgb S 44.18 100
31562876 R ugb 100
31562906 A xgb S 44.18 100
31562906 R wgb 100
31565814 R dcb 100
31587347 A ygb S 44.13 100
31587739 A zgb S 44.13 100
31587740 R tgb 100
31587740 A ahb S 44.13 100
31587964 A bhb S 44.13 100
31588130 A chb S 44.13 100
31588444 A dhb S 44.13 100
31588620 A ehb S 44.13 100
31588787 A fhb S 44.13 100
31588970 A ghb S 44.13 100
31589154 A hhb S 44.13 100
31589524 A ihb S 44.13 100
31589755 R ygb 100
31589755 R zgb 100
31589756 R bhb 100
31589756 R chb 100
31589756 R dhb 100
31589757 R ehb 100
31589757 R fhb 100
31589757 R ghb 100
31589758 R hhb 100
31589758 R ihb 100
31590186 A jhb S 44.13 100
31590256 A khb B 43.99 100
31590256 R vgb 100
31590345 R mab 100
31590354 A lhb S 44.13 100
31590399 R fz 50
31590399 R ty 700
31590415 R khb 100
31590445 A mhb B 43.97 100
31590722 A nhb S 44.13 100
31591068 A ohb S 44.13 100
31591418 A phb S 44.13 100
31591786 A qhb S 44.13 100
31592111 R jhb 100
31592112 R lhb 100
31592113 R nhb 100
31592113 R ohb 100
31592113 R phb 100
31592114 R qhb 100
31592498 A rhb S 44.13 100
31592684 A shb S 44.13 100
31593070 A thb S 44.13 100
31593397 A uhb S 44.13 100
31593484 A vhb S 44.13 100
31593689 A whb S 44.13 100
31593905 A xhb S 44.13 100
31594113 A yhb S 44.13 100
31594348 A zhb S 44.13 100
31594386 A aib B 43.98 100
31594386 R mhb 100
31594458 R rhb 100
31594458 R thb 100
31594458 R shb 100
31594458 R uhb 100
31594459 R whb 100
31594459 R vhb 100
31594460 R xhb 100
31594460 R yhb 100
31594460 R zhb 100
31594745 A bib S 44.13 100
31594953 A cib S 44.13 100
31595137 A dib S 44.13 100
31595313 R gz 100
31595337 A eib S 44.13 100
31595356 R aib 100
31595386 A fib B 43.97 100
31595521 A gib S 44.13 100
31595675 R fib 100
31595705 A hib B 43.97 100
31595716 A iib S 44.13 100
31595781 R xm 100
31595781 R bu 700
31595825 R hib 100
31595855 A jib B 43.94 100
31596229 R ww 100
31599414 R nu 100
31600117 A kib S 44.11 100
31600118 R ahb 100
31600118 A lib S 44.11 100
31600176 A mib S 44.18 100
31600176 R xgb 100
31600206 A nib S 44.18 100
31600207 R mib 100
31602088 A oib S 44.11 100
31602226 A pib S 44.18 100
31602226 R nib 100
31602869 A qib S 44.10 100
31602870 R lib 100
31602870 A rib S 44.10 100
31602936 A sib S 44.18 100
31602936 R pib 100
31603372 A tib S 44.10 3
31607766 A uib S 44.15 100
31607766 R sib 100
31608432 R bib 100
31608432 R cib 100
31608435 R dib 100
31608435 R eib 100
31608435 R gib 100
31608436 R iib 100
31608436 R kib 100
31608436 R oib 100
31608437 R qib 100
31608437 R tib 3
31608476 A vib S 44.15 100
31608477 R uib 100
31609144 A wib S 44.08 100
31609144 R rib 100
31609145 A xib S 44.08 100
31609166 A yib S 44.15 100
31609166 R vib 100
31609196 A zib S 44.15 100
31609196 R yib 100
31609638 A ajb S 44.08 100
31609850 R wib 100
31609851 R ajb 100
31609851 R xib 100
31609851 A bjb S 44.08 100
31610237 A cjb S 44.07 100
31610237 R bjb 100
31610238 A djb S 44.07 100
31610295 A ejb S 44.14 100
31610296 R zib 100
31610326 A fjb S 44.14 100
31610327 R ejb 100
31610639 A gjb S 44.07 100
31610676 A hjb S 44.14 100
31610676 R fjb 100
31610676 R djb 100
31610677 A ijb S 44.07 100
31610706 A jjb S 44.14 100
31610707 R hjb 100
31610869 A kjb S 44.07 100
31610916 A ljb S 44.14 100
31610916 R jjb 100
31610917 R ijb 100
31610917 A mjb S 44.07 100
31610947 A njb S 44.14 100
31610947 R ljb 100
31611068 A ojb S 44.07 100
31611069 R mjb 100
31611069 A pjb S 44.06 100
31611146 A qjb S 44.14 100
31611146 R njb 100
31611246 A rjb S 44.14 100
31611247 R qjb 100
31611269 A sjb S 44.06 100
31611326 A tjb S 44.13 100
31611326 R rjb 100
31611591 R cjb 100
31611592 R gjb 100
31611592 R kjb 100
31611593 R ojb 100
31611593 R pjb 100
31611593 A ujb S 44.06 100
31611593 R sjb 100
31611606 R ujb 100
31611606 A vjb S 44.13 100
31611635 R tjb 100
31611665 A wjb S 44.21 100
31612167 A xjb S 44.13 100
31612168 R vjb 100
31612168 A yjb S 44.13 100
31612226 A zjb S 44.20 100
31612226 R wjb 100
31612257 A akb S 44.20 100
31612257 R zjb 100
31612356 A bkb S 44.13 100
31612416 A ckb S 44.20 100
31612416 R akb 100
31612447 A dkb S 44.20 100
31612447 R ckb 100
31612556 A ekb S 44.12 100
31612557 R yjb 100
31612557 A fkb S 44.12 100
31612626 A gkb S 44.20 100
31612626 R dkb 100
31612676 A hkb S 44.19 100
31612676 R gkb 100
31612772 A ikb S 44.12 100
31612816 A jkb S 44.19 100
31612816 R hkb 100
31613190 R xjb 100
31613190 R bkb 100
31613191 R fkb 100
31613191 R ekb 100
31613191 A kkb S 44.12 100
31613191 R ikb 100
31613226 R jkb 100
31613255 A lkb S 44.19 100
31614737 A mkb S 44.12 100
31614738 R kkb 100
31614738 A nkb S 44.12 100
31614916 A okb S 44.12 100
31615099 A pkb S 44.11 100
31615100 R nkb 100
31615100 A qkb S 44.11 100
31615216 A rkb S 44.19 100
31615216 R lkb 100
31615397 A skb S 44.11 100
31615435 R rkb 100
31615465 A tkb S 44.19 100
31621449 A ukb S 44.10 100
31621450 R qkb 100
31621451 A vkb S 44.10 100
31621485 A wkb S 44.18 100
31621485 R tkb 100
31621495 R wkb 100
31621525 A xkb S 44.18 100
31621526 A ykb S 44.18 100
31621526 R xkb 100
31621694 R ukb 100
31622705 A zkb S 44.17 100
31622706 R ykb 100
31622736 A alb S 44.17 100
31622736 R zkb 100
31623077 A blb S 44.10 100
31623078 R vkb 100
31623078 A clb S 44.09 100
31623465 A dlb S 44.16 100
31623465 R alb 100
31623805 A elb S 44.09 73
31623805 A flb S 44.09 30
31623806 R clb 100
31623806 A glb S 44.09 100
31623886 A hlb S 44.16 100
31623886 R dlb 100
31640866 R mkb 100
31640868 R okb 100
31640869 R pkb 100
31640869 R skb 100
31640869 R blb 100
31640870 R elb 73
31640870 R flb 30
31642725 A ilb S 44.16 100
31642725 R hlb 100
31642993 A jlb S 44.09 100
31642994 R glb 100
31642994 A klb S 44.08 100
31643076 A llb S 44.16 100
31643077 R ilb 100
31643326 A mlb S 44.16 100
31643326 R llb 100
31643386 A nlb S 44.15 100
31643386 R mlb 100
31643678 A olb S 44.08 100
31644026 A plb S 44.15 100
31644026 R nlb 100
31644027 R klb 100
31644027 A qlb S 44.08 100
31644058 A rlb S 44.15 100
31644058 R plb 100
31644335 A slb S 44.08 97
31644336 A tlb S 44.08 100
31652573 R jlb 100
31652574 R qlb 100
31652575 A ulb S 44.08 100
31652575 R olb 100
31652575 R tlb 100
31652575 R slb 97
31664806 A vlb B 43.97 100
31664806 R jib 100
31665005 R vlb 100
31665035 A wlb B 43.94 100
31668921 A xlb S 44.03 100
31669043 R xlb 100
31689646 A ylb B 43.95 100
31689646 R wlb 100
31692548 A zlb B 44.04 1000
31692590 A amb B 44.04 100
31693019 R amb 100
31695021 A bmb B 44.04 100
31695086 A cmb B 43.97 100
31695086 R ylb 100
31695096 R zlb 1000
31695338 R bmb 100
31695375 R cmb 100
31695405 A dmb B 43.95 100
31695965 A emb B 44.04 100
31696006 A fmb B 43.97 100
31696006 R dmb 100
31696281 R emb 100
31696315 R fmb 100
31696345 A gmb B 43.95 100
31696736 A hmb B 44.04 100
31696796 A imb B 43.97 100
31696796 R gmb 100
31696866 R ulb 100
31696866 A jmb S 44.14 100
31696905 R rlb 100
31696935 A kmb S 44.22 100
31697033 R hmb 100
31697076 R imb 100
31697106 A lmb B 43.95 100
31697896 A mmb S 44.16 100
31697896 R kmb 100
31698069 A nmb S 44.16 100
31698069 R mmb 100
31698508 A omb S 44.08 100
31698566 A pmb S 44.16 100
31698566 R nmb 100
31698567 R jmb 100
31698567 A qmb S 44.08 100
31698597 A rmb S 44.15 100
31698597 R pmb 100
31698873 R omb 100
31699148 A smb S 44.08 100
31699206 A tmb S 44.15 100
31699206 R rmb 100
31699207 R qmb 100
31699207 A umb S 44.08 100
31699237 A vmb S 44.15 100
31699237 R tmb 100
31699433 R smb 100
31699696 A wmb S 44.08 100
31699980 R wmb 100
31700220 A xmb S 44.08 100
31700266 A ymb S 44.15 100
31700266 R vmb 100
31700267 R umb 100
31700267 A zmb S 44.08 100
31700297 A anb S 44.15 100
31700297 R ymb 100
31700498 R xmb 100
31700751 A bnb S 44.07 100
31700795 A cnb S 44.15 100
31700796 R anb 100
31700796 R zmb 100
31700796 A dnb S 44.07 100
31700827 A enb S 44.15 100
31700827 R cnb 100
31701018 R bnb 100
31701268 A fnb S 44.07 100
31701316 A gnb S 44.14 100
31701316 R enb 100
31701316 R dnb 100
31701317 A hnb S 44.07 100
31701347 A inb S 44.14 100
31701347 R gnb 100
31701529 R fnb 100
31701536 R hnb 100
31701536 A jnb S 44.14 100
31701576 R inb 100
31701606 A knb S 44.21 100
31701790 A lnb S 44.09 100
31701906 A mnb S 44.16 100
31701906 R knb 100
31701907 R jnb 100
31701907 A nnb S 44.09 100
31701937 A onb S 44.16 100
31701937 R mnb 100
31702065 R lnb 100
31702346 A pnb S 44.16 100
31702347 R onb 100
31702383 A qnb S 44.08 100
31702383 R nnb 100
31702384 A rnb S 44.08 100
31702466 A snb S 44.16 100
31702466 R pnb 100
31702560 R qnb 100
31702812 A tnb S 44.08 100
31702813 R rnb 100
31702813 A unb S 44.08 100
31702866 A vnb S 44.15 100
31702866 R snb 100
31702897 A wnb S 44.15 100
31702897 R vnb 100
31703092 R tnb 100
31703389 A xnb S 44.08 100
31703390 R unb 100
31703390 A ynb S 44.08 100
31703396 A znb S 44.15 100
31703396 R wnb 100
31703466 A aob S 44.15 100
31703466 R znb 100
31703600 R xnb 100
31703862 A bob S 44.08 100
31703863 R ynb 100
31703863 A cob S 44.08 100
31703916 A dob S 44.15 100
31703916 R aob 100
31703948 A eob S 44.15 100
31703949 R dob 100
31704129 R bob 100
31704403 A fob S 44.07 100
31704404 R cob 100
31704404 A gob S 44.07 100
31704446 A hob S 44.15 100
31704446 R eob 100
31704476 A iob S 44.15 100
31704477 R hob 100
31704656 R fob 100
31704892 A job S 44.07 100
31704893 R gob 100
31704893 A kob S 44.07 100
31704936 A lob S 44.14 100
31704936 R iob 100
31704966 A mob S 44.14 100
31704967 R lob 100
31705152 R job 100
31705155 R kob 100
31705155 A nob S 44.14 100
31705195 R mob 100
31705225 A oob S 44.21 100
31705421 A pob S 44.09 100
31705421 R nob 100
31705421 A qob S 44.09 100
31705465 A rob S 44.16 100
31705466 R oob 100
31705496 A sob S 44.16 100
31705496 R rob 100
31705672 R pob 100
31705934 A tob S 44.08 100
31705976 A uob S 44.16 100
31705976 R sob 100
31705977 R qob 100
31705977 A vob S 44.08 100
31706007 A wob S 44.16 100
31706007 R uob 100
31706192 R tob 100
31706451 A xob S 44.08 100
31706496 A yob S 44.15 100
31706496 R wob 100
31706497 R vob 100
31706497 A zob S 44.08 100
31706526 A apb S 44.15 100
31706527 R yob 100
31706728 R xob 100
31706987 A bpb S 44.08 100
31707068 A cpb S 44.15 100
31707068 R apb 100
31707069 R zob 100
31707069 A dpb S 44.08 100
31707145 A epb S 44.15 100
31707146 R cpb 100
31707417 R bpb 100
31707551 A fpb S 44.08 100
31707596 A gpb S 44.15 100
31707596 R epb 100
31707597 R dpb 100
31707597 A hpb S 44.07 100
31707627 A ipb S 44.15 100
31707627 R gpb 100
31707810 R fpb 100
31708059 A jpb S 44.07 100
31708106 A kpb S 44.15 100
31708106 R ipb 100
31708107 R hpb 100
31708107 A lpb S 44.07 100
31708162 A mpb S 44.14 100
31708162 R kpb 100
31708320 R jpb 100
31708327 R lpb 100
31708327 A npb S 44.14 100
31708365 R mpb 100
31708395 A opb S 44.22 100
31708555 A ppb S 44.09 100
31708606 A qpb S 44.16 100
31708606 R opb 100
31708607 R npb 100
31708607 A rpb S 44.09 100
31708637 A spb S 44.16 100
31708637 R qpb 100
31710319 R ppb 100
31711003 A tpb S 44.08 100
31711004 R rpb 100
31711004 A upb S 44.08 100
31711156 A vpb S 44.15 100
31711156 R spb 100
31711631 R tpb 100
31711665 R vpb 100
31711695 A wpb S 44.16 100
31711970 A xpb S 44.08 100
31711971 R upb 100
31711971 A ypb S 44.08 100
31712068 A zpb S 44.15 100
31712068 R wpb 100
31712124 A aqb S 44.15 100
31712125 R zpb 100
31712399 R xpb 100
31712730 A bqb S 44.08 100
31712731 R ypb 100
31712731 A cqb S 44.07 100
31712815 A dqb S 44.15 100
31712815 R aqb 100
31712847 A eqb S 44.15 100
31712847 R dqb 100
31713110 R bqb 100
31713434 A fqb S 44.07 100
31713435 R cqb 100
31713435 A gqb S 44.07 100
31713495 A hqb S 44.14 100
31713496 R eqb 100
31713526 A iqb S 44.14 100
31713526 R hqb 100
31713799 R fqb 100
31713815 R gqb 100
31713816 A jqb S 44.14 100
31713845 R iqb 100
31713875 A kqb S 44.22 100
31714131 A lqb S 44.09 100
31714132 R jqb 100
31714132 A mqb S 44.09 100
31714186 A nqb S 44.16 100
31714186 R kqb 100
31714216 A oqb S 44.16 100
31714216 R nqb 100
31714494 R lqb 100
31714802 A pqb S 44.08 100
31714855 A qqb S 44.16 100
31714856 R oqb 100
31714856 R mqb 100
31714856 A rqb S 44.08 100
31714886 A sqb S 44.15 100
31714886 R qqb 100
31715143 R pqb 100
31715994 A tqb S 44.08 100
31716067 A uqb S 44.15 100
31716067 R sqb 100
31716068 R rqb 100
31716068 A vqb S 44.08 100
31716098 A wqb S 44.15 100
31716098 R uqb 100
31720865 A xqb S 44.11 100
31720866 R wqb 100
31721116 R xqb 100
31721145 A yqb S 44.15 100
31721245 A zqb S 44.11 100
31721246 R yqb 100
31721426 A arb S 44.11 100
31721426 R zqb 100
31722375 R lmb 100
31722405 A brb B 43.94 100
31723655 R brb 100
31723685 A crb B 43.91 100
31724505 R nu 100
31725610 A drb S 44.04 100
31725655 A erb S 44.11 100
31725655 R arb 100
31725656 R vqb 100
31725656 A frb S 44.04 100
31725685 A grb S 44.11 100
31725686 R erb 100
31725800 A hrb S 44.04 97
31725801 A irb S 44.04 100
31725975 A jrb S 44.03 100
31725976 R frb 100
31725977 A krb S 44.03 100
31726016 A lrb S 44.11 100
31726016 R grb 100
31726046 A mrb S 44.10 100
31726047 R lrb 100
31726176 A nrb S 44.03 100
31726368 A orb S 44.03 100
31726368 R krb 100
31726369 A prb S 44.03 100
31726416 A qrb S 44.10 100
31726416 R mrb 100
31726648 A rrb S 44.03 100
31726806 A srb S 44.10 100
31726807 R qrb 100
31726837 A trb S 44.10 100
31726837 R srb 100
31727048 A urb S 44.02 100
31727049 R prb 100
31727049 A vrb S 44.02 100
31727075 A wrb S 44.10 100
31727076 R trb 100
31727287 A xrb S 44.02 100
31727335 A yrb S 44.09 100
31727336 R wrb 100
31727366 A zrb S 44.09 100
31727366 R yrb 100
31727503 A asb S 44.02 100
31727504 R vrb 100
31727504 A bsb S 44.02 100
31727546 A csb S 44.09 100
31727546 R zrb 100
31727738 R tqb 100
31727740 R drb 100
31727740 R irb 100
31727740 R hrb 97
31727741 R jrb 100
31727741 R nrb 100
31727741 R orb 100
31727742 R rrb 100
31727745 R urb 100
31727746 R xrb 100
31727746 R asb 100
31727785 R csb 100
31727815 A dsb S 44.09 100
31729000 A esb S 44.02 100
31729057 A fsb S 44.09 100
31729057 R dsb 100
31729058 R bsb 100
31729058 A gsb S 44.02 100
31729087 A hsb S 44.09 100
31729087 R fsb 100
31729271 A isb S 44.01 100
31729272 R gsb 100
31729272 A jsb S 44.01 100
31729345 A ksb S 44.09 100
31729346 R hsb 100
31729396 A lsb S 44.08 100
31729396 R ksb 100
31729543 A msb S 44.01 100
31729606 A nsb S 44.08 100
31729606 R lsb 100
31729607 R jsb 100
31729607 A osb S 44.01 100
31729807 A psb S 44.01 100
31730072 R esb 100
31730072 R isb 100
31730072 R msb 100
31730072 R osb 100
31730073 A qsb S 44.01 100
31730073 R psb 100
31730076 R qsb 100
31730076 A rsb S 44.08 100
31730105 R nsb 100
31730135 A ssb S 44.11 100
31730396 A tsb S 44.03 100
31730396 R rsb 100
31730396 A usb S 44.02 100
31730415 R crb 100
31730445 A vsb B 43.90 100
31730544 A wsb S 44.02 100
31730586 A xsb S 44.10 100
31730586 R ssb 100
31730587 R usb 100
31730587 A ysb S 44.02 100
31730626 A zsb S 44.09 100
31730626 R xsb 100
31730816 A atb S 44.05 100
31730816 R zsb 100
31730816 R atb 100
31730847 A btb S 44.09 100
31730899 R wsb 100
31730934 R tsb 100
31731026 A ctb S 44.05 100
31731026 R btb 100
31731035 R ctb 100
31731065 A dtb S 44.09 100
31731239 A etb S 44.02 100
31731240 R ysb 100
31731240 A ftb S 44.02 100
31731246 A gtb S 44.05 100
31731246 R dtb 100
31731265 R gtb 100
31731295 A htb S 44.09 100
31731356 A itb S 44.09 100
31731356 R htb 100
31731386 A jtb S 44.09 100
31731387 R itb 100
31731576 A ktb S 44.05 100
31731576 R jtb 100
31731576 R ktb 100
31731583 A ltb S 44.02 100
31731583 R ftb 100
31731583 A mtb S 44.01 100
31731607 A ntb S 44.09 100
31731636 A otb S 44.09 100
31731637 R ntb 100
31731667 A ptb S 44.09 100
31731667 R otb 100
31731796 A qtb S 44.05 100
31731796 R ptb 100
31731797 R qtb 100
31731816 A rtb S 44.01 100
31731828 A stb S 44.09 100
31731828 R mtb 100
31731829 A ttb S 44.01 100
31731865 A utb S 44.09 100
31731865 R stb 100
31731896 A vtb S 44.08 100
31731896 R utb 100
31732017 A wtb S 44.05 100
31732017 R vtb 100
31732017 R wtb 100
31732047 A xtb S 44.08 100
31732056 A ytb S 44.01 100
31732056 R ttb 100
31732057 A ztb S 44.01 100
31732096 A aub S 44.08 100
31732097 R xtb 100
31732236 A bub S 44.05 100
31732236 R aub 100
31732236 R bub 100
31732267 A cub S 44.08 100
31732375 R etb 100
31732376 R ltb 100
31732376 R rtb 100
31732377 R ytb 100
31732456 A dub S 44.05 100
31732456 R cub 100
31732456 R dub 100
31732486 A eub S 44.08 100
31732566 A fub S 44.05 100
31732566 R eub 100
31732567 R fub 100
31732597 A gub S 44.08 100
31732727 A hub S 44.01 100
31732765 A iub S 44.08 100
31732766 R gub 100
31732766 R ztb 100
31732766 A jub S 44.01 100
31732797 A kub S 44.08 100
31732798 R iub 100
31732959 A lub S 44.01 100
31732959 R jub 100
31732960 A mub S 44.01 100
31732996 A nub S 44.05 100
31732996 R kub 100
31733005 R nub 100
31733035 A oub S 44.08 100
31733199 A pub S 44.00 100
31733216 A qub S 44.05 100
31733216 R oub 100
31733217 R qub 100
31733217 R mub 100
31733217 A rub S 44.00 100
31733248 A sub S 44.08 100
31733436 A tub S 44.05 100
31733436 R sub 100
31733437 R tub 100
31733446 A uub S 44.00 100
31733468 A vub S 44.07 100
31733656 A wub S 44.05 100
31733656 R vub 100
31733657 R wub 100
31733688 A xub S 44.07 100
31733689 R hub 100
31733689 R lub 100
31733690 R pub 100
31733690 R rub 100
31733690 R uub 100
31733690 A yub S 44.00 100
31733695 R yub 100
31733695 A zub S 44.07 100
31733736 R xub 100
31733766 A avb S 44.11 100
31733876 A bvb S 44.05 100
31733876 R avb 100
31733877 R bvb 100
31733877 R zub 100
31733877 A cvb S 44.05 100
31733909 A dvb S 44.11 100
31734016 A evb S 44.00 100
31734065 R cvb 100
31734065 A fvb S 44.00 100
31734075 R fvb 100
31734075 A gvb S 44.11 100
31734096 A hvb S 44.05 100
31734097 R dvb 100
31734097 R hvb 100
31734097 R gvb 100
31734098 A ivb S 44.05 100
31734128 A jvb S 44.11 100
31734286 R ivb 100
31734286 A kvb S 44.00 100
31734316 A lvb S 44.05 100
31734316 R jvb 100
31734316 R lvb 100
31734348 A mvb S 44.07 100
31734502 A nvb S 44.00 100
31734525 A ovb S 44.05 100
31734526 R mvb 100
31734526 R kvb 100
31734526 A pvb S 44.00 100
31734536 R ovb 100
31734566 A qvb S 44.07 100
31734711 A rvb S 44.00 100
31734712 R pvb 100
31734712 A svb S 44.00 100
31734747 A tvb S 44.05 100
31734747 R qvb 100
31734755 R tvb 100
31734785 A uvb S 44.07 100
31734866 A vvb S 44.05 100
31734867 R uvb 100
31734867 R vvb 100
31734898 A wvb S 44.07 100
31734950 R evb 100
31734950 R nvb 100
31734950 R rvb 100
31734955 R svb 100
31734955 A xvb S 44.07 100
31734995 R wvb 100
31735025 A yvb S 44.11 100
31735076 A zvb S 44.05 100
31735077 R yvb 100
31735077 R xvb 100
31735077 A awb S 44.05 100
31735077 R zvb 100
31735108 A bwb S 44.11 100
31735286 A cwb S 44.04 100
31735287 R awb 100
31735287 A dwb S 44.04 100
31735296 A ewb S 44.05 100
31735297 R bwb 100
31735297 R ewb 100
31735327 A fwb S 44.11 100
31735337 A gwb S 44.11 100
31735337 R fwb 100
31735513 A hwb S 44.04 100
31735516 A iwb S 44.05 100
31735516 R gwb 100
31735516 R iwb 100
31735517 R dwb 100
31735517 A jwb S 44.03 100
31735548 A kwb S 44.11 100
31735736 A lwb S 44.05 100
31735736 R kwb 100
31735737 R lwb 100
31735743 A mwb S 44.03 100
31735768 A nwb S 44.11 100
31735769 R jwb 100
31735769 A owb S 44.03 100
31735957 A pwb S 44.05 100
31735957 R nwb 100
31735957 R pwb 100
31735982 A qwb S 44.03 100
31735988 A rwb S 44.11 100
31736027 A swb S 44.11 100
31736027 R rwb 100
31736057 A twb S 44.11 100
31736058 R swb 100
31736216 R cwb 100
31736216 R hwb 100
31736217 R mwb 100
31736217 R owb 100
31736217 R qwb 100
31736217 A uwb S 44.03 100
31736276 A vwb S 44.05 100
31736276 R twb 100
31736286 R vwb 100
31736316 A wwb S 44.11 100
31736496 A xwb S 44.05 100
31736496 R wwb 100
31736505 R xwb 100
31736534 A ywb S 44.03 100
31736535 A zwb S 44.11 100
31736536 R uwb 100
31736536 A axb S 44.03 100
31736716 A bxb S 44.05 100
31736716 R zwb 100
31736717 R bxb 100
31736747 A cxb S 44.11 100
31736758 A dxb S 44.03 100
31736936 A exb S 44.05 100
31736936 R cxb 100
31736936 R axb 100
31736936 A fxb S 44.02 100
31736937 R exb 100
31736966 A gxb S 44.11 100
31736991 A hxb S 44.02 100
31737026 A ixb S 44.10 100
31737026 R gxb 100
31737027 R fxb 100
31737027 A jxb S 44.02 100
31737068 A kxb S 44.10 100
31737068 R ixb 100
31737156 A lxb S 44.05 100
31737156 R kxb 100
31737157 R lxb 100
31737189 A mxb S 44.10 100
31737221 A nxb S 44.02 100
31737375 A oxb S 44.05 100
31737375 R mxb 100
31737376 R oxb 100
31737406 A pxb S 44.10 100
31737471 R ywb 100
31737471 R dxb 100
31737471 R hxb 100
31737472 R jxb 100
31737472 A qxb S 44.02 100
31737472 R nxb 100
31737597 A rxb S 44.05 100
31737597 R pxb 100
31737598 R rxb 100
31737628 A sxb S 44.10 100
31737752 A txb S 44.02 100
31737752 R qxb 100
31737753 A uxb S 44.02 100
31737816 A vxb S 44.05 100
31737816 R sxb 100
31737817 R vxb 100
31737848 A wxb S 44.10 100
31737973 A xxb S 44.02 100
31738027 A yxb S 44.09 100
31738027 R wxb 100
31738027 R uxb 100
31738028 A zxb S 44.01 100
31738058 A ayb S 44.09 100
31738058 R yxb 100
31738190 A byb S 44.01 100
31738191 R zxb 100
31738191 A cyb S 44.01 100
31738246 A dyb S 44.05 100
31738246 R ayb 100
31738247 R dyb 100
31738278 A eyb S 44.09 100
31738357 A fyb S 44.05 100
31738357 R eyb 100
31738367 R fyb 100
31738396 A gyb S 44.09 100
31738446 R txb 100
31738446 R xxb 100
31738446 R byb 100
31738579 A hyb S 44.05 100
31738579 R gyb 100
31738579 R hyb 100
31738609 A iyb S 44.09 100
31738677 A jyb S 44.01 100
31738678 R cyb 100
31738678 A kyb S 44.01 100
31738798 A lyb S 44.05 100
31738798 R iyb 100
31738807 R lyb 100
31738837 A myb S 44.09 100
31738935 A nyb S 44.01 100
31739006 A oyb S 44.20 1000
31739018 A pyb S 44.05 100
31739018 R myb 100
31739019 R kyb 100
31739019 R pyb 100
31739019 A qyb S 44.01 100
31739049 A ryb S 44.08 100
31739098 A syb S 44.08 100
31739098 R ryb 100
31739166 A tyb S 44.01 100
31739167 R qyb 100
31739167 A uyb S 44.01 100
31739236 A vyb S 44.05 100
31739237 R syb 100
31739237 R vyb 100
31739268 A wyb S 44.08 100
31739425 R jyb 100
31739425 R nyb 100
31739425 R tyb 100
31739426 R uyb 100
31739426 A xyb S 44.08 100
31739456 A yyb S 44.05 100
31739456 R wyb 100
31739456 R yyb 100
31739457 R xyb 100
31739457 A zyb S 44.05 100
31739487 A azb S 44.08 100
31739566 A bzb S 44.05 100
31739566 R azb 100
31739566 R bzb 100
31739597 A czb S 44.08 100
31739775 A dzb S 44.05 100
31739776 R czb 100
31739785 R dzb 100
31739814 A ezb S 44.08 100
31739996 A fzb S 44.05 100
31739996 R ezb 100
31740005 R fzb 100
31740035 A gzb S 44.08 100
31743515 A hzb S 44.05 100
31743516 R gzb 100
31743525 R hzb 100
31743572 A izb S 44.08 100
31743716 A jzb S 44.05 100
31743716 R izb 100
31743716 R jzb 100
31743747 A kzb S 44.08 100
31743936 A lzb S 44.05 100
31743936 R kzb 100
31743936 R lzb 100
31743967 A mzb S 44.08 100
31744156 A nzb S 44.05 100
31744156 R mzb 100
31744157 R nzb 100
31744188 A ozb S 44.08 100
31744376 A pzb S 44.05 100
31744377 R ozb 100
31744377 R pzb 100
31744408 A qzb S 44.08 100
31744596 A rzb S 44.05 100
31744596 R qzb 100
31744596 R rzb 100
31744627 A szb S 44.08 100
31744646 A tzb B 43.91 100
31744646 R vsb 100
31744815 R tzb 100
31744845 A uzb B 43.90 100
31745246 A vzb S 44.05 100
31745247 R szb 100
31745255 R vzb 100
31745303 A wzb S 44.08 100
31745357 A xzb S 44.05 100
31745357 R wzb 100
31745366 R xzb 100
31745396 A yzb S 44.08 100
31745576 A zzb S 44.05 100
31745576 R yzb 100
31745576 R zzb 100
31745607 A aac S 44.08 100
31745795 A bac S 44.05 100
31745796 R aac 100
31745796 R bac 100
31745827 A cac S 44.08 100
31746015 A dac S 44.05 100
31746016 R cac 100
31746016 R dac 100
31746046 A eac S 44.08 100
31746236 A fac S 44.05 100
31746236 R eac 100
31746237 R fac 100
31746268 A gac S 44.08 100
31746437 A hac S 44.01 100
31746456 A iac S 44.05 100
31746456 R gac 100
31746456 R iac 100
31746457 R zyb 100
31746457 A jac S 44.01 100
31746487 A kac S 44.08 100
31746566 A lac S 44.05 100
31746566 R kac 100
31746567 R lac 100
31746597 A mac S 44.08 100
31746776 A nac S 44.05 100
31746776 R mac 100
31746785 R nac 100
31746815 A oac S 44.08 100
31746848 R hac 100
31746996 A pac S 44.05 100
31746996 R oac 100
31747005 R pac 100
31747034 A qac S 44.08 100
31747216 A rac S 44.05 100
31747216 R qac 100
31747217 R rac 100
31747247 A sac S 44.08 100
31747422 R hk 100
31747436 A tac S 44.05 100
31747436 R sac 100
31747437 R tac 100
31747467 A uac S 44.08 100
31747469 A vac S 44.01 100
31747470 R jac 100
31747470 A wac S 44.01 100
31747656 A xac S 44.05 100
31747656 R uac 100
31747657 R xac 100
31747687 A yac S 44.11 100
31747769 R vac 100
31747770 R wac 100
31747770 A zac S 44.11 100
31747876 A abc S 44.05 100
31747876 R yac 100
31747876 R abc 100
31747876 R zac 100
31747877 A bbc S 44.05 100
31747908 A cbc S 44.11 100
31748096 A dbc S 44.05 100
31748097 R cbc 100
31748097 R dbc 100
31748127 A ebc S 44.11 100
31748306 A fbc S 44.05 100
31748306 R ebc 100
31748326 R fbc 100
31748356 A gbc S 44.11 100
31748413 R hk 100
31748415 A hbc B 43.97 100
31748456 R hbc 100
31748460 A ibc S 44.01 100
31748526 A jbc S 44.05 100
31748526 R gbc 100
31748527 R bbc 100
31748527 A kbc S 44.01 100
31748536 R jbc 100
31748566 A lbc S 44.11 100
31748746 A mbc S 44.05 100
31748747 R lbc 100
31748840 R ibc 100
31748886 A nbc S 44.05 100
31748886 R mbc 100
31748984 A obc B 43.92 100
31749015 R nbc 100
31749026 A pbc B 43.90 100
31749026 R uzb 100
31749045 A qbc S 44.11 100
31749425 R pbc 100
31749436 A rbc S 44.11 100
31749436 R qbc 100
31749455 A sbc B 43.90 100
31750976 A tbc B 43.91 100
31750977 R sbc 100
31756035 R tbc 100
31756065 A ubc B 43.91 100
31756996 A vbc B 43.91 100
31756996 R ubc 100
31757266 A wbc S 44.07 100
31757266 R rbc 100
31757306 A xbc S 44.07 100
31757306 R wbc 100
31757366 A ybc B 43.91 100
31757366 R vbc 100
31758995 A zbc S 44.00 100
31758996 R kbc 100
31758997 A acc S 44.00 100
31759039 A bcc B 43.98 100
31759182 R zbc 100
31759635 A ccc S 44.00 100
31759806 R ccc 100
31760225 A dcc S 44.00 100
31760398 R dcc 100
31760809 A ecc S 44.00 100
31760990 R ecc 100
31761236 R bcc 100
31761265 R ybc 100
31761294 A fcc B 43.91 100
31761377 A gcc S 44.00 100
31761378 R acc 100
31761378 A hcc S 44.00 100
31761646 R gcc 100
31762002 A icc S 44.00 100
31762003 R hcc 100
31762003 A jcc S 43.99 100
31762175 R icc 100
31762537 A kcc S 43.99 100
31762537 R jcc 100
31762538 A lcc S 43.99 100
31762670 R lcc 100
31762694 R kcc 100
31762735 A mcc B 43.91 100
31762736 R fcc 100
31762746 R xbc 100
31762776 A ncc S 44.07 100
31764057 A occ S 44.07 100
31764529 A pcc S 44.00 100
31764709 R pcc 100
31767238 A qcc B 43.97 100
31767238 R obc 100
31767239 A rcc B 43.98 100
31767241 R qcc 100
31767266 R ncc 100
31767295 A scc S 44.11 100
31773586 A tcc S 44.08 100
31773586 R scc 100
31773617 A ucc S 44.08 100
31773617 R tcc 100
31775120 A vcc S 44.01 100
31775121 R occ 100
31775121 A wcc S 44.01 100
31775125 R rcc 100
31775125 A xcc B 43.92 100
31775155 R mcc 100
31775156 A ycc B 43.97 100
31775185 A zcc B 43.91 100
31775299 R vcc 100
31775300 R xcc 100
31775301 A adc B 43.98 100
31775302 R ycc 100
31775336 A bdc B 43.91 100
31775336 R zcc 100
31776839 A cdc S 44.01 100
31776839 R wcc 100
31776840 A ddc S 44.01 100
31776846 R adc 100
31776846 A edc B 43.92 100
31776875 R bdc 100
31776905 A fdc B 43.91 100
31777051 R cdc 100
31777086 A gdc B 43.91 100
31777087 R fdc 100
31777848 A hdc S 44.01 100
31777849 R ddc 100
31777849 A idc S 44.00 100
31777885 R gdc 100
31777915 A jdc B 43.91 100
31778035 R hdc 100
31778035 R idc 100
31778035 A kdc S 44.08 100
31778077 A ldc B 43.91 100
31778077 R jdc 100
31778826 A mdc S 44.01 100
31778826 R kdc 100
31778827 A ndc S 44.01 100
31778865 R ldc 100
31778895 A odc B 43.91 100
31778987 R mdc 100
31779026 A pdc B 43.91 100
31779026 R odc 100
31779287 A qdc B 43.97 100
31779288 R edc 100
31779288 A rdc B 43.98 100
31779290 R qdc 100
31779935 A sdc S 44.01 100
31779936 R ndc 100
31779937 A tdc S 44.01 100
31779946 R rdc 100
31779946 A udc B 43.92 100
31779975 R pdc 100
31780014 A vdc B 43.91 100
31780035 R sdc 100
31780078 A wdc B 43.91 100
31780078 R vdc 100
31787497 A xdc B 43.98 100
31787498 R udc 100
31787498 A ydc B 43.98 100
31787500 R xdc 100
31788705 R tdc 100
31788705 A zdc S 44.08 100
31788736 A aec B 43.91 100
31788736 R wdc 100
31788755 R ucc 100
31788767 A bec B 43.92 100
31788767 R aec 100
31788794 A cec S 44.11 100
31788911 A dec S 44.04 20
31789446 A eec B 43.92 100
31789447 R bec 100
31789496 A fec B 43.92 100
31789496 R eec 100
31789590 A gec B 43.99 100
31789966 A hec B 43.92 100
31789966 R fec 100
31789967 R ydc 100
31789967 A iec B 43.99 100
31790495 A jec B 43.92 100
31790495 R hec 100
31790526 A kec B 43.92 100
31790526 R jec 100
31790976 A lec B 43.92 100
31790977 R kec 100
31791428 A mec B 43.99 100
31791429 R iec 100
31791429 A nec B 43.99 100
31791446 A oec B 43.92 100
31791446 R lec 100
31791477 A pec B 43.92 100
31791477 R oec 100
31791857 R mec 100
31791886 A qec B 43.93 100
31791887 R pec 100
31792871 A rec B 43.99 100
31792872 R nec 100
31792872 A sec B 43.99 100
31792877 R rec 100
31792886 R qec 100
31792916 A tec B 43.91 100
31794116 A uec B 43.92 100
31794116 R tec 100
31794186 A vec B 43.92 100
31794187 R uec 100
31794595 A wec B 43.92 100
31794596 R vec 100
31794627 A xec B 43.92 100
31794627 R wec 100
31801255 R xec 100
31801286 A yec B 43.92 100
31801295 R yec 100
31801325 A zec B 43.91 100
31801357 R sec 100
31801555 R zec 100
31801585 A afc B 43.90 100
31804927 A bfc S 44.11 100
31804927 R cec 100
31804957 A cfc S 44.11 100
31804958 R bfc 100
31807457 A dfc B 43.95 100
31807496 A efc B 43.91 100
31807496 R afc 100
31808147 A ffc B 43.92 100
31808147 R efc 100
31808365 R ffc 100
31808395 A gfc B 43.90 100
31808676 A hfc B 43.92 100
31808676 R gfc 100
31808925 R hfc 100
31808955 A ifc B 43.90 100
31809216 A jfc B 43.92 100
31809217 R ifc 100
31809436 R jfc 100
31809465 A kfc B 43.90 100
31809716 A lfc B 43.92 100
31809716 R kfc 100
31809936 R lfc 100
31809966 A mfc B 43.90 100
31810756 A nfc S 44.11 100
31810756 R cfc 100
31810787 A ofc S 44.10 100
31810787 R nfc 100
31811521 A pfc S 44.03 100
31811565 A qfc B 43.91 100
31811566 R mfc 100
31811566 R zdc 100
31811567 A rfc S 44.03 100
31812176 A sfc S 44.10 100
31812176 R ofc 100
31812206 A tfc S 44.10 100
31812206 R sfc 100
31812633 A ufc S 44.03 100
31813166 A vfc S 44.10 100
31813166 R tfc 100
31813167 R rfc 100
31813167 A wfc S 44.03 100
31813600 A xfc S 44.02 100
31814032 R pfc 100
31814033 R ufc 100
31814033 R xfc 100
31814033 R wfc 100
31814033 A yfc S 44.02 100
31814065 R vfc 100
31814095 A zfc S 44.10 100
31819072 A agc B 43.80 100
31821624 R gec 100
31821632 A bgc B 43.97 100
31821666 R qfc 100
31821677 R bgc 100
31821695 A cgc B 43.90 100
31828307 A dgc B 43.91 100
31828307 R cgc 100
31839944 A egc S 44.16 100
31840306 A fgc S 44.09 100
31840306 R zfc 100
31840337 A ggc S 44.09 100
31840337 R fgc 100
31841636 A hgc S 44.09 100
31841637 R ggc 100
31841667 A igc S 44.09 100
31841668 R hgc 100
31842636 A jgc S 44.09 100
31842636 R igc 100
31842667 A kgc S 44.09 100
31842667 R jgc 100
31843766 A lgc S 44.08 100
31843766 R kgc 100
31843796 A mgc S 44.08 100
31843796 R lgc 100
31844906 A ngc S 44.08 100
31844906 R mgc 100
31844937 A ogc S 44.08 100
31844937 R ngc 100
31845998 A pgc S 44.02 100
31845998 R yfc 100
31845999 A qgc S 44.01 100
31846007 R pgc 100
31846026 A rgc S 44.08 100
31846026 R ogc 100
31846057 A sgc S 44.08 100
31846057 R rgc 100
31846526 R dgc 100
31846556 A tgc B 43.90 100
31848617 A ugc S 44.08 100
31848617 R sgc 100
31848961 A vgc S 43.98 50
31849076 R ugc 100
31849106 A wgc S 44.08 100
31854157 A xgc B 43.98 100
31854215 A ygc B 43.90 100
31854216 R tgc 100
31858756 A zgc B 43.91 100
31858756 R ygc 100
31858774 R xgc 100
31859250 R vgc 50
31859355 R zgc 100
31859385 A ahc B 43.90 100
31860958 A bhc B 43.97 100
31862216 A chc S 44.08 100
31862216 R wgc 100
31862646 R chc 100
31862675 A dhc S 44.08 100
31863186 A ehc S 44.08 100
31863187 R dhc 100
31863505 R ehc 100
31863535 A fhc S 44.08 100
31864072 A ghc S 44.01 100
31864073 R qgc 100
31864073 A hhc S 44.00 100
31864379 A ihc B 43.97 100
31864380 A jhc B 43.97 100
31864426 A khc B 43.90 100
31864427 R ahc 100
31864427 R ghc 100
31864952 R bhc 100
31864985 R khc 100
31865015 A lhc B 43.90 100
31865200 A mhc S 44.00 100
31865201 R hhc 100
31865201 A nhc S 44.00 100
31865692 R mhc 100
31865723 R nhc 100
31865723 A ohc S 44.08 100
31866466 A phc S 44.08 100
31866466 R fhc 100
31868396 R phc 100
31868425 A qhc S 44.08 100
31868976 A rhc S 44.08 100
31868976 R qhc 100
31869306 R rhc 100
31869336 A shc S 44.08 100
31872126 A thc B 43.98 100
31872166 R shc 100
31872176 A uhc B 43.90 100
31872176 R lhc 100
31872195 A vhc S 44.11 100
31873034 R thc 100
31873075 R uhc 100
31873105 A whc B 43.90 100
31874396 A xhc B 43.91 100
31874396 R whc 100
31874846 R xhc 100
31874875 A yhc B 43.90 100
31875436 A zhc B 43.91 100
31875436 R yhc 100
31875876 R zhc 100
31875906 A aic B 43.90 100
31875925 R aic 100
31875954 A bic B 43.90 100
31876536 A cic B 43.91 100
31876537 R bic 100
31876865 R cic 100
31876895 A dic B 43.90 100
31877486 A eic B 43.98 100
31877546 A fic B 43.90 100
31877546 R ihc 100
31877546 R dic 100
31877547 A gic B 43.99 100
31877568 R jhc 100
31877569 A hic B 43.99 100
31877595 R fic 100
31877625 A iic B 43.90 100
31877733 R eic 100
31878086 A jic B 43.90 100
31878087 R iic 100
31880646 A kic B 43.91 100
31880646 R jic 100
31880666 R kic 100
31880703 A lic B 43.90 100
31887391 A mic B 43.96 100
31887413 A nic B 43.96 100
31887446 A oic B 43.90 100
31887447 R lic 100
31887477 A pic B 43.91 100
31887477 R oic 100
31887566 R pic 100
31887595 A qic B 43.90 100
31888635 A ric B 43.99 100
31888689 R gic 100
31888689 A sic B 43.99 100
31888711 R hic 100
31888712 A tic B 43.99 100
31889244 R ric 100
31910383 A uic B 43.96 100
31910384 A vic B 43.96 100
31910432 R mic 100
31910433 A wic B 43.97 100
31910433 R nic 100
31910434 A xic B 43.97 100
31913766 R qic 100
31913796 A yic B 43.90 100
31917106 A zic B 43.90 100
31917106 R yic 100
31929815 R zic 100
31929845 A ajc B 43.90 100
31933384 A bjc B 43.96 100
31933406 A cjc B 43.96 100
31933432 R uic 100
31933433 A djc B 43.97 100
31933453 R vic 100
31933454 A ejc B 43.97 100
31933484 R wic 100
31933484 A fjc B 43.97 100
31933505 R xic 100
31933506 A gjc B 43.97 100
31952846 A hjc B 44.00 100
31952894 R sic 100
31952895 R tic 100
31952895 A ijc B 44.01 100
31952896 A jjc B 44.01 100
31952896 R ejc 100
31952896 A kjc B 44.01 100
31952917 R cjc 100
31952918 R bjc 100
31952918 A ljc B 44.01 100
31952919 A mjc B 44.01 100
31952919 R djc 100
31952919 A njc B 44.01 100
31952920 R gjc 100
31952921 A ojc B 44.01 100
31952921 R fjc 100
31952922 A pjc B 44.01 100
31956383 A qjc B 44.01 100
31956406 A rjc B 44.01 100
31956916 A sjc S 44.11 100
31956916 R vhc 100
31958516 R sjc 100
31958526 A tjc B 43.92 100
31958527 R ajc 100
31958545 A ujc S 44.11 100
31967860 A vjc B 44.01 100
31967924 R ijc 100
31967925 A wjc B 44.02 100
31967947 R jjc 100
31967947 R rjc 100
31967947 A xjc B 44.02 100
31967948 R qjc 100
31967948 A yjc B 44.02 100
31967949 A zjc B 44.02 100
31967949 R ljc 100
31967950 R mjc 100
31967950 A akc B 44.02 100
31967950 A bkc B 44.02 100
31967951 R kjc 100
31967952 A ckc B 44.02 100
31967952 R njc 100
31967953 A dkc B 44.02 100
31967953 R ojc 100
31967954 A ekc B 44.02 100
31967954 R pjc 100
31967955 A fkc B 44.02 100
31973063 R vjc 100
31974375 R ujc 100
31974386 R tjc 100
31974405 A gkc S 44.11 100
31974416 A hkc B 43.97 100
31975161 R wjc 100
31975161 R xjc 100
31975161 R yjc 100
31976446 R hkc 100
31976475 A ikc B 43.92 100
31978012 A jkc S 44.04 100
31978675 R jkc 100
31979373 A kkc B 44.01 100
31979394 A lkc B 44.01 100
31979860 A mkc B 44.04 100
31979890 R fkc 100
31979913 R ekc 100
31979913 R dkc 100
31979914 R zjc 100
31979916 R akc 100
31979917 R bkc 100
31979919 R ckc 100
31979992 R mkc 100
31980036 R ikc 100
31980065 A nkc B 43.92 100
31980142 R dec 20
31982971 A okc S 44.04 100
31983400 R okc 100
31984025 A pkc S 44.11 100
31984026 R gkc 100
31984056 A qkc S 44.11 100
31984056 R pkc 100
31985110 A rkc S 44.04 100
31985353 R rkc 100
31988202 A skc S 44.16 100
31991764 A tkc S 44.04 100
31991764 R ohc 100
31991765 A ukc S 44.04 100
31992415 R tkc 100
31993188 A vkc S 44.04 100
31995091 R vkc 100
31996376 R hj 100
31998521 A wkc S 44.04 100
31999032 R wkc 100
31999950 A xkc S 47.76 22
32000830 A ykc S 53.88 260
32001461 A zkc S 50.40 12
32002413 A alc B 44.00 100
32002436 A blc B 44.00 100
32002514 A clc S 72.00 10
32003252 A dlc S 46.78 50
32003307 A elc S 48.96 63
32003447 A flc S 54.60 5
32008126 R nkc 100
32008156 A glc B 43.92 100
32020792 A hlc S 44.08 100
32022880 A ilc B 43.95 100
32022881 R ukc 100
32022882 R ilc 100
32022883 A jlc B 44.00 100
32022886 A klc S 44.06 100
32022888 R klc 100
32022907 R alc 100
32022907 A llc B 44.00 100
32022915 R qkc 100
32022916 A mlc B 43.92 100
32022917 R glc 100
32022929 R blc 100
32022930 A nlc B 44.00 100
32022945 A olc S 44.11 100
32022958 R kkc 100
32022959 A plc B 44.01 100
32022980 R lkc 100
32022980 A qlc B 44.01 100
32023146 R jlc 100
32023146 A rlc B 44.01 100
32023186 A slc B 43.93 100
32023186 R mlc 100
32024824 A tlc S 44.08 20
32024866 R slc 100
32024896 A ulc B 43.93 100
32025315 R olc 100
32025345 A vlc S 44.17 100
32025405 A wlc B 44.02 100
32025427 A xlc B 44.02 100
32025428 R rlc 100
32025428 A ylc B 44.02 100
32025445 A zlc B 43.94 100
32025446 R ulc 100
32025465 R zlc 100
32025503 A amc B 43.94 100
32027436 A bmc B 43.94 100
32027436 R amc 100
32027467 A cmc B 43.94 100
32027467 R bmc 100
32027644 A dmc B 44.03 400
32027686 A emc B 43.95 100
32027686 R cmc 100
32027716 A fmc B 43.95 100
32027717 R emc 100
32031942 R hlc 100
32031943 R ylc 100
32031944 A gmc B 44.03 100
32032912 R llc 100
32032913 R nlc 100
32032913 A hmc B 44.04 100
32032914 R qlc 100
32032914 A imc B 44.04 100
32032915 A jmc B 44.04 100
32032915 R gmc 100
32032915 R plc 100
32032915 A kmc B 44.04 100
32032916 A lmc B 44.04 100
32032956 A mmc B 43.96 100
32032957 R fmc 100
32032965 R mmc 100
32033013 A nmc B 43.96 100
32034761 A omc B 44.04 100
32034816 A pmc B 43.96 100
32034816 R nmc 100
32034847 A qmc B 43.96 100
32034847 R pmc 100
32035911 R wlc 100
32035912 R xlc 100
32035912 R kmc 100
32035912 A rmc B 44.05 100
32035912 A smc B 44.04 100
32035913 A tmc B 44.05 100
32035914 R smc 100
32035914 A umc B 44.05 100
32038157 R omc 100
32039016 A vmc S 44.13 100
32039016 R vlc 100
32039737 A wmc S 44.08 100
32039738 R umc 100
32039738 A xmc B 44.04 100
32040076 A ymc B 43.97 100
32040077 R qmc 100
32040592 R wmc 100
32040593 R xmc 100
32040593 A zmc B 44.05 100
32040635 R ymc 100
32040664 A anc B 43.97 100
32040676 A bnc B 43.97 100
32040676 R anc 100
32041676 R vmc 100
32041705 A cnc S 44.17 100
32042406 A dnc S 44.13 100
32042406 R cnc 100
32042485 A enc S 44.06 100
32042486 R zmc 100
32042486 R tlc 20
32042486 A fnc B 44.04 100
32042486 A gnc S 44.06 20
32042491 A hnc S 44.09 100
32042876 R hmc 100
32042877 A inc B 44.04 100
32042899 R imc 100
32042900 R jmc 100
32042900 A jnc B 44.04 100
32042901 A knc B 44.04 100
32042916 A lnc B 44.05 100
32042917 R gnc 20
32042917 A mnc S 44.08 20
32042921 R lmc 100
32042922 A nnc B 44.04 100
32043007 R enc 100
32043008 R fnc 100
32043008 A onc B 44.05 100
32043716 R onc 100
32043716 A pnc B 44.05 100
32043717 R hnc 100
32043745 R dnc 100
32043775 A qnc S 44.17 100
32043929 A rnc S 44.06 100
32044378 R rnc 100
32044706 A snc S 44.13 100
32044706 R qnc 100
32045295 R snc 100
32045325 A tnc S 44.17 100
32045856 A unc S 44.13 100
32045856 R tnc 100
32045860 A vnc S 44.06 100
32045861 R pnc 100
32045861 A wnc B 44.03 100
32045893 R rmc 100
32045894 A xnc B 44.06 100
32045915 R tmc 100
32045916 A ync B 44.06 100
32045936 A znc B 43.98 100
32045936 R bnc 100
32046270 R vnc 100
32046271 R wnc 100
32046271 A aoc B 44.05 100
32046306 A boc B 43.98 100
32046306 R znc 100
32046749 R xnc 100
32046749 R ync 100
32046756 A coc B 44.03 100
32046967 R coc 100
32046995 R unc 100
32047025 A doc S 44.17 100
32047096 A eoc S 44.06 100
32047420 R eoc 100
32048351 A foc B 44.06 100
32048351 R aoc 100
32048352 A goc B 44.06 100
32048372 A hoc B 44.06 100
32049276 R goc 100
32049315 A ioc S 44.17 100
32049316 R doc 100
32052865 R inc 100
32052866 A joc B 44.05 100
32052866 A koc B 44.06 100
32052887 R jnc 100
32052888 A loc B 44.05 100
32052888 R knc 100
32052888 R nnc 100
32052889 A moc B 44.05 100
32052889 A noc B 44.05 100
32055383 R koc 100
32055383 A ooc S 44.06 100
32055384 A poc B 44.05 100
32056339 R foc 100
32056339 R hoc 100
32056356 R poc 100
32056386 A qoc S 44.15 100
32056386 R ioc 100
32056406 R boc 100
32056417 A roc S 44.15 100
32056417 R qoc 100
32056443 A soc B 43.96 100
32056741 R joc 100
32056741 R loc 100
32056741 R moc 100
32057371 R ooc 100
32057642 A toc S 44.06 100
32059268 R noc 100
32059269 A uoc S 44.05 3
32059270 A voc S 44.05 100
32059271 R mnc 20
32059271 A woc S 44.05 100
32059306 R soc 100
32059316 A xoc S 44.13 100
32059317 R roc 100
32059336 A yoc B 43.95 100
32059366 A zoc S 44.13 100
32059366 R xoc 100
32059771 R lnc 100
32059816 R yoc 100
32059845 A apc B 43.93 100
32059985 R uoc 3
32059985 R voc 100
32060078 R egc 100
32060343 A bpc S 44.05 100
32060385 A cpc S 44.12 100
32060386 R zoc 100
32060386 R woc 100
32060386 A dpc S 44.05 100
32060416 A epc S 44.12 100
32060416 R cpc 100
32062344 R bpc 100
32062356 R dpc 100
32062356 A fpc S 44.05 100
32062359 A gpc S 44.07 100
32062367 R gpc 100
32062395 R epc 100
32062425 A hpc S 44.12 100
32062659 A ipc S 44.05 100
32062706 A jpc S 44.12 100
32062706 R hpc 100
32062707 R fpc 100
32062707 A kpc S 44.05 100
32062736 A lpc S 44.12 100
32062736 R jpc 100
32064107 R toc 100
32064615 R ipc 100
32064626 R kpc 100
32064626 A mpc S 44.12 100
32064630 A npc S 44.07 100
32064630 R mpc 100
32064631 A opc S 44.07 100
32064637 R npc 100
32064665 R lpc 100
32064695 A ppc S 44.15 100
32065426 A qpc B 43.96 100
32065426 R apc 100
32065655 R qpc 100
32065685 A rpc B 43.93 100
32066006 A spc B 43.96 100
32066006 R rpc 100
32066215 R spc 100
32066245 A tpc B 43.93 100
32066467 A upc B 43.96 100
32066467 R tpc 100
32066475 A vpc S 44.14 100
32066476 R ppc 100
32066695 R upc 100
32066706 A wpc S 44.14 100
