33193634 A usd B 44.07 100
33194721 R usd 25
33194722 A vsd B 44.07 100
33194766 A wsd S 44.16 100
33194766 R tsd 100
33194796 A xsd S 44.16 100
33194796 R wsd 100
33197388 R msd 100
33197388 A ysd S 44.12 100
33197392 A zsd S 44.11 100
33197393 R ysd 100
33197393 A atd S 44.10 100
33197398 R zsd 100
33197427 R xsd 100
33197427 A btd B 43.98 100
33197428 R rsd 100
33197457 A ctd S 44.16 100
33197484 A dtd B 43.98 100
33197484 R btd 100
33198069 A etd S 44.08 100
33198098 A ftd S 44.15 100
33198098 R ctd 100
33200873 A gtd B 44.07 100
33200901 A htd S 44.07 50
33200902 R vsd 100
33200902 R usd 75
33200902 A itd S 44.07 50
33200903 R htd 50
33200903 R itd 50
33200905 A jtd B 44.07 100
33200906 A ktd S 44.10 100
33201155 R jtd 100
33201156 R atd 100
33201156 A ltd S 44.10 100
33201159 A mtd B 44.07 100
33201288 R etd 100
33201289 R ktd 100
33201291 A ntd S 44.11 100
33201317 R ftd 100
33201347 A otd S 44.16 100
33203186 R ltd 100
33203186 A ptd S 44.11 100
33203189 A qtd S 44.10 100
33203190 A rtd B 44.05 100
33203190 R qsd 100
33203191 A std B 44.05 100
33203217 A ttd B 44.00 100
33203217 R dtd 100
33209300 A utd B 44.07 500
33212978 R xqd 480
33215263 R nsd 41
33215326 A vtd S 44.14 43
33215565 R mtd 100
33215753 A wtd B 44.08 100
33231113 R vtd 43
33231173 A xtd S 44.08 43
33232547 R utd 500
33233463 R xtd 43
33233467 R rtd 100
33234097 R ttd 100
33234126 A ytd B 43.98 100
33238277 A ztd B 44.01 100
33238277 R ytd 100
33238596 R ztd 100
33238626 A aud B 43.98 100
33239207 A bud B 44.01 100
33239207 R aud 100
33239496 R bud 100
33239526 A cud B 43.98 100
33240082 R gtd 100
33240083 R ptd 100
33240084 A dud S 44.10 100
33240085 R qtd 100
33244894 R wtd 100
33244896 A eud B 44.08 100
33247659 R eud 60
33247661 A fud B 44.08 100
33268007 A gud S 44.16 100
33268007 R otd 100
33290093 A hud B 43.93 100
33291587 R eud 23
33298656 A iud S 44.15 100
33298657 R gud 100
33300104 R rc 100
33300445 R bv 200
33300492 R dud 100
33300492 A jud S 44.11 100
33300495 R ntd 100
33300495 A kud S 44.10 100
33300519 R iud 100
33300521 R kud 100
33300548 A lud S 44.17 100
33300782 R bm 200
33300832 R rnd 100
33300848 R ku 100
33301010 R oyb 1000
33322247 R eud 17
33322247 R fud 23
33322249 A mud B 44.08 100
33322251 A nud S 44.12 100
33322287 A oud S 44.17 100
33322287 R lud 100
33322288 R oud 100
33322345 A pud S 44.17 100
33335312 R mud 100
33335312 R fud 77
33335316 A qud B 44.03 100
33335347 A rud S 44.17 100
33335347 R pud 100
33335504 A sud B 44.07 100
33379807 A tud B 43.99 100
33379808 R cud 100
33379819 R qud 100
33379820 R nud 100
33379832 A uud S 44.11 100
33379847 R rud 100
33379857 A vud B 43.99 100
33379857 R tud 100
33379858 R jud 100
33379858 A wud S 44.11 100
33379859 R uud 100
33379877 A xud S 44.17 100
33394287 A yud B 43.99 100
33394287 R vud 100
33407058 A zud B 43.99 100
33407058 R yud 100
33407077 R zud 100
33407115 A avd B 43.98 100
33409897 R hud 100
33409962 A bvd B 43.93 100
33417898 A cvd S 44.22 100
33426090 A dvd S 44.10 100
33430822 A evd S 44.10 100
33430823 R wud 100
33430823 A fvd S 44.10 100
33430823 R dvd 100
33433855 R evd 100
33439629 R std 100
33439630 A gvd B 44.07 53
33470788 R sud 100
33471028 R fvd 100
33471028 A hvd S 44.12 100
33471057 A ivd B 44.02 100
33471058 R avd 100
33488557 R gvd 53
33488557 A jvd B 44.04 53
33488587 R ivd 100
33488617 A kvd B 43.98 100
33495816 A lvd B 44.08 100
33499407 R jvd 53
33499407 A mvd B 44.08 100
33499409 A nvd S 44.12 200
33499409 R nvd 200
33499437 R xud 100
33499447 A ovd B 43.98 100
33499447 R kvd 100
33499466 A pvd S 44.20 100
33499496 A qvd B 43.98 100
33499496 R ovd 100
33507121 R hvd 100
33507121 A rvd B 44.12 380
33507166 R pvd 100
33507177 A svd B 44.03 100
33507177 R qvd 100
33507206 A tvd S 44.21 100
33507233 A uvd B 44.03 100
33507233 R svd 100
33508180 A vvd B 44.10 10
33510279 R kqd 100
33510280 R mvd 100
33510280 A wvd B 44.12 100
33512164 R aqd 100
33512207 R tvd 100
33512237 A xvd S 44.22 100
33512237 R xvd 100
33512268 A yvd S 44.22 100
33513884 R dhd 100
33513885 A zvd S 44.13 100
33513926 R yvd 100
33513956 A awd S 44.22 100
33514381 R zvd 100
33514383 A bwd S 44.13 100
33514426 R awd 100
33514456 A cwd S 44.22 100
33514713 R lvd 100
33515371 R rvd 380
33515372 R wvd 100
33515372 A dwd B 44.04 100
33515376 A ewd B 44.08 100
33516057 A fwd S 44.20 100
33516058 R cwd 100
33517440 A gwd S 44.13 100
33517441 R dwd 100
33517441 A hwd B 44.08 100
33518270 A iwd S 44.16 100
33518297 R fwd 100
33518326 A jwd S 44.22 100
33519128 A kwd S 44.20 100
33519128 R jwd 100
33522776 R kwd 100
33522807 A lwd S 44.22 100
33523712 A mwd S 44.13 100
33523994 A nwd B 44.10 480
33524957 A owd S 44.20 100
33524957 R lwd 100
33526334 R mwd 100
33526335 R hwd 100
33526335 A pwd B 44.10 100
33527395 R nwd 480
33527868 A qwd B 44.10 100
33528809 R ewd 100
33528836 R owd 100
33528866 A rwd S 44.22 100
33529469 R pwd 100
33529473 A swd B 44.08 100
33529620 R swd 100
33529637 A twd S 44.17 100
33529637 R rwd 100
33529646 R uvd 100
33529693 A uwd B 44.01 100
33531377 R qwd 100
33531378 A vwd B 44.04 100
33531378 A wwd B 44.10 100
33531457 A xwd B 44.02 100
33531457 R uwd 100
33531488 A ywd B 44.02 100
33531489 R xwd 100
33540526 A zwd B 43.08 100
33552623 R wwd 10
33552624 A axd B 44.10 100
33557782 R wwd 90
33557782 R axd 100
33557784 A bxd B 44.10 100
33557817 R twd 100
33557827 R ywd 100
33557828 R vwd 100
33557828 A cxd B 44.10 100
33557847 A dxd S 44.22 100
33557857 A exd B 44.02 100
33557857 R exd 100
33557887 A fxd B 44.01 100
33559679 A gxd S 44.13 100
33563038 R gwd 100
33564960 R gxd 100
33566879 A hxd S 44.12 30
33568907 A ixd B 44.03 100
33568907 R fxd 100
33568937 A jxd B 44.03 100
33568937 R ixd 100
33573557 A kxd S 44.20 100
33573558 R dxd 100
33576247 A lxd S 44.14 100
33577296 R lxd 100
33623487 R kxd 100
33623517 A mxd S 44.22 100
33628411 A nxd S 44.13 100
33628447 A oxd S 44.22 100
33628447 R mxd 100
33645407 A pxd B 44.11 100
33645447 A qxd B 44.03 100
33645447 R jxd 100
33645478 A rxd B 44.03 100
33645478 R qxd 100
33647356 A sxd B 40.80 30
33660845 R nxd 100
33660846 R cxd 100
33660846 A txd B 44.11 100
33683320 A uxd B 40.80 30
33688057 R oxd 100
33688087 A vxd S 44.22 100
33688198 R txd 100
33688200 A wxd S 44.15 100
33688236 A xxd S 44.22 100
33688237 R vxd 100
33691148 A yxd B 44.11 100
33701291 R hxd 30
33736217 A zxd S 44.20 100
33736218 R xxd 100
33737144 R yxd 100
33739057 A ayd B 44.11 53
33751054 A byd S 44.12 100
33753036 R zxd 100
33753066 A cyd S 44.22 100
33753067 A dyd S 44.22 100
33753068 R cyd 100
33790100 A eyd B 44.11 200
33790137 A fyd B 44.03 100
33790137 R rxd 100
33790157 R fyd 100
33790194 A gyd B 44.03 100
33802077 A hyd S 44.22 100
33802078 R dyd 100
33806207 A iyd S 44.21 100
33806208 R hyd 100
33809789 A jyd B 44.10 200
33809810 A kyd B 44.05 100
33809811 R gyd 100
33809819 R iyd 100
33809868 A lyd S 44.22 100
33814163 R eyd 200
33825313 R byd 100
33825313 A myd B 44.12 100
33825314 R wxd 100
33825314 A nyd S 44.16 100
33825315 R ayd 53
33825315 A oyd B 44.13 53
33825347 A pyd S 44.64 100
33825679 R jyd 200
33825707 R lyd 100
33825737 A qyd S 44.22 100
33825777 A ryd S 44.22 100
33825777 R qyd 100
33835678 A syd S 44.40 100
33845890 R hrc 400
33854108 A tyd S 44.22 100
33854108 R ryd 100
33856847 R oyd 53
33856847 R nyd 100
33856848 A uyd B 44.11 53
33856848 A vyd S 44.15 100
33856877 A wyd S 44.20 100
33856878 R tyd 100
33858757 R myd 100
33874007 R uyd 53
33874008 A xyd B 44.13 53
33874038 A yyd B 44.05 100
33874039 R kyd 100
33887896 R xyd 53
33887896 R pxd 100
33887896 R bxd 100
33887898 A zyd B 44.10 100
33887929 A azd S 44.15 200
33891117 A bzd B 44.10 100
33894117 A czd B 44.10 200
33903439 A dzd B 44.10 200
33903440 R bzd 100
33903440 A ezd B 44.10 100
33903466 R yyd 100
33903496 A fzd B 44.05 100
33907506 A gzd B 44.10 100
33907751 R czd 200
33913154 R we 100
33921911 A hzd B 12.00 1
33928720 A izd S 44.13 100
33928729 R pyd 100
33928736 A jzd S 44.64 100
33936377 R ezd 100
33936377 A kzd B 44.10 100
33936379 R azd 200
33939547 R kzd 100
33939547 A lzd B 44.05 100
33939549 R dzd 200
33939577 R fzd 100
33939607 A mzd B 44.03 100
33939667 A nzd B 44.03 100
33939667 R mzd 100
33939677 R nzd 100
33939725 A ozd B 44.03 100
33940164 R gzd 100
33940168 A pzd B 44.08 200
33940169 R lzd 100
33940169 A qzd B 44.08 100
33942416 R izd 100
33942420 A rzd S 44.15 200
33942441 R jzd 100
33942446 A szd S 44.64 100
33942458 A tzd B 44.03 100
33942458 R ozd 100
33942527 R qzd 100
33942528 A uzd B 44.10 100
33942529 R rzd 200
33942542 R szd 100
33942557 R wyd 100
33942568 R bwd 100
33942570 A vzd S 44.13 100
33942572 A wzd S 44.16 100
33942587 A xzd S 44.21 100
33944822 R vzd 100
33944823 A yzd S 44.13 100
33949171 A zzd B 42.84 20
33950078 R uzd 100
33950078 A aae B 44.08 100
33950081 R wzd 100
33950081 A bae S 44.15 100
33950110 A cae S 44.20 100
33950110 R xzd 100
33953352 R vyd 100
33953353 A dae S 44.13 13
33953967 A eae B 44.03 100
33953967 R tzd 100
33954516 R eae 100
33954546 A fae B 44.03 100
33963683 A gae B 44.09 400
33963684 R aae 100
33963684 A hae B 44.09 100
33965579 R vt 650
33973111 R hae 100
33973112 A iae B 44.10 100
33981472 A jae S 47.76 2
33982210 R bae 100
33982237 R cae 100
33982293 A kae S 44.20 100
33984942 R agc 100
33985038 A lae S 44.11 5
33992724 A mae S 44.13 100
34001417 A nae S 44.99 50
34007188 A oae B 33.00 50
34040170 R pzd 200
34040170 R dae 13
34040171 A pae S 44.13 13
34040171 R iae 100
34040172 A qae B 44.09 100
34048007 R lae 5
34048008 R qae 100
34048008 A rae B 44.10 100
34048038 A sae B 43.34 40
34048049 A tae B 44.03 100
34048049 R fae 100
34048456 R pae 13
34048456 R mae 100
34048456 R yzd 87
34048459 A uae S 44.14 100
34048459 A vae S 44.13 100
34048461 R uae 100
34048461 A wae S 44.15 100
34048498 A xae S 44.20 100
34048498 R kae 100
34050455 R zyd 100
34050456 A yae S 44.15 100
34062173 A zae B 44.10 180
34062173 R rae 100
34062174 A abe B 44.10 100
34062598 R sae 40
34062605 A bbe B 43.34 45
34093906 A cbe S 44.28 50
34095516 R zae 180
34106448 A dbe B 44.05 180
34110399 R lcd 100
34117229 R wae 100
34117257 R xae 100
34117287 A ebe S 44.20 100
34117521 R yzd 13
34117521 R vae 100
34120932 R dbe 180
34131453 A fbe S 44.12 200
34131497 A gbe S 44.20 100
34131498 R ebe 100
34141921 R fbe 200
34141922 A hbe S 44.12 200
34141922 A ibe S 44.15 100
34141922 R yae 100
34141923 A jbe S 44.15 100
34141924 R ibe 100
34160607 R hbe 200
34162888 A kbe B 44.12 100
34162927 R gbe 100
34162928 A lbe B 44.03 100
34162928 R tae 100
34162957 A mbe S 44.20 100
34167534 A nbe S 44.14 200
34167534 R jbe 100
34167535 A obe S 44.14 100
34167536 R nbe 200
34167549 R mbe 100
34167582 A pbe S 44.21 100
34167639 A qbe B 44.03 100
34167640 R lbe 100
34168117 R obe 100
34168117 R abe 100
34168117 A rbe S 44.15 100
34168117 A sbe B 44.12 50
34168147 R pbe 100
34168176 A tbe S 44.23 100
34172558 A ube S 44.41 200
34175314 R kbe 100
34179829 A vbe B 44.12 100
34179830 A wbe B 44.09 200
34181418 A xbe B 44.03 100
34181418 R qbe 100
34181447 R rbe 100
34181447 A ybe S 44.16 100
34181449 A zbe B 44.04 100
34181449 R xbe 100
34181480 A ace B 44.04 100
34181481 R zbe 100
34181512 A bce B 44.05 100
34181512 R ace 100
34181543 A cce B 44.05 100
34181543 R bce 100
34184108 R sbe 50
34184108 R ybe 100
34184108 A dce S 44.15 200
34184108 A ece B 44.09 50
34184109 A fce S 44.15 100
34184111 A gce B 44.10 200
34184112 R ece 50
34184112 A hce S 44.15 200
34184112 A ice B 44.10 50
34184113 R wbe 200
34184113 A jce B 44.10 200
34184118 R jce 200
34184118 A kce B 44.09 200
34184120 R gce 200
34184138 A lce S 44.20 100
34184138 R tbe 100
34184148 R cce 100
34184169 A mce S 44.20 100
34184169 R lce 100
34184195 A nce B 44.04 100
34184237 R nce 100
34184267 A oce B 44.03 100
34184287 R mce 100
34184298 A pce B 44.04 100
34184298 R oce 100
34184317 A qce S 44.20 100
34184397 R ice 50
34184397 A rce B 44.12 50
34184398 R dce 200
34184398 A sce S 44.15 200
34184399 R hce 200
34184427 R qce 100
34184457 A tce S 44.22 100
34184487 R tce 100
34184516 A uce S 44.22 100
34184618 A vce S 44.22 100
34184618 R uce 100
34188328 A wce B 44.12 100
34188328 A xce S 44.15 100
34188329 R sce 200
34188367 A yce B 44.04 100
34188368 R pce 100
34188368 A zce S 44.22 100
34188368 R vce 100
34188399 A ade B 44.04 100
34188399 R yce 100
34188430 A bde B 44.04 100
34188430 R ade 100
34188461 A cde B 44.04 100
34188461 R bde 100
34188844 R erc 200
34189314 R oxc 100
34189440 R rce 50
34189440 R wce 100
34189441 R fce 100
34189442 A dde S 44.15 100
34189442 A ede S 44.12 100
34189443 A fde S 44.15 200
34189465 R xce 100
34189465 A gde B 44.09 100
34189465 A hde S 44.14 100
34189466 R dde 100
34189466 A ide S 44.14 100
34189474 R hde 100
34189475 A jde S 44.14 100
34189476 R ide 100
34189476 A kde S 44.14 100
34189477 R jde 100
34189477 A lde S 44.14 100
34189478 R kde 100
34189478 A mde S 44.15 100
34189480 A nde B 44.04 100
34189481 R cde 100
34189481 A ode S 44.22 100
34189481 R zce 100
34189490 R nde 100
34189522 A pde S 44.22 100
34189523 R ode 100
34189523 A qde B 44.05 100
34189553 A rde S 44.22 100
34189554 R pde 100
34190793 R ede 100
34190794 R lde 100
34190794 A sde B 44.09 100
34190794 A tde S 44.15 100
34190795 R gde 100
34190795 R mde 100
34190795 A ude B 44.12 100
34190795 A vde S 44.14 100
34190796 R fde 200
34190797 R vde 100
34190797 A wde S 44.15 100
34190801 A xde S 44.17 200
34190808 R wde 100
34190808 A yde S 44.15 100
34190809 A zde S 44.16 200
34190838 A aee B 44.05 100
34190839 R qde 100
34190843 R ude 100
34190843 R vbe 100
34190848 R yde 100
34190848 A bee B 44.09 100
34190848 A cee S 44.14 100
34190849 R sde 100
34190849 A dee B 44.10 100
34190849 R tde 100
34190850 A eee S 44.14 100
34190850 R bee 100
34190850 R zde 200
34190851 A fee S 44.15 200
34190851 A gee B 44.10 100
34190851 R dee 100
34190852 A hee B 44.10 100
34190852 R gee 100
34190852 A iee B 44.10 100
34190853 R hee 100
34190853 A jee B 44.10 100
34190854 R iee 100
34190854 A kee B 44.10 100
34190855 R jee 100
34190855 A lee B 44.10 100
34190856 R kee 100
34190856 A mee B 44.10 100
34190857 R lee 100
34190857 A nee B 44.10 100
34190857 R fee 200
34190857 A oee S 44.15 200
34190858 R mee 100
34190858 R cee 100
34190858 A pee B 44.11 100
34190858 A qee S 44.14 100
34190858 R oee 200
34190859 A ree S 44.15 200
34190859 R nee 100
34190859 R eee 100
34190859 A see B 44.11 100
34190859 A tee S 44.14 100
34190860 R pee 100
34190860 A uee B 44.11 100
34190861 R see 100
34190861 A vee B 44.11 100
34190867 R qee 100
34190867 A wee S 44.14 100
34190868 R uee 100
34190868 A xee B 44.11 100
34190869 R tee 100
34190869 A yee S 44.14 100
34190869 R vee 100
34190869 A zee B 44.05 100
34190869 A afe B 44.11 100
34190870 R aee 100
34190870 R xee 100
34190870 A bfe B 44.11 100
34190871 R wee 100
34190871 A cfe S 44.15 100
34190872 R afe 100
34190872 A dfe B 44.11 100
34190873 R bfe 100
34190873 A efe B 44.12 100
34190879 R xde 200
34190888 A ffe S 44.21 100
34190888 R rde 100
34190889 R zee 100
34190897 R dfe 100
34190897 A gfe B 44.09 100
34190918 R ffe 100
34190928 A hfe B 44.04 100
34190929 A ife B 44.04 100
34190930 R hfe 100
34190948 A jfe S 44.21 100
34190949 A kfe S 44.21 100
34190950 R jfe 100
34191047 A lfe S 44.21 100
34191048 R kfe 100
34194398 A mfe B 44.04 100
34194398 R ife 100
34194454 A nfe B 44.05 100
34194455 R mfe 100
34194636 A ofe B 44.12 200
34194637 R gfe 100
34194637 R ree 200
34194638 A pfe B 44.12 100
34194639 R efe 100
34194639 A qfe B 44.12 100
34194689 A rfe B 44.05 100
34194689 R nfe 100
34194719 A sfe B 44.05 100
34194720 R rfe 100
34195788 R pfe 100
34195789 A tfe B 44.12 100
34195805 R qfe 100
34195805 A ufe B 44.12 100
34195805 R yee 100
34195805 A vfe S 44.15 100
34195806 R cfe 100
34195806 A wfe S 44.19 200
34195806 A xfe S 44.16 100
34195806 A yfe B 44.12 100
34195806 R tfe 100
34195806 R ufe 100
34195807 A zfe B 44.13 100
34195808 A age S 44.14 100
34195817 R lfe 100
34195818 R xfe 100
34195819 A bge S 44.15 100
34195819 R yfe 100
34195819 A cge B 44.09 100
34195819 R zfe 100
34195819 A dge B 44.12 100
34195820 R vfe 100
34195820 A ege S 44.14 100
34195822 R age 100
34195839 A fge B 44.05 100
34195839 R sfe 100
34195846 A gge S 44.22 100
34195848 A hge S 44.21 100
34195848 R gge 100
34195849 R hge 100
34195876 A ige B 44.05 100
34195877 R fge 100
34195905 A jge S 44.22 100
34198158 R jge 100
34198159 A kge B 44.05 100
34198159 R ige 100
34198188 A lge S 44.22 100
34198278 A mge S 44.14 500
34198318 A nge S 44.22 100
34198318 R lge 100
34198348 A oge S 44.22 100
34198348 R nge 100
34199851 R dge 100
34199852 A pge B 44.13 100
34199859 R ege 100
34199859 A qge S 44.15 100
34199892 A rge B 44.05 100
34199892 R kge 100
34199923 A sge B 44.06 100
34199923 R rge 100
34199929 R oge 100
34199954 A tge B 44.06 100
34199954 R sge 100
34199959 A uge S 44.22 100
34199966 R mge 120
34199969 A vge B 44.11 100
34199988 R qge 100
34199988 R bge 100
34199988 A wge S 44.16 100
34199988 A xge S 44.15 100
34199988 R cge 100
34199989 A yge B 44.11 100
34199998 R wge 100
34199998 A zge S 44.15 100
34199999 R zge 100
34199999 A ahe S 44.16 100
34200004 A bhe S 44.14 100
34200007 R ahe 100
34200008 A che S 44.15 100
34200010 A dhe B 44.06 100
34200010 R che 100
34200010 R tge 100
34200011 A ehe S 44.16 100
34200011 A fhe S 44.22 100
34200011 R uge 100
34200013 A ghe B 44.13 100
34200014 R pge 100
34200014 A hhe B 44.13 100
34200023 R vge 100
34200032 R ghe 100
34200041 A ihe B 44.06 100
34200041 R dhe 100
34200042 R hhe 100
34200043 A jhe B 44.13 100
34200044 R ehe 100
34200044 A khe S 44.15 100
34200046 A lhe B 44.13 100
34200049 R xge 100
34200049 A mhe B 44.11 100
34200050 A nhe S 44.15 100
34200050 R jhe 100
34200050 R yge 100
34200051 A ohe B 44.11 100
34200051 R lhe 100
34200051 R mhe 100
34200052 R nhe 100
34200052 A phe B 44.13 100
34200052 A qhe S 44.14 100
34200053 R phe 100
34200053 A rhe B 44.11 100
34200054 R bhe 100
34200055 A she S 44.14 100
34200071 R ihe 100
34200075 R khe 100
34200075 A the S 44.15 100
34200076 R ohe 100
34200076 A uhe B 44.11 100
34200083 A vhe S 44.22 100
34200083 R fhe 100
34200092 R vhe 100
34200101 A whe B 44.05 100
34200123 A xhe S 44.22 100
34200126 A yhe S 55.20 140
34200129 A zhe S 44.22 100
34200130 R xhe 100
34200230 R qhe 100
34200230 R she 100
34200231 R rhe 100
34200231 A aie B 44.11 100
34200231 A bie S 44.14 100
34200232 R uhe 100
34200232 A cie B 44.11 100
34200232 R aie 100
34200232 A die B 44.13 100
34200233 R the 100
34200234 A eie S 44.15 100
34200238 R mge 380
34200249 R eie 100
34200249 A fie S 44.16 100
34200265 R bie 100
34200269 A gie S 44.17 100
34200271 R gie 100
34200272 A hie B 44.05 100
34200272 A iie S 44.17 200
34200272 R whe 100
34200272 R wfe 200
34200273 A jie S 44.17 200
34200300 R zhe 100
34200302 A kie B 44.05 100
34200303 R hie 100
34200317 R cie 100
34200318 A lie B 44.13 100
34200331 A mie S 44.22 100
34200333 A nie B 44.05 100
34200333 R kie 100
34200350 R mie 100
34200364 A oie B 44.06 100
34200364 R nie 100
34200381 A pie S 44.22 100
34200437 R tfd 200
34200449 R kce 200
34200449 A qie B 44.13 200
34200453 R iie 200
34200454 A rie S 44.18 100
34200455 R rie 100
34200480 R pie 100
34200480 A sie B 44.06 100
34200481 R oie 100
34200509 R fie 100
34200509 A tie S 44.17 100
34200509 A uie S 44.23 100
34200512 A vie B 44.06 100
34200512 R sie 100
34200514 A wie S 44.18 100
34200518 R tie 100
34200519 A xie S 44.16 100
34200522 A yie B 44.11 100
34200523 R xie 100
34200524 A zie S 44.17 100
34200543 A aje B 44.06 100
34200543 R vie 100
34200543 A bje B 44.13 100
34200544 R lie 100
34200544 R die 100
34200544 A cje B 44.13 100
34200544 A dje B 44.13 100
34200545 R qie 200
34200545 A eje B 44.13 200
34200546 R bje 100
34200546 R dje 100
34200546 R cje 100
34200546 A fje B 44.13 100
34200546 A gje B 44.13 100
34200548 R uie 100
34200573 A hje B 44.07 100
34200574 R aje 100
34200579 A ije S 44.23 100
34200588 R eje 200
34200588 A jje B 44.13 200
34200601 A kje B 44.13 100
34200602 R gje 100
34200602 R fje 100
34200602 A lje B 44.13 100
34200603 A mje B 44.13 100
34200605 A nje B 44.07 100
34200605 R hje 100
34200609 R kje 100
34200626 A oje B 39.60 45
34200635 A pje B 44.07 100
34200636 R nje 100
34200672 A qje B 44.07 100
34200672 R pje 100
34200673 A rje B 44.14 100
34200674 R mje 100
34200674 A sje B 44.14 100
34200674 R lje 100
34200675 A tje B 44.14 100
34200677 A uje B 44.13 100
34200677 R uje 100
34200680 A vje B 44.14 100
34200682 R rje 100
34200683 A wje B 44.14 100
34200704 A xje B 44.07 100
34200704 R qje 100
34200722 R wje 100
34200723 R vje 100
34200837 R yie 100
34200839 R sje 100
34200839 A yje B 44.13 100
34200859 R xje 100
34200861 A zje S 44.17 100
34200868 R zje 100
34200868 A ake S 44.16 100
34200869 R zie 100
34200870 A bke S 44.16 100
34200884 A cke S 56.16 5
34200885 A dke S 48.00 100
34200885 A eke S 55.16 3
34200885 A fke S 46.61 200
34200885 A gke S 48.60 3
34200886 A hke S 45.42 3
34200886 A ike S 47.30 100
34200886 A jke S 54.22 1
34200886 A kke S 52.56 100
34200887 A lke S 45.36 10
34200890 A mke B 44.07 100
34200900 R mke 100
34200904 A nke S 54.00 20
34200904 A oke S 50.28 100
34200904 A pke S 50.79 100
34200905 A qke S 51.60 50
34200905 A rke S 51.26 2
34200905 A ske S 55.80 3
34200906 A tke S 47.40 14
34200906 A uke S 72.00 90
34200906 A vke S 51.60 20
34200907 A wke S 45.84 10
34200907 A xke S 72.00 25
34200907 A yke S 46.56 100
34200908 A zke S 45.12 100
34200908 A ale S 49.44 70
34200909 A ble S 54.60 35
34200909 A cle S 57.00 1
34200909 A dle S 55.20 15
34200910 A ele S 49.32 30
34200910 A fle S 47.94 40
34200911 A gle S 44.41 145
34200911 A hle S 44.23 100
34200911 R ije 100
34200924 A ile S 44.77 100
34200924 A jle S 48.12 200
34200924 A kle S 44.37 200
34200925 A lle S 44.52 200
34200925 A mle S 44.37 100
34200925 A nle S 44.49 100
34200926 A ole S 45.26 100
34200926 A ple B 42.84 30
34200927 A qle B 39.34 40
34200927 A rle B 36.90 15
34200927 A sle B 40.50 15
34200939 A tle B 44.06 100
34200944 A ule B 39.64 15
34200944 A vle B 39.66 10
34200944 A wle B 42.00 20
34200944 A xle B 39.96 1
34200945 A yle B 40.80 5
34200945 A zle B 38.88 1
34200945 A ame B 41.40 14
34200945 A bme B 39.00 100
34200946 A cme B 36.25 4
34200946 A dme B 0.12 1
34200946 A eme B 43.02 3
34200946 A fme B 43.32 100
34200947 A gme B 43.20 35
34200947 A hme B 42.00 35
34200947 A ime B 43.08 15
34200947 A jme B 41.88 15
34200948 A kme B 40.54 3
34200948 A lme B 43.02 11
34200948 A mme B 37.32 1
34200948 A nme B 39.60 2
34200964 A ome B 43.20 100
34200964 A pme B 43.80 100
34200964 A qme B 44.15 2
34200964 A rme B 41.22 15
34200965 A sme B 41.22 15
34200965 R ake 100
34200965 A tme B 40.92 200
34200965 A ume S 44.17 100
34200985 A vme S 44.23 100
34200985 R hle 100
34201073 R qme 2
34201074 R ume 100
34201074 A wme S 44.16 100
34201100 R tje 100
34201100 A xme B 44.13 100
34201101 R jje 200
34201101 R bke 100
34201102 R yje 100
34201102 A yme S 44.16 100
34201102 A zme B 44.13 100
34201102 A ane B 44.09 200
34201103 R xme 100
34201103 R wme 100
34201103 A bne B 44.13 100
34201104 A cne S 44.15 100
34201104 A dne B 44.11 100
34201158 A ene S 44.15 72
34201158 R bne 100
34201159 A fne B 44.13 100
34201162 R wie 100
34201178 R zme 100
34201178 A gne B 44.13 100
34201194 A hne B 42.90 100
34201198 R ene 72
34201356 A ine B 44.13 100
34201359 A jne B 44.13 100
34201391 R dne 100
34201440 R yme 100
34201440 A kne S 44.15 100
34201454 R kne 100
34201456 A lne S 44.16 100
34201479 R ane 200
34201480 A mne B 44.13 200
34201511 R mne 200
34201511 A nne B 44.09 200
34201517 R lne 100
34201518 A one S 44.15 100
34201524 R one 100
34201525 A pne S 44.16 100
34201526 A qne S 44.23 100
34201526 R vme 100
34201559 R nne 200
34201560 R cne 100
34201560 A rne B 44.13 200
34201560 A sne S 44.16 100
34201561 R rne 200
34201562 A tne B 44.09 200
34201592 R tle 100
34201598 R tne 200
34201598 A une B 44.13 200
34201619 R une 200
34201619 A vne B 44.09 200
34201622 A wne B 44.06 100
34201637 A xne S 44.23 100
34201637 R qne 100
34201652 R wne 100
34201670 R xne 100
34201682 A yne B 44.06 100
34201700 A zne S 44.22 100
34201775 A aoe B 41.50 2
34202013 A boe B 44.11 250
34202013 A coe S 44.17 250
34202014 R vne 200
34202014 R jie 200
34202014 A doe B 44.11 200
34202015 A eoe S 44.16 200
34202119 R yne 100
34202129 R fne 100
34202148 A foe B 44.06 100
34202160 R coe 250
34202160 A goe S 44.16 250
34202169 R goe 250
34202169 R foe 100
34202173 A hoe S 44.16 250
34202179 R hoe 250
34202180 A ioe S 44.22 100
34202181 R zne 100
34202181 A joe S 44.16 250
34202190 A koe S 44.16 100
34202191 R pne 100
34202191 R eoe 200
34202192 A loe S 44.16 100
34202192 A moe S 44.16 200
34202192 R sne 100
34202192 A noe S 44.16 100
34202192 R jne 100
34202194 R ine 100
34202195 A ooe B 44.13 100
34202196 R ooe 100
34202199 A poe B 44.06 100
34202203 R koe 100
34202211 A qoe S 44.22 100
34202212 R ioe 100
34202226 A roe B 44.13 100
34202228 A soe B 44.13 100
34202229 R gne 100
34202229 R joe 250
34202230 A toe B 44.13 100
34202230 A uoe B 44.13 100
34202230 R moe 200
34202231 R roe 100
34202231 A voe B 44.13 100
34202231 A woe S 44.19 200
34202232 R soe 100
34202232 A xoe S 44.17 250
34202233 R uoe 100
34202234 R woe 200
34202235 A yoe S 44.16 200
34202235 A zoe B 44.13 100
34202236 A ape B 44.13 100
34202242 A bpe S 44.22 100
34202243 R qoe 100
34202248 R loe 100
34202248 R doe 200
34202248 R toe 100
34202248 A cpe B 44.13 200
34202248 A dpe B 44.13 100
34202248 A epe S 44.16 100
34202249 R voe 100
34202249 A fpe B 44.13 100
34202252 R zoe 100
34202254 R ape 100
34202255 A gpe B 44.13 100
34202257 A hpe B 44.13 100
34202258 R gpe 100
34202258 R hpe 100
34202258 R dpe 100
34202258 A ipe B 44.13 100
34202258 R fpe 100
34202258 A jpe B 44.13 100
34202260 R ipe 100
34202260 A kpe B 44.13 100
34202260 R bpe 100
34202260 R cpe 200
34202261 A lpe B 44.11 200
34202261 A mpe B 44.13 100
34202261 R mpe 100
34202269 R lpe 200
34202269 R jpe 100
34202269 A npe B 44.13 200
34202269 A ope B 44.13 100
34202270 A ppe B 44.06 100
34202271 R poe 100
34202278 R epe 100
34202279 A qpe S 44.16 100
34202291 A rpe S 44.23 100
34202291 A spe S 44.22 100
34202292 R rpe 100
34202301 R spe 100
34202302 A tpe B 44.06 100
34202302 R ppe 100
34202331 A upe S 44.23 100
34202893 A vpe B 44.14 129
34202894 R kpe 100
34202894 R noe 100
34202894 A wpe S 44.16 100
34202895 A xpe B 44.13 100
34202895 R ope 100
34202895 A ype B 44.14 100
34202896 R wpe 100
34202896 R yoe 200
34202896 A zpe S 44.16 100
34202897 R qpe 100
34202900 A aqe S 44.16 100
34202900 R zpe 100
34202901 A bqe S 44.16 100
34202940 A cqe B 44.06 100
34202940 R tpe 100
34202941 R upe 100
34202970 A dqe B 44.06 100
34202971 R cqe 100
34202972 A eqe S 44.23 100
34203010 R boe 250
34203010 A fqe B 44.12 250
34203131 R ype 68
34203166 R ype 32
34203166 R vpe 68
34203173 A gqe B 44.13 100
34203179 A hqe S 44.16 200
34203209 A iqe S 44.23 100
34203209 R eqe 100
34204636 R fqe 250
34204637 A jqe B 44.12 250
34204668 R jqe 250
34204670 A kqe B 44.12 250
34204688 R kqe 250
34204690 A lqe B 44.12 250
34204698 R lqe 250
34204698 A mqe B 44.12 250
34204717 R mqe 250
34204719 A nqe B 44.12 250
34204728 A oqe B 44.14 134
34204728 R hqe 200
34204738 R nqe 250
34204739 A pqe B 44.12 250
34204809 A qqe B 42.00 100
34205166 A rqe B 44.14 100
34205169 A sqe B 44.14 100
34205169 R sqe 100
34205205 A tqe B 44.14 100
34205260 A uqe S 44.15 72
34205280 R gqe 100
34205281 A vqe B 44.13 100
34205312 R vpe 61
34205312 R oqe 39
34205317 R pqe 250
34205319 A wqe B 44.12 250
34205333 A xqe S 44.16 100
34205334 R xpe 100
34205334 A yqe B 44.13 100
34205334 R bqe 100
34205336 R vqe 100
34205336 A zqe B 44.13 100
34205336 A are S 44.15 100
34205337 R yqe 100
34205337 A bre B 44.13 100
34205337 R aqe 100
34205338 A cre S 44.16 100
34205338 R zqe 100
34205338 A dre B 44.13 100
34205348 R bre 100
34205348 A ere B 44.13 100
34205514 R oqe 95
34205514 R rqe 100
34205514 R tqe 5
34205515 R tqe 95
34205515 R ere 100
34205515 A fre B 44.13 100
34205516 R npe 200
34205516 A gre B 44.12 200
34205539 R xoe 250
34205539 A hre S 44.16 250
34205539 R xqe 100
34205560 A ire S 44.23 100
34205560 R iqe 100
34205591 A jre S 44.23 100
34205591 R ire 100
34205649 A kre S 44.15 100
34205651 R kre 100
34205850 A lre S 44.15 100
34205875 R dre 100
34205875 R fre 100
34205876 R are 100
34205876 R cre 100
34205876 A mre S 44.16 200
34205876 A nre S 44.15 100
34205877 A ore S 44.15 100
34205879 R lre 100
34205880 R ore 100
34205881 A pre S 44.14 100
34205881 A qre S 44.15 100
34205882 R nre 100
34205882 A rre S 44.14 100
34205883 R pre 100
34205883 R gre 200
34205883 A sre B 44.09 200
34205884 A tre S 44.14 100
34205884 R qre 100
34205885 R rre 100
34205885 A ure S 44.14 100
34205886 R sre 200
34205886 A vre B 44.12 200
34205886 A wre S 44.14 100
34205886 R tre 100
34205887 A xre S 44.14 100
34205887 R vre 200
34205887 A yre B 44.09 200
34205888 R wre 100
34205899 R wqe 250
34205900 R ure 100
34205900 A zre S 44.14 100
34205901 A ase B 44.11 250
34205902 R xre 100
34205902 A bse S 44.14 100
34205902 R yre 200
34205903 A cse B 44.11 200
34205903 R zre 100
34205903 A dse S 44.14 100
34205904 R bse 100
34205904 A ese S 44.13 100
34205905 R dse 100
34205905 A fse S 44.13 100
34205905 R ese 100
34205905 A gse S 44.16 100
34205926 A hse S 44.14 100
34205926 R hse 100
34205930 R dqe 100
34205931 A ise S 44.22 100
34205931 R jre 100
34205961 A jse B 44.04 100
34205963 A kse S 44.22 100
34205963 R ise 100
34205964 R ofe 100
34205965 A lse S 44.13 100
34205965 R lse 100
34205966 A mse S 44.13 100
34205966 R gse 100
34205967 R fse 100
34205967 A nse S 44.13 100
34205971 A ose S 44.13 100
34205971 R ose 100
34205972 R mse 100
34205972 A pse S 44.13 100
34205972 A qse B 44.09 200
34205972 R cse 200
34205973 R nse 100
34205973 A rse S 44.13 100
34205973 R qse 200
34205974 A sse B 44.11 200
34205974 R pse 100
34205974 A tse S 44.16 100
34205986 A use S 44.15 72
34206016 A vse S 44.22 100
34206017 R kse 100
34206028 R hre 250
34206028 A wse S 44.15 250
34206029 R tse 100
34206029 A xse S 44.15 100
34206030 R mre 200
34206030 A yse S 44.15 200
34206032 A zse S 44.13 100
34206047 A ate S 44.22 100
34206047 R vse 100
34206049 R wse 250
34206051 A bte S 44.15 250
34206052 R zse 100
34206053 A cte S 44.13 100
34206055 R cte 100
34206057 A dte S 44.13 100
34206058 R dte 100
34206060 A ete S 44.13 100
34206062 R ete 100
34206077 A fte S 44.21 100
34206078 R ate 100
34206079 R uqe 72
34206079 R use 72
34206080 A gte S 44.15 72
34206080 A hte S 44.15 72
34206081 R gte 72
34206081 R hte 72
34206082 A ite S 44.14 72
34206082 A jte S 44.14 72
34206083 R xse 100
34206083 A kte S 44.14 100
34206092 R ite 72
34206092 R jte 72
34206093 A lte S 44.14 72
34206093 A mte S 44.14 72
34206094 R lte 72
34206094 R mte 72
34206095 A nte S 44.14 72
34206095 A ote S 44.14 72
34206096 R kte 100
34206096 A pte S 44.14 100
34206099 R bte 250
34206101 A qte S 44.15 250
34206108 R sse 200
34206108 A rte S 44.21 100
34206108 A ste B 44.09 200
34206108 R fte 100
34206109 R pte 100
34206109 A tte S 44.13 100
34206111 A ute S 44.13 100
34206112 R ute 100
34206136 R nte 72
34206136 R ote 72
34206137 A vte S 44.14 72
34206137 A wte S 44.14 72
34206138 R vte 72
34206138 R wte 72
34206139 A xte S 44.14 72
34206139 A yte S 44.14 72
34206139 A zte S 44.21 100
34206139 R rte 100
34206146 A aue S 44.13 100
34206146 R aue 100
34206169 A bue S 44.20 100
34206169 R zte 100
34206172 R tte 100
34206172 R rse 100
34206172 A cue B 44.13 1100
34206173 R ste 200
34206173 A due B 44.11 200
34206173 A eue S 44.14 100
34206173 A fue S 44.14 100
34206173 A gue B 44.11 100
34206173 A hue B 44.11 100
34206181 R xte 72
34206181 R yte 72
34206182 A iue S 44.13 72
34206183 A jue S 44.13 72
34206183 R fue 100
34206184 A kue S 44.13 100
34206185 R cue 100
34206192 R iue 72
34206192 R jue 72
34206193 A lue S 44.13 72
34206194 A mue S 44.13 72
34206194 R lue 72
34206194 A nue B 44.13 100
34206195 A oue S 44.13 72
34206195 R mue 72
34206196 A pue S 44.13 72
34206196 R oue 72
34206198 R pue 72
34206199 A que S 44.20 100
34206200 R bue 100
34206200 R cue 1000
34206201 R eue 100
34206201 R kue 56
34206220 R kue 44
34206220 R yse 200
34206220 A rue S 44.15 44
34206220 R qte 250
34206220 R gue 100
34206221 A sue B 44.13 100
34206221 A tue S 44.19 200
34206221 R hue 100
34206222 A uue B 44.13 100
34206222 R nue 100
34206222 A vue S 44.16 250
34206223 R tue 200
34206224 A wue S 44.16 200
34206237 A xue S 44.15 100
34206238 R sue 100
34206238 A yue B 44.13 100
34206239 R rue 44
34206239 R uue 100
34206239 A zue B 44.11 100
34206239 A ave B 44.05 100
34206239 A bve S 44.15 44
34206239 R xue 100
34206239 A cve S 44.14 100
34206240 A dve B 44.12 100
34206240 R yue 100
34206240 R jse 100
34206240 R bve 44
34206241 A eve S 44.14 44
34206241 R dve 100
34206241 A fve B 44.11 100
34206242 R cve 100
34206243 R zue 100
34206243 A gve B 44.11 100
34206245 A hve B 44.13 100
34206246 R fve 100
34206246 A ive B 44.11 100
34206246 R gve 100
34206247 A jve B 44.13 100
34206247 R hve 100
34206249 R que 100
34206259 R jve 100
34206259 A kve B 44.11 100
34206260 R ive 100
34206261 A lve B 44.11 100
34206270 R kve 100
34206270 A mve B 44.13 100
34206272 A nve B 44.05 100
34206272 R ave 100
34206279 A ove S 44.22 100
34206281 R vue 250
34206283 A pve S 44.17 250
34206286 A qve B 44.13 100
34206286 R qve 100
34206288 R pve 250
34206288 A rve S 44.16 250
34206289 A sve S 44.22 100
34206290 R ove 100
34206290 R sve 100
34206302 A tve B 44.05 100
34206303 R nve 100
34206325 A uve B 44.13 100
34206325 R uve 100
34206327 A vve B 44.13 100
34206329 A wve S 44.22 100
34206330 R rve 250
34206333 A xve S 44.17 250
34206348 A yve S 44.17 600
34206366 R xve 250
34206367 A zve S 44.16 250
34206379 R wue 200
34206380 A awe S 44.17 200
34206380 R ase 250
34206380 A bwe B 44.11 250
34206381 R due 200
34206381 A cwe B 44.11 200
34206390 R zve 250
34206393 A dwe S 44.17 250
34206393 R awe 200
34206394 A ewe S 44.16 200
34206411 R wve 100
34206412 A fwe B 44.05 100
34206413 R tve 100
34206439 R eve 44
34206439 A gwe S 44.16 100
34206440 R lve 100
34206440 A hwe B 44.13 100
34206441 A iwe S 44.23 100
34206442 R vve 100
34206443 R mve 100
34206443 A jwe B 44.13 100
34206443 A kwe B 44.05 100
34206444 R fwe 100
34206444 R hwe 100
34206444 A lwe B 44.13 100
34206444 A mwe B 44.13 100
34206445 R jwe 100
34206445 A nwe B 44.13 100
34206446 R mwe 100
34206447 R lwe 100
34206447 A owe B 44.13 100
34206486 A pwe B 44.13 100
34206486 R pwe 100
34206487 A qwe B 44.13 100
34206512 A rwe B 44.05 100
34206512 R kwe 100
34206530 A swe S 44.23 100
34206530 R iwe 100
34206543 A twe B 44.06 100
34206544 R rwe 100
34206575 A uwe B 44.06 100
34206575 R twe 100
34206904 A vwe S 44.15 72
34206905 R owe 100
34206905 A wwe B 44.13 100
34206943 R nwe 100
34206943 A xwe B 44.13 100
34206963 A ywe S 44.15 72
34206964 R wwe 100
34206964 A zwe B 44.13 100
34206977 R uwe 100
34206993 R qwe 100
34206999 R gwe 100
34206999 A axe S 44.15 100
34207000 R xwe 100
34207000 R zwe 100
34207000 A bxe B 44.12 100
34207001 A cxe B 44.13 100
34207002 A dxe S 44.15 100
34207005 R dxe 100
34207007 A exe B 44.06 100
34207009 R axe 100
34207010 A fxe S 44.16 100
34207010 R bxe 100
34207010 A gxe B 44.13 100
34207014 A hxe B 44.11 100
34207014 A ixe S 44.18 100
34207015 A jxe B 44.13 100
34207016 R cxe 100
34207016 A kxe B 44.13 100
34207018 R jxe 100
34207020 A lxe B 44.13 100
34207020 R gxe 100
34207020 A mxe B 44.13 100
34207022 A nxe B 44.06 100
34207022 R exe 100
34207023 R lxe 100
34207025 R vwe 72
34207025 R ywe 72
34207025 A oxe B 44.15 649
34207026 R fxe 100
34207026 R kxe 100
34207026 R ewe 200
34207026 A pxe B 44.13 100
34207028 A qxe S 44.16 100
34207028 R mxe 100
34207029 A rxe B 44.13 100
34207029 R hxe 100
34207030 R pxe 100
34207030 A sxe B 44.13 100
34207030 A txe B 44.15 100
34207031 R rxe 100
34207031 R txe 100
34207031 A uxe B 44.13 100
34207032 R sxe 100
34207032 A vxe B 44.13 100
34207033 A wxe B 44.15 100
34207033 R uxe 100
34207033 A xxe B 44.14 100
34207035 R wxe 100
34207035 R vxe 100
34207036 A yxe B 44.14 100
34207036 R xxe 100
34207037 A zxe B 44.14 100
34207037 R yxe 100
34207038 A aye B 44.14 100
34207039 R zxe 100
34207039 A bye B 44.14 100
34207040 R aye 100
34207040 A cye B 44.14 100
34207041 A dye B 44.15 100
34207041 R dye 100
34207042 R nxe 100
34207044 A eye B 44.15 100
34207046 R eye 100
34207057 R oxe 649
34207058 R bye 100
34207058 R cye 100
34207058 A fye B 44.13 100
34207058 A gye B 44.13 100
34207058 R qxe 100
34207059 A hye S 44.16 200
34207059 A iye S 44.16 100
34207060 A jye B 44.13 100
34207061 A kye B 44.11 100
34207071 A lye B 44.06 100
34207081 R bwe 250
34207081 A mye B 44.12 250
34207082 R mye 250
34207085 A nye B 44.11 250
34207089 R cwe 200
34207090 A oye B 44.13 200
34207091 R gye 100
34207091 A pye B 44.13 100
34207091 R fye 100
34207092 A qye B 44.13 100
34207092 R jye 100
34207094 A rye B 44.13 100
34207099 R oye 200
34207099 A sye B 44.11 200
34207110 R sye 200
34207110 A tye B 44.11 200
34207111 R lye 100
34207114 R tye 200
34207114 A uye B 44.11 200
34207117 R kye 100
34207117 A vye B 44.11 100
34207120 R swe 100
34207130 R iye 100
34207131 A wye S 44.16 100
34207132 R wye 100
34207132 A xye S 44.16 100
34207134 R vye 100
34207137 R nye 250
34207137 A yye B 44.13 250
34207138 R qye 100
34207139 R rye 100
34207139 A zye B 44.13 100
34207139 R pye 100
34207139 A aze B 44.13 100
34207140 A bze B 44.06 100
34207141 A cze B 44.06 100
34207141 A dze B 44.13 100
34207141 R xye 100
34207141 R bze 100
34207142 A eze S 44.16 100
34207143 R dze 100
34207145 A fze B 44.13 100
34207145 A gze B 44.11 100
34207147 R gze 100
34207147 A hze B 44.11 100
34207149 R eze 100
34207149 A ize S 44.16 100
34207150 A jze S 44.23 100
34207159 R ize 100
34207160 A kze S 44.16 100
34207161 R jze 100
34207169 R kze 100
34207169 A lze S 44.16 100
34207174 R hze 100
34207174 R ixe 100
34207175 A mze S 44.16 100
34207179 A nze B 44.07 100
34207179 R cze 100
34207180 R mze 100
34207180 R lze 100
34207180 A oze S 44.16 100
34207180 A pze S 44.16 100
34207180 R hye 200
34207180 R nze 100
34207182 A qze S 44.17 200
34207183 A rze B 44.11 100
34207184 A sze S 44.18 100
34207184 R rze 100
34207184 R sze 100
34207188 R oze 100
34207188 R pze 100
34207188 R qze 200
34207189 A tze S 44.16 200
34207189 A uze S 44.16 100
34207189 A vze S 44.16 100
34207191 A wze B 44.11 100
34207192 A xze S 44.18 100
34207192 A yze S 44.23 100
34207192 R vze 100
34207193 A zze S 44.16 100
34207193 R xze 100
34207199 R zze 100
34207200 A aaf S 44.16 100
34207201 A baf S 44.23 100
34207201 R yze 100
34207210 A caf B 44.06 100
34207211 A daf B 44.07 100
34207212 R caf 100
34207212 R baf 100
34207218 R daf 100
34207243 A eaf S 44.23 100
34207257 A faf B 44.06 100
34207354 A gaf S 44.15 72
34207355 R aze 100
34207356 A haf B 44.13 100
34207357 R fze 100
34207369 R zye 100
34207369 A iaf B 44.13 100
34207401 R faf 100
34207421 A jaf S 44.23 100
34207421 R eaf 100
34207431 A kaf B 44.06 100
34207451 A laf S 44.23 100
34207452 R jaf 100
34207492 A maf S 44.15 100
34207493 R haf 100
34207494 A naf B 44.13 100
34207510 R wze 100
34207510 A oaf B 44.11 200
34207520 R dwe 250
34207520 A paf S 44.16 250
34207521 R tze 200
34207522 A qaf S 44.16 200
34207538 R qaf 200
34207539 A raf S 44.17 200
34207539 R paf 250
34207540 R raf 200
34207541 A saf S 44.16 200
34207542 A taf S 44.16 250
34207543 R maf 100
34207543 R kaf 100
34207543 A uaf S 44.23 100
34207543 R laf 100
34207545 A vaf S 44.15 100
34207548 R saf 200
34207548 A waf S 44.17 200
34207550 R taf 250
34207552 A xaf S 44.16 250
34207555 R gaf 72
34207555 R vaf 100
34207555 A yaf B 44.15 472
34207556 R yye 250
34207556 R iaf 100
34207556 R uze 100
34207556 R naf 100
34207557 R uye 200
34207557 A zaf B 44.13 100
34207557 A abf B 44.13 200
34207557 A bbf B 44.13 100
34207557 R aaf 100
34207557 A cbf S 44.17 100
34207557 A dbf S 44.17 100
34207558 R zaf 100
34207558 A ebf B 44.13 100
34207559 R bbf 100
34207559 A fbf B 44.13 100
34207559 A gbf B 44.11 250
34207560 R oaf 200
34207560 R xaf 250
34207561 R ebf 100
34207561 A hbf B 44.13 100
34207563 A ibf S 44.17 250
34207564 R fbf 100
34207564 R cbf 100
34207564 A jbf B 44.14 100
34207564 A kbf S 44.16 100
34207565 R hbf 100
34207565 A lbf B 44.14 100
34207566 R jbf 100
34207566 A mbf B 44.14 100
34207566 R yaf 53
34207567 R lbf 100
34207567 A nbf B 44.14 100
34207572 A obf B 44.06 100
34207575 A pbf S 44.22 100
34207575 R uaf 100
34207595 R yaf 419
34207596 R nbf 100
34207596 R abf 200
34207596 R dbf 100
34207597 A qbf B 44.11 200
34207597 A rbf B 44.13 100
34207597 R waf 200
34207597 A sbf S 44.16 200
34207597 A tbf S 44.16 100
34207606 R mbf 100
34207606 R kbf 100
34207606 A ubf B 44.13 100
34207607 A vbf S 44.16 100
34207608 R ubf 100
34207608 A wbf B 44.13 100
34207609 A xbf B 44.11 100
34207620 R gbf 250
34207621 A ybf B 44.12 250
34207621 R rbf 100
34207621 A zbf B 44.13 100
34207622 A acf B 44.12 200
34207622 R qbf 200
34207623 A bcf B 44.13 100
34207623 R wbf 100
34207624 A ccf B 44.13 100
34207624 R zbf 100
34207625 R bcf 100
34207626 A dcf B 44.13 100
34207631 R ccf 100
34207631 A ecf B 44.13 100
34207631 R tbf 100
34207632 A fcf S 44.16 100
34207632 R dcf 100
34207632 A gcf B 44.13 100
34207641 R ybf 250
34207643 R xbf 100
34207643 A hcf B 44.11 250
34207650 R fcf 100
34207650 A icf S 44.16 100
34207652 R ecf 100
34207652 R gcf 100
34207652 A jcf B 44.13 100
34207652 A kcf B 44.13 100
34207656 A lcf B 44.11 100
34207658 A mcf B 44.06 100
34207659 R obf 100
34207659 R pbf 100
34207660 R acf 200
34207661 A ncf B 44.13 200
34207661 R kcf 100
34207662 A ocf B 44.13 100
34207662 R jcf 100
34207662 A pcf B 44.13 100
34207663 R lcf 100
34207664 A qcf B 44.11 200
34207669 R hcf 250
34207669 A rcf B 44.12 250
34207670 R mcf 100
34207670 R ncf 200
34207670 A scf B 44.11 200
34207673 R qcf 200
34207674 A tcf S 44.18 200
34207679 R scf 200
34207679 A ucf B 44.13 200
34207690 A vcf S 44.22 100
34207692 R vcf 100
34207694 A wcf B 44.14 200
34207695 R icf 100
34207696 A xcf S 44.16 100
34207698 A ycf S 44.16 100
34207699 A zcf B 44.06 100
34207710 A adf B 44.06 100
34207710 R zcf 100
34207722 A bdf S 44.23 100
34207724 R wcf 170
34207725 R vbf 100
34207725 A cdf S 44.16 100
34207728 R wcf 30
34207729 R ycf 100
34207729 A ddf B 44.11 100
34207729 R xcf 100
34207730 A edf S 44.16 100
34207732 R rcf 250
34207732 A fdf B 44.13 250
34207732 A gdf B 44.13 100
34207733 R pcf 100
34207733 A hdf B 44.13 100
34207734 R ocf 100
34207734 R gdf 100
34207734 A idf B 44.13 100
34207739 R fdf 250
34207741 A jdf B 44.12 250
34207752 A kdf B 44.06 100
34207753 R adf 100
34207765 A ldf B 44.14 200
34207766 A mdf S 44.16 100
34207766 R edf 100
34207766 A ndf S 44.16 100
34207832 R mdf 100
34207848 R ldf 200
34207849 R ndf 100
34207849 A odf S 44.16 100
34207869 R odf 100
34207869 A pdf S 44.16 100
34207871 A qdf S 44.16 100
34207900 A rdf B 44.07 100
34207900 R kdf 100
34207907 R qdf 100
34207921 R cdf 100
34207921 R sbf 200
34207922 A sdf S 44.16 100
34207922 A tdf S 44.17 200
34207923 A udf B 44.13 100
34207925 A vdf B 44.13 100
34207925 R vdf 100
34207925 R udf 100
34207928 A wdf B 44.13 100
34207930 R wdf 100
34207937 A xdf B 44.14 100
34207940 R idf 100
34207940 R sdf 100
34207940 A ydf B 44.14 100
34207941 A zdf S 44.16 100
34207942 R ddf 100
34207942 R tcf 200
34207942 A aef B 44.11 100
34207952 A bef B 44.07 100
34207953 R rdf 100
34207966 A cef B 44.13 100
34207966 R cef 100
34207966 A def B 44.14 100
34207967 R jdf 250
34207967 R zdf 100
34207967 R xdf 100
34207967 A eef S 44.16 100
34207969 A fef B 44.12 250
34207970 R bdf 100
34207972 A gef B 44.14 100
34207972 R def 100
34207972 R gef 100
34207973 R tdf 200
34207973 A hef S 44.16 200
34207984 R fef 250
34207984 A ief B 44.12 250
34207990 R ief 250
34207990 R hef 200
34207992 A jef B 44.12 250
34208000 A kef S 44.23 100
34208002 A lef S 44.23 100
34208002 R kef 100
34208006 A mef B 44.14 100
34208006 R mef 100
34208006 A nef B 44.14 100
34208011 A oef B 44.14 100
34208022 R ydf 100
34208022 A pef B 44.13 100
34208023 A qef S 44.16 200
34208024 R jef 250
34208026 A ref B 44.12 250
34208040 R hdf 100
34208040 A sef B 44.13 100
34208040 R qef 200
34208041 R pef 100
34208042 A tef B 44.13 100
34208072 A uef S 44.16 200
34208072 A vef S 44.23 100
34208073 R lef 100
34208074 A wef B 44.07 100
34208074 R bef 100
34208076 R aef 100
34208077 A xef S 44.18 100
34208082 R wef 100
34208085 R oef 100
34208086 R sef 100
34208086 A yef B 44.13 100
34208087 R nef 100
34208088 R pdf 100
34208088 A zef S 44.16 100
34208112 A aff B 44.06 100
34208122 R ref 250
34208122 R ucf 200
34208122 A bff B 44.12 200
34208123 A cff B 44.12 250
34208123 R zef 100
34208123 R eef 100
34208123 A dff S 44.16 100
34208123 A eff S 44.16 100
34208124 R bff 200
34208124 A fff B 44.13 200
34208125 A gff B 44.13 100
34208126 A hff B 44.13 100
34208126 R hff 100
34208127 R gff 100
34208141 R eff 100
34208141 A iff S 44.16 100
34208151 R aff 100
34208151 R dff 100
34208151 R uef 200
34208152 A jff S 44.16 100
34208154 A kff S 44.23 100
34208154 R vef 100
34208154 A lff S 44.17 200
34208157 A mff S 44.16 100
34208166 R lff 200
34208166 A nff B 44.13 100
34208166 R nff 100
34208167 A off B 44.13 100
34208167 R off 100
34208170 R kff 100
34208182 A pff B 44.07 100
34208184 A qff B 44.07 100
34208184 R pff 100
34208200 A rff S 44.23 100
34208206 A sff B 44.13 100
34208206 R sff 100
34208338 R iff 100
34208339 A tff S 44.16 100
34208339 A uff S 44.16 200
34208342 A vff B 44.13 100
34208342 R vff 100
34208370 R mff 100
34208371 R qff 100
34208402 A wff B 44.07 100
34208408 R cff 250
34208408 A xff B 44.13 250
34208446 R tff 100
34208447 R yef 100
34208447 A yff B 44.13 100
34208448 A zff B 44.13 100
34208448 A agf S 44.16 100
34208451 A bgf B 44.13 100
34208452 R bgf 100
34208489 R uff 200
34208492 R yff 100
34208493 A cgf B 44.14 100
34208494 R tef 100
34208494 A dgf B 44.14 100
34208496 A egf B 44.13 100
34208496 R zff 100
34208496 R egf 100
34208499 A fgf B 44.13 100
34208499 R cgf 100
34208501 A ggf B 44.14 100
34208501 A hgf B 44.14 100
34208502 R hgf 100
34208520 R rff 100
34208522 A igf B 44.07 100
34208522 R wff 100
34208531 R igf 100
34208533 R xef 100
34208535 A jgf B 44.14 100
34208551 A kgf S 44.23 100
34208561 A lgf B 44.07 100
34208561 R kgf 100
34208581 R lgf 100
34208592 A mgf S 44.23 100
34208610 R dgf 100
34208610 A ngf B 44.13 100
34208610 A ogf B 44.06 100
34208610 A pgf S 44.16 200
34208613 A qgf B 44.07 100
34208614 R ogf 100
34208620 R fgf 100
34208620 A rgf B 44.13 100
34208621 R ngf 100
34208621 A sgf B 44.13 100
34208630 A tgf S 44.23 100
34208631 R mgf 100
34208639 R qgf 100
34208661 A ugf S 44.23 100
34208661 R tgf 100
34208669 A vgf B 44.07 100
34209323 R jgf 100
34209325 R ggf 100
34209369 A wgf B 44.07 100
34209370 R vgf 100
34209806 R wgf 100
34209835 A xgf B 44.07 100
34209846 A ygf S 44.15 72
34209846 R sgf 100
34209846 R rgf 100
34209847 R jff 100
34209847 A zgf B 44.13 100
34209847 A ahf B 44.13 100
34209847 A bhf S 44.16 100
34209849 A chf B 44.13 100
34209850 R chf 100
34209850 R ygf 72
34209851 A dhf B 44.13 100
34209852 R bhf 100
34209852 A ehf S 44.16 100
34209853 A fhf B 44.13 100
34209853 R dhf 100
34209853 R fhf 100
34209855 A ghf B 44.13 100
34209858 A hhf B 44.13 100
34209861 R ehf 100
34209861 A ihf S 44.16 100
34209868 R xff 250
34209869 R agf 100
34209870 A jhf B 44.12 250
34209870 R ihf 100
34209870 A khf S 44.16 100
34209870 A lhf S 44.16 100
34209871 R jhf 250
34209871 R khf 100
34209871 A mhf S 44.16 100
34209873 A nhf B 44.11 250
34209875 R nhf 250
34209876 A ohf B 44.12 250
34209878 R ibf 250
34209879 A phf S 44.16 250
34209883 R ohf 250
34209885 A qhf B 44.11 250
34209901 A rhf S 44.23 100
34209901 R ugf 100
34209909 R phf 250
34209912 R rhf 100
34209912 A shf S 44.17 250
34209918 R ghf 100
34209918 R hhf 100
34209920 A thf B 44.13 100
34209922 A uhf B 44.13 100
34209922 R thf 100
34209922 R uhf 100
34209925 A vhf B 44.13 100
34209926 R vhf 100
34209928 A whf B 44.13 100
34209930 R whf 100
34209941 A xhf S 44.22 100
34209947 R shf 250
34209947 A yhf S 44.16 250
34209959 R ahf 100
34209959 R mhf 100
34209959 R fff 200
34209959 A zhf B 44.11 200
34209960 A aif B 44.13 100
34209960 A bif S 44.16 100
34209968 R pgf 200
34209969 A cif S 44.17 200
34209969 R lhf 100
34209970 A dif S 44.15 100
34209970 R cif 200
34209971 R bif 100
34209971 A eif S 44.16 200
34209971 A fif S 44.15 100
34209978 R fif 100
34209979 A gif S 44.16 100
34209980 R yhf 250
34209982 A hif S 44.17 250
34209991 A iif B 44.13 100
34209991 R xgf 100
34209991 A jif S 44.18 100
34209992 A kif B 44.13 100
34209996 R eif 200
34209997 A lif S 44.16 200
34210001 A mif S 44.22 100
34210001 R xhf 100
34210021 A nif B 44.05 100
34210037 R qhf 250
34210038 A oif B 44.12 250
34210040 R kif 100
34210042 A pif B 44.13 100
34210043 R pif 100
34210051 A qif B 44.13 100
34210058 R hif 250
34210059 A rif S 44.16 250
34210080 R oif 250
34210082 A sif B 44.12 250
34210086 A tif B 44.13 100
34210087 R iif 100
34210087 R tif 100
34210087 R zhf 200
34210087 A uif B 44.13 200
34210088 R uif 200
34210092 A vif B 44.06 100
34210092 R nif 100
34210099 R rif 250
34210102 A wif S 44.17 250
34210118 R sif 250
34210120 A xif B 44.12 250
34210123 A yif B 44.06 100
34210123 R vif 100
34210126 A zif B 44.13 100
34210126 R zif 100
34210142 R zgf 100
34210143 A ajf B 44.09 200
34210143 A bjf B 44.13 100
34210149 R ajf 200
34210149 A cjf B 44.13 200
34210152 R qif 100
34210152 R jif 100
34210153 A djf B 44.06 100
34210154 R yif 100
34210159 A ejf B 44.13 100
34210180 R mif 100
34210184 A fjf B 44.06 100
34210185 R djf 100
34210208 R gif 100
34210209 A gjf S 44.16 100
34210209 R bjf 100
34210209 A hjf S 44.23 100
34210209 A ijf B 44.14 100
34210210 R dif 100
34210211 A jjf S 44.16 100
34210215 A kjf B 44.06 100
34210215 R fjf 100
34210238 R xif 250
34210240 A ljf B 44.12 250
34210246 A mjf B 44.06 100
34210246 R kjf 100
34210251 R lif 200
34210252 A njf S 44.16 100
34210255 A ojf B 44.15 2200
34210256 R gjf 100
34210256 R jjf 100
34210256 R aif 100
34210257 A pjf B 44.14 100
34210257 R ijf 100
34210258 A qjf B 44.15 100
34210258 A rjf S 44.17 100
34210258 A sjf S 44.16 100
34210265 R ejf 100
34210265 A tjf S 44.18 100
34210269 R tjf 100
34210282 R hjf 100
34210287 R qjf 72
34210287 R wif 250
34210291 A ujf S 44.17 250
34210299 A vjf B 44.06 100
34210300 R mjf 100
34210309 R ljf 250
34210309 A wjf B 44.12 250
34210310 R wjf 250
34210311 R qjf 8
34210312 A xjf S 44.23 100
34210313 A yjf B 44.12 250
34210320 R yjf 250
34210321 A zjf B 44.12 250
34210331 R xjf 100
34210351 R njf 100
34210353 A akf B 44.07 100
34210353 R vjf 100
34210361 A bkf S 44.23 100
34210384 A ckf B 44.07 100
34210384 R akf 100
34210394 R iwd 100
34210395 A dkf S 44.19 200
34210406 A ekf S 44.18 100
34210407 A fkf S 44.16 100
34210408 A gkf S 44.16 32
34210413 R ekf 100
34210413 R gkf 32
34210440 R bkf 100
34210471 A hkf S 44.24 100
34210483 A ikf S 44.24 100
34210484 R hkf 100
34210484 R ckf 100
34210484 R ikf 100
34210495 R fcd 50
34210495 A jkf B 44.16 1046
34210496 R rjf 100
34210496 R pjf 100
34210496 R sjf 100
34210497 A kkf S 44.17 100
34210497 A lkf S 44.19 100
34210497 A mkf B 44.15 100
34210497 R ujf 250
34210498 R kkf 100
34210498 A nkf S 44.19 100
34210499 R lkf 100
34210500 A okf S 44.19 100
34210500 A pkf S 44.18 250
34210500 R nkf 100
34210501 A qkf S 44.18 100
34210502 R okf 100
34210502 A rkf S 44.18 100
34210510 R fkf 100
34210511 R qjf 20
34210511 R qkf 100
34210511 A skf B 44.16 20
34210512 R zjf 250
34210512 R pkf 250
34210512 A tkf S 44.18 100
34210514 A ukf B 44.12 250
34210515 A vkf B 44.07 100
34210515 A wkf S 44.19 250
34210516 A xkf S 44.24 100
34210516 R rkf 100
34210516 A ykf S 44.18 100
34210517 R tkf 100
34210518 A zkf S 44.18 100
34210518 A alf B 44.07 100
34210519 R vkf 100
34210520 R ukf 250
34210521 A blf B 44.12 250
34210527 R skf 20
34210529 R jkf 80
34210529 A clf B 44.15 100
34210538 R jkf 966
34210538 R clf 100
34210538 R mkf 100
34210538 R ojf 1334
34210538 R xkf 100
34210539 R zkf 100
34210539 R ykf 100
34210540 A dlf B 44.15 100
34210540 A elf B 44.13 100
34210540 A flf S 44.18 100
34210540 A glf S 44.17 100
34210541 R wkf 250
34210541 R flf 100
34210541 R dlf 100
34210541 A hlf S 44.18 250
34210541 A ilf B 44.13 100
34210541 A jlf S 44.17 100
34210541 R ojf 500
34210542 R elf 100
34210543 A klf B 44.15 100
34210543 A llf B 44.15 100
34210543 R klf 100
34210543 R llf 100
34210545 R ojf 66
34210545 R dkf 200
34210546 A mlf S 44.18 200
34210552 A nlf B 44.07 100
34210552 R alf 100
34210570 R hlf 250
34210570 A olf S 44.25 100
34210570 A plf S 44.17 250
34210571 R ilf 100
34210571 A qlf B 44.15 100
34210572 R mlf 200
34210573 A rlf S 44.19 200
34210574 R qlf 100
34210590 R blf 250
34210591 A slf B 44.13 250
34210591 R slf 250
34210595 A tlf B 44.12 250
34210600 R tlf 250
34210602 A ulf B 44.12 250
34210621 A vlf B 44.07 100
34210622 R nlf 100
34210623 A wlf S 44.25 100
34210623 R olf 100
34210623 R vlf 100
34210654 A xlf S 44.24 100
34210655 R wlf 100
34210655 A ylf B 44.07 100
34210678 R ojf 90
34210694 A zlf S 46.25 11
34210697 A amf S 44.32 11
34210736 A bmf S 44.17 100
34210737 R jlf 100
34210737 A cmf S 44.17 100
34210738 R glf 100
34210738 A dmf S 44.17 100
34210828 R ojf 72
34210838 R ulf 250
34210838 A emf B 44.12 250
34210890 R emf 250
34210892 A fmf B 44.12 250
34210900 R ylf 100
34210901 R fmf 250
34210903 A gmf B 44.12 250
34210910 R gmf 250
34210910 A hmf B 44.12 250
34210930 A imf B 44.07 100
34210951 A jmf B 44.07 100
34210951 R imf 100
34211020 A kmf B 44.15 140
34211042 R hmf 250
34211044 A lmf B 44.12 250
34211073 A mmf S 44.24 100
34211074 R xlf 100
34211078 R lmf 250
34211079 A nmf B 44.12 250
34211110 A omf B 44.07 100
34211110 R jmf 100
34211112 A pmf S 44.24 100
34211112 R mmf 100
34211397 R nmf 250
34211397 A qmf B 44.13 250
34211432 A rmf B 44.08 100
34211432 R omf 100
34211475 R kmf 140
34211476 R cjf 200
34211476 A smf B 44.13 200
34211516 R qmf 250
34211518 A tmf B 44.12 250
34211541 A umf B 44.13 100
34211727 R ojf 138
34211732 A vmf B 44.13 100
34211733 R umf 100
34211733 A wmf B 44.13 100
34211736 A xmf B 44.14 100
34211740 R tmf 250
34211743 A ymf B 44.12 250
34211743 R vmf 100
34211749 R rlf 200
34211750 A zmf S 44.17 200
34211750 R ymf 250
34211750 A anf B 44.12 250
34211751 R anf 250
34211751 R xmf 100
34211752 R zmf 200
34211752 A bnf S 44.17 200
34211753 A cnf B 44.12 250
34211753 R dmf 100
34211753 R smf 200
34211753 A dnf B 44.09 200
34211754 R cmf 100
34211754 A enf S 44.17 100
34211754 A fnf S 44.19 100
34211754 A gnf S 44.17 100
34211754 R dnf 200
34211755 A hnf B 44.12 200
34211780 A inf S 44.24 100
34211780 R pmf 100
34211780 R rmf 100
34211824 A jnf S 44.24 100
34211824 R inf 100
34211825 A knf B 44.06 100
34211831 R cnf 250
34211833 A lnf B 44.11 250
34211851 R lnf 250
34211852 A mnf B 44.12 250
34211882 A nnf B 44.06 100
34211882 R knf 100
34211888 R plf 250
34211889 A onf S 44.17 250
34211891 R bnf 200
34211891 A pnf S 44.17 200
34211923 A qnf B 44.06 100
34211923 R nnf 100
34211970 A rnf B 44.06 100
34211970 R qnf 100
34212003 A snf S 44.15 72
34212034 R snf 72
34212090 R mnf 250
34212092 A tnf B 44.11 250
34212143 A unf B 44.13 100
34212144 A vnf B 44.13 100
34212183 A wnf B 44.15 66
34212184 R enf 100
34212184 R gnf 100
34212184 R onf 250
34212184 R unf 100
34212186 R vnf 100
34212186 A xnf B 44.14 100
34212186 A ynf S 44.17 100
34212187 R wmf 100
34212187 A znf B 44.14 100
34212188 A aof B 44.15 100
34212189 R pnf 200
34212189 A bof S 44.19 200
34212189 A cof B 44.15 100
34212189 R xnf 100
34212190 A dof B 44.14 100
34212193 R znf 100
34212194 A eof B 44.15 100
34212195 R ynf 100
34212195 R dof 100
34212195 A fof S 44.17 100
34212195 A gof B 44.15 100
34212195 R aof 100
34212196 R fof 100
34212196 A hof S 44.17 100
34212197 R bmf 100
34212197 R gof 100
34212197 A iof B 44.13 100
34212197 R cof 100
34212198 R bof 200
34212198 A jof S 44.17 200
34212199 A kof B 44.15 100
34212200 R jof 200
34212200 A lof S 44.19 200
34212201 A mof B 44.15 100
34212201 R kof 100
34212202 R mof 100
34212204 A nof S 44.17 100
34212206 A oof B 44.15 100
34212206 A pof B 44.15 100
34212206 R oof 100
34212207 R pof 100
34212209 A qof B 44.15 100
34212209 R qof 100
34212211 R fnf 100
34212212 A rof B 44.15 100
34212212 R rof 100
34212213 R tnf 250
34212214 A sof B 44.15 100
34212215 A tof B 44.12 250
34212216 A uof B 44.15 100
34212216 R sof 100
34212216 R uof 100
34212221 A vof B 44.15 100
34212221 A wof B 44.15 100
34212231 A xof B 44.06 100
34212231 R rnf 100
34212232 R jnf 100
34212244 R nof 100
34212244 R hof 100
34212245 R iof 100
34212245 A yof B 44.15 100
34212245 A zof S 44.17 100
34212246 A apf B 44.15 100
34212246 R eof 100
34212247 R vof 100
34212247 R yof 100
34212247 A bpf B 44.15 100
34212248 R wof 100
34212248 A cpf S 44.19 100
34212249 R apf 100
34212249 A dpf B 44.16 100
34212250 R bpf 100
34212250 R tof 250
34212250 A epf B 44.16 100
34212250 A fpf B 44.12 250
34212251 R dpf 100
34212251 A gpf B 44.13 100
34212251 R zof 100
34212251 R hnf 200
34212251 A hpf S 44.19 100
34212251 A ipf B 44.13 200
34212260 R fpf 250
34212262 A jpf B 44.07 100
34212262 R xof 100
34212264 A kpf B 44.12 250
34212267 A lpf S 44.24 100
34212277 R cpf 100
34212294 A mpf B 44.07 100
34212294 R jpf 100
34212300 R lpf 100
34212301 R kpf 250
34212301 A npf B 44.12 250
34212324 A opf B 44.07 100
34212325 R mpf 100
34212332 A ppf S 44.25 100
34212338 A qpf S 44.18 250
34212339 R gpf 100
34212339 A rpf B 44.16 100
34212339 R lof 200
34212339 R hpf 100
34212340 A spf S 44.18 200
34212340 A tpf S 44.18 100
34212340 A upf B 44.16 100
34212340 R epf 100
34212341 R rpf 100
34212341 A vpf B 44.16 100
34212342 A wpf B 44.16 100
34212342 R upf 100
34212343 R spf 200
34212344 A xpf S 44.19 200
34212345 R yve 32
34212346 R xpf 200
34212347 A ypf S 44.18 200
34212351 A zpf S 44.25 100
34212351 R ppf 100
34212355 A aqf B 44.07 100
34212355 R opf 100
34212356 R qpf 250
34212359 R zpf 100
34212361 R wpf 100
34212362 R vpf 100
34212362 A bqf B 44.13 100
34212363 A cqf S 44.18 250
34212363 R tpf 100
34212363 A dqf B 44.13 100
34212363 A eqf S 44.17 100
34212364 A fqf B 44.15 100
34212364 R ipf 200
34212364 A gqf B 44.13 200
34212365 R bqf 100
34212365 A hqf B 44.15 100
34212365 R dqf 100
34212365 A iqf B 44.13 100
34212365 A jqf B 44.15 100
34212367 R fqf 100
34212367 R iqf 100
34212367 A kqf B 44.15 100
34212368 R jqf 100
34212369 A lqf B 44.15 100
34212371 A mqf B 44.15 100
34212371 R npf 250
34212372 A nqf B 44.13 250
34212387 A oqf B 44.08 100
34212387 R aqf 100
34212390 A pqf S 44.25 100
34212390 R pqf 100
34212410 R nqf 250
34212415 A qqf B 44.12 250
34212419 A rqf B 44.08 100
34212419 R oqf 100
34212421 A sqf S 44.25 100
34212430 A tqf S 44.25 100
34212431 R sqf 100
34212462 A uqf S 44.24 100
34212462 R tqf 100
34212495 R eqf 20
34212534 R eqf 48
34212569 R eqf 32
34212570 A vqf S 44.18 100
34212591 R lqf 100
34212592 R uqf 100
34212593 R mqf 100
34212600 A wqf B 44.08 100
34212601 R rqf 100
34212601 R qqf 250
34212604 A xqf B 44.13 250
34212609 R cqf 250
34212610 R gqf 200
34212610 A yqf B 44.13 200
34212615 A zqf S 44.18 250
34212622 A arf S 44.25 100
34212631 A brf B 44.08 100
34212632 R wqf 100
34212633 A crf B 44.15 100
34212634 A drf B 44.15 100
34212634 R hqf 100
34212634 R kqf 100
34212634 A erf B 44.15 100
34212647 R zqf 250
34212662 A frf B 44.08 100
34212663 A grf S 44.18 250
34212663 R brf 100
34212672 R grf 250
34212677 A hrf S 44.19 250
34212678 R hrf 250
34212679 A irf S 44.18 250
34212683 R crf 100
34212687 R irf 250
34212690 A jrf S 44.19 250
34212690 A krf B 44.15 100
34212695 A lrf B 44.09 100
34212695 R frf 100
34212702 R ypf 200
34212703 A mrf S 44.19 200
34212703 R erf 100
34212703 R drf 100
34212703 A nrf B 44.16 100
34212703 A orf B 44.16 100
34212724 A prf B 44.14 200
34212725 R krf 100
34212726 A qrf B 44.09 100
34212726 R yqf 200
34212726 A rrf B 44.14 200
34212726 R lrf 100
34212727 R jrf 250
34212728 A srf S 44.18 250
34212730 R srf 250
34212732 A trf B 44.16 100
34212732 A urf S 44.19 250
34212732 R nrf 100
34212733 A vrf B 44.16 100
34212733 A wrf B 44.16 100
34212733 R orf 100
34212749 R arf 100
34212757 A xrf B 44.09 100
34212757 R qrf 100
34212779 A yrf S 44.25 100
34212830 A zrf S 44.25 100
34212830 R yrf 100
34212847 R yve 568
34212851 R urf 250
34212851 A asf S 44.18 250
34212859 R mrf 200
34212860 A bsf S 44.18 100
34212860 R vqf 100
34212860 R asf 250
34212862 A csf S 44.25 100
34212862 R zrf 100
34212863 R prf 200
34212863 A dsf S 44.19 250
34212863 A esf B 44.14 100
34212869 A fsf S 44.18 67
34212877 R trf 100
34212891 R fsf 67
34212892 A gsf B 44.09 100
34212892 R xrf 100
34212895 R xqf 250
34212898 A hsf B 44.14 250
34212900 R hsf 250
34212903 A isf B 44.13 250
34212908 A jsf B 44.16 100
34212910 R isf 250
34212913 A ksf B 44.13 250
34212915 R esf 100
34212916 A lsf B 44.14 100
34212916 R wrf 100
34212916 R vrf 100
34212917 A msf B 44.16 100
34212917 A nsf B 44.16 100
34212922 A osf B 44.09 100
34212923 R gsf 100
34212942 R csf 100
34212950 R bsf 100
34212950 A psf S 44.19 100
34212951 R dsf 250
34212954 A qsf S 44.20 250
34212954 A rsf B 44.09 100
34212954 R osf 100
34212955 R ksf 250
34212955 A ssf B 44.14 250
34212960 R ssf 250
34212963 A tsf B 44.13 250
34212964 R rrf 200
34212964 A usf B 44.16 200
34212964 R psf 100
34212964 A vsf S 44.19 100
34212965 R nsf 100
34212965 A wsf B 44.16 100
34212965 A xsf B 44.16 100
34212965 R msf 100
34212972 A ysf S 44.25 100
34212979 R ysf 100
34212981 R jsf 100
34212985 R tsf 250
34212986 A zsf B 44.14 250
34212986 A atf B 44.10 100
34212987 R rsf 100
34212987 A btf B 44.16 100
34212991 R usf 200
34212992 A ctf B 44.14 200
34213009 A dtf S 44.26 100
34213018 A etf B 44.10 100
34213018 R atf 100
34213022 A ftf S 44.26 100
34213023 R dtf 100
34213037 R lsf 100
34213038 A gtf B 44.15 100
34213049 A htf B 44.10 100
34213049 R etf 100
34213059 R btf 100
34213064 A itf S 44.26 100
34213064 R ftf 100
34213072 A jtf B 44.16 100
34213073 R wsf 100
34213073 A ktf B 44.16 100
34213074 R xsf 100
34213074 A ltf B 44.16 100
34213080 A mtf B 44.10 100
34213081 R htf 100
34213090 R itf 100
34213116 R jtf 100
34213118 A ntf B 44.10 100
34213119 R mtf 100
34213121 A otf S 44.26 100
34213122 A ptf B 44.17 100
34213123 R ktf 100
34213124 A qtf B 44.17 100
34213124 R ltf 100
34213125 A rtf B 44.17 100
34213139 R ptf 100
34213145 A stf B 44.17 100
34213146 A ttf B 44.17 100
34213146 R qtf 100
34213147 R rtf 100
34213147 A utf B 44.17 100
34213148 R ttf 100
34213148 A vtf B 44.17 100
34213150 A wtf B 44.10 100
34213150 R ntf 100
34213180 A xtf B 44.10 100
34213181 R wtf 100
34213188 A ytf S 44.22 100
34213190 R utf 100
34213190 A ztf B 44.17 100
34213212 A auf B 44.10 100
34213212 R xtf 100
34213242 A buf B 44.11 100
34213243 R auf 100
34213271 R zsf 250
34213271 R qsf 250
34213272 R vtf 100
34213272 A cuf B 44.17 100
34213293 A duf S 44.19 300
34213294 R gtf 100
34213300 A euf B 44.11 100
34213301 R buf 100
34213311 R vsf 100
34213312 A fuf S 44.22 100
34213312 R ztf 100
34213312 A guf B 44.18 100
34213313 R ytf 100
34213313 R cuf 100
34213313 A huf B 44.18 100
34213314 A iuf S 44.21 100
34213315 R guf 100
34213315 R fuf 100
34213315 A juf B 44.18 100
34213315 A kuf S 44.21 100
34213316 A luf B 44.18 100
34213316 R huf 100
34213317 R iuf 100
34213317 R juf 100
34213317 A muf B 44.18 100
34213317 A nuf S 44.21 100
34213318 R luf 100
34213318 R kuf 100
34213319 A ouf B 44.18 100
34213319 A puf S 44.21 100
34213319 R otf 100
34213319 R muf 100
34213320 A quf B 44.18 100
34213320 R nuf 100
34213321 A ruf S 44.21 100
34213321 R ouf 100
34213321 A suf B 44.18 100
34213321 R puf 100
34213322 R suf 100
34213322 A tuf S 44.21 100
34213323 R ruf 100
34213323 A uuf S 44.21 100
34213323 A vuf B 44.18 68
34213324 R tuf 100
34213325 R vuf 68
34213325 R quf 32
34213325 A wuf S 44.21 100
34213325 A xuf B 44.16 100
34213326 R uuf 100
34213326 A yuf B 44.17 100
34213327 A zuf S 44.20 100
34213328 R wuf 100
34213329 A avf S 44.20 100
34213329 R quf 68
34213330 R zuf 100
34213331 A bvf S 44.20 100
34213331 A cvf B 44.11 100
34213332 R euf 100
34213332 R stf 100
34213333 R avf 100
34213334 A dvf S 44.20 100
34213341 A evf B 44.17 100
34213342 R xuf 100
34213342 R bvf 100
34213342 A fvf B 44.15 100
34213343 R yuf 100
34213343 A gvf B 44.17 100
34213344 A hvf S 44.20 100
34213349 A ivf S 44.26 100
34213354 A jvf S 44.20 250
34213355 R dvf 100
34213355 A kvf S 44.19 100
34213356 R hvf 100
34213356 A lvf S 44.19 100
34213356 R evf 100
34213357 R gvf 100
34213357 R kvf 100
34213357 A mvf B 44.15 100
34213357 R lvf 100
34213358 A nvf S 44.19 100
34213358 A ovf S 44.19 100
34213358 R fvf 100
34213358 R nvf 100
34213359 A pvf S 44.19 200
34213359 A qvf S 44.19 100
34213360 R jvf 250
34213363 A rvf B 44.11 100
34213363 R cvf 100
34213366 A svf B 44.17 100
34213367 R mvf 100
34213367 A tvf B 44.17 100
34213368 R pvf 200
34213368 R ovf 100
34213368 A uvf S 44.22 100
34213371 R rvf 100
34213382 R tvf 100
34213382 A vvf S 44.20 250
34213382 A wvf B 44.14 100
34213384 R uvf 100
34213384 A xvf S 44.19 100
34213385 A yvf S 44.19 200
34213390 R svf 100
34213401 A zvf B 44.11 100
34213402 A awf B 44.16 100
34213403 A bwf B 44.13 250
34213403 R wvf 100
34213403 A cwf B 44.16 100
34213410 A dwf S 44.26 100
34213411 R ivf 100
34213411 R qvf 100
34213411 R bwf 250
34213411 R yvf 200
34213411 R zvf 100
34213412 A ewf S 44.19 100
34213412 A fwf S 44.19 200
34213412 R xvf 100
34213413 A gwf S 44.19 100
34213414 R ewf 100
34213415 A hwf S 44.19 100
34213415 A iwf B 44.12 250
34213416 R gwf 100
34213416 A jwf S 44.18 100
34213430 R dwf 100
34213439 R iwf 250
34213440 A kwf B 44.13 250
34213440 R hwf 100
34213441 A lwf S 44.18 100
34213442 A mwf B 44.08 100
34213449 R vvf 250
34213449 A nwf S 44.19 250
34213452 R kwf 250
34213454 A owf B 44.12 250
34213459 A pwf B 44.08 100
34213460 R mwf 100
34213462 A qwf S 44.26 100
34213466 R awf 100
34213466 R jwf 100
34213467 A rwf S 44.18 100
34213468 R lwf 100
34213469 A swf S 44.18 100
34213470 A twf S 44.26 100
34213471 R qwf 100
34213475 A uwf B 44.16 100
34213490 A vwf B 44.08 100
34213491 R pwf 100
34213501 A wwf S 44.26 100
34213501 R twf 100
34213522 R owf 250
34213523 R cwf 100
34213523 A xwf B 44.16 100
34213523 R rwf 100
34213523 A ywf S 44.19 100
34213524 R fwf 200
34213524 A zwf B 44.12 250
34213540 R zwf 250
34213540 A axf B 44.12 250
34213551 A bxf S 44.19 200
34213553 A cxf B 44.08 100
34213553 R vwf 100
34213569 R bxf 200
34213569 A dxf S 44.19 200
34213571 A exf S 44.26 100
34213572 R wwf 100
34213580 R dxf 200
34213581 A fxf S 44.19 200
34213592 R axf 250
34213594 A gxf B 44.12 250
34213599 A hxf B 44.08 100
34213600 R cxf 100
34213600 R fxf 200
34213601 A ixf S 44.19 200
34213601 R gxf 250
34213602 A jxf B 44.12 250
34213602 R ixf 200
34213602 A kxf S 44.19 200
34213603 A lxf S 44.26 100
34213603 R exf 100
34213622 R jxf 250
34213625 A mxf B 44.12 250
34213630 A nxf B 44.08 100
34213630 R hxf 100
34213633 R mxf 250
34213633 A oxf B 44.12 250
34213635 A pxf S 44.25 100
34213635 R lxf 100
34213648 R kxf 200
34213661 A qxf B 44.09 100
34213661 R nxf 100
34213693 A rxf B 44.09 100
34213694 R qxf 100
34213788 R oxf 250
34213789 A sxf B 44.13 250
34213830 R sxf 250
34213832 A txf B 44.12 250
34213907 R txf 250
34213907 A uxf B 44.13 250
34214339 A vxf B 44.16 68
34214351 R nwf 250
34214351 A wxf S 44.18 250
34214352 R xwf 100
34214352 R vxf 68
34214352 R ywf 100
34214352 A xxf S 44.19 200
34214353 A yxf B 44.16 68
34214353 A zxf B 44.14 100
34214353 A ayf S 44.18 100
34214354 R xxf 200
34214354 R swf 100
34214354 A byf S 44.18 100
34214354 A cyf S 44.18 200
34214355 R ayf 100
34214356 A dyf S 44.18 100
34214357 A eyf B 44.14 100
34214357 R byf 100
34214357 A fyf S 44.18 100
34214357 A gyf S 44.18 100
34214358 R dyf 100
34214358 A hyf S 44.17 100
34214359 R fyf 100
34214360 A iyf S 44.17 100
34214364 R gyf 100
34214364 R uwf 100
34214370 R uxf 250
34214370 A jyf S 44.17 100
34214372 A kyf B 44.12 250
34214380 A lyf S 44.24 100
34214381 R pxf 100
34214398 R rxf 100
34214403 R yxf 68
34214403 R hyf 100
34214403 R kyf 250
34214403 A myf B 44.14 68
34214403 A nyf S 44.17 100
34214403 R ctf 200
34214403 R cyf 200
34214404 A oyf S 44.17 200
34214404 A pyf B 44.13 200
34214405 R iyf 100
34214405 A qyf S 44.17 100
34214405 A ryf B 44.12 250
34214406 R eyf 100
34214407 R nyf 100
34214408 A syf S 44.17 100
34214408 R qyf 100
34214409 A tyf S 44.17 100
34214409 R syf 100
34214410 A uyf S 44.17 100
34214411 R ryf 250
34214411 R tyf 100
34214413 A vyf B 44.11 250
34214414 R vyf 250
34214414 A wyf B 44.12 250
34214422 R wxf 250
34214422 A xyf S 44.18 250
34214438 A yyf B 44.06 100
34214440 R wyf 250
34214440 R yyf 100
34214440 A zyf B 44.12 250
34214448 R zyf 250
34214450 A azf B 44.12 250
34214453 A bzf S 44.24 100
34214454 R lyf 100
34214470 A czf B 44.06 100
34214481 R xyf 250
34214483 A dzf S 44.18 250
34214489 R azf 250
34214490 A ezf B 44.12 250
34214509 R bzf 100
34214519 A fzf B 44.06 100
34214520 R czf 100
34214539 A gzf S 44.24 100
34214550 A hzf B 44.06 100
34214551 R fzf 100
34214581 A izf B 44.07 100
34214581 R hzf 100
34214612 A jzf B 44.07 100
34214612 R izf 100
34214622 R uyf 100
34214622 R oyf 200
34214622 A kzf S 44.17 100
34214622 A lzf S 44.18 200
34214625 A mzf S 44.17 200
34214643 A nzf B 44.07 100
34214643 R jzf 100
34214674 A ozf B 44.07 100
34214674 R nzf 100
34214704 R kzf 100
34214706 A pzf B 44.07 100
34214706 R ozf 100
34214708 A qzf B 44.12 100
34214710 R mzf 200
34214710 R dzf 250
34214711 R jyf 100
34214713 A rzf S 44.19 250
34214715 A szf S 44.21 100
34214718 A tzf S 44.18 100
34214730 R tzf 100
34214738 A uzf B 44.07 100
34214738 R pzf 100
34214738 R gzf 100
34214769 A vzf S 44.25 100
34214782 R lzf 200
34214782 R ezf 250
34214782 A wzf B 44.13 250
34214783 A xzf S 44.19 200
34214783 R pyf 200
34214783 A yzf B 44.13 200
34214802 A zzf B 44.07 100
34214802 R uzf 100
34214805 A aag S 44.25 100
34214805 R vzf 100
34214812 R aag 100
34214815 A bag S 44.19 100
34214828 R wzf 250
34214828 A cag B 44.14 250
34214829 R yzf 200
34214829 A dag B 44.14 200
34214834 A eag B 44.08 100
34214834 R zzf 100
34214836 R bag 100
34214848 R xzf 200
34214858 R qzf 100
34214860 A fag S 44.25 100
34214863 A gag B 44.13 200
34214865 A hag B 44.08 100
34214866 R eag 100
34214868 A iag S 44.19 100
34214897 A jag B 44.08 100
34214897 R hag 100
34214900 R rzf 250
34214903 A kag S 44.20 250
34214904 R gag 200
34214904 R szf 100
34214904 A lag S 44.19 200
34214904 A mag B 44.13 100
34214905 A nag S 44.21 200
34214908 R iag 100
34214916 A oag S 44.19 67
34214932 R fag 100
34214932 A pag B 44.08 100
34214933 R jag 100
34214959 A qag B 44.15 100
34214959 R zxf 100
34214960 R myf 68
34214960 A rag B 44.15 100
34214960 A sag B 44.15 100
34214961 R dag 200
34214961 A tag B 44.15 200
34214962 A uag S 44.26 100
34214962 R rag 100
34214962 R sag 100
34214962 A vag B 44.15 100
34214962 A wag B 44.15 100
34214968 R cag 250
34214968 A xag B 44.14 250
34214969 R tag 200
34214969 A yag B 44.16 200
34214970 R wag 100
34214970 R vag 100
34214970 A zag B 44.16 100
34214970 A abg B 44.16 100
34214973 A bbg B 44.16 200
34214976 A cbg S 44.19 100
34214982 A dbg B 44.09 100
34214982 R pag 100
34214991 R xag 250
34214991 A ebg B 44.15 250
34214996 R yag 200
34214997 A fbg B 44.14 200
34214998 R fbg 200
34214998 R bbg 200
34214998 A gbg B 44.15 200
34215004 A hbg B 44.16 100
34215005 R abg 100
34215005 R zag 100
34215005 A ibg B 44.16 100
34215005 A jbg B 44.16 100
34215008 R hbg 100
34215012 R ebg 250
34215013 A kbg B 44.15 250
34215013 A lbg B 44.09 100
34215014 R dbg 100
34215036 R oag 67
34215036 R gbg 200
34215037 A mbg B 44.16 200
34215043 A nbg B 44.09 100
34215044 R lbg 100
34215050 A obg B 41.18 100
34215059 R lag 200
34215059 A pbg S 44.21 200
34215068 R pbg 200
34215068 A qbg S 44.19 200
34215068 R mbg 200
34215068 A rbg B 44.16 200
34215069 R qbg 200
34215069 A sbg S 44.21 200
34215070 R jbg 100
34215070 R ibg 100
34215070 A tbg B 44.16 100
34215070 A ubg B 44.16 100
34215070 R kbg 250
34215070 A vbg B 44.16 250
34215075 A wbg B 44.09 100
34215075 R nbg 100
34215078 R rbg 200
34215078 R kag 250
34215079 R vbg 250
34215080 R cbg 100
34215081 A xbg B 44.16 250
34215089 A ybg S 44.20 250
34215090 R ybg 250
34215090 A zbg B 44.16 200
34215098 R xbg 250
34215099 R uag 100
34215101 A acg B 44.15 250
34215102 A bcg S 44.20 250
34215105 A ccg B 44.16 100
34215106 A dcg B 44.10 100
34215106 A ecg B 44.16 100
34215106 R wbg 100
34215106 R tbg 100
34215107 R ubg 100
34215107 A fcg B 44.16 100
34215107 R mag 100
34215107 R nag 200
34215108 R ccg 100
34215108 R ecg 100
34215108 A gcg B 44.17 100
34215109 R qag 100
34215110 A hcg S 44.19 67
34215110 R fcg 100
34215110 A icg B 44.17 100
34215111 R gcg 100
34215111 A jcg B 44.17 100
34215115 R hcg 67
34215116 R icg 100
34215116 A kcg B 44.17 100
34215118 R acg 250
34215119 R jcg 100
34215119 A lcg B 44.17 100
34215121 A mcg B 44.15 250
34215122 R kcg 100
34215122 A ncg B 44.17 100
34215126 A ocg S 44.19 100
34215127 R lcg 100
34215127 A pcg B 44.17 100
34215129 R mcg 250
34215130 R ncg 100
34215130 A qcg B 44.17 100
34215130 A rcg S 44.26 100
34215131 A scg S 44.26 100
34215131 R rcg 100
34215132 A tcg B 44.15 250
34215133 R pcg 100
34215133 A ucg B 44.18 100
34215134 R bcg 250
34215135 R qcg 100
34215135 A vcg B 44.18 100
34215137 A wcg B 44.10 100
34215137 R dcg 100
34215161 R scg 100
34215167 A xcg B 44.10 100
34215168 R wcg 100
34215189 A ycg S 44.20 250
34215190 A zcg B 44.18 100
34215190 R ucg 100
34215191 R vcg 100
34215191 A adg B 44.18 100
34215192 A bdg S 44.26 100
34215192 R zcg 100
34215192 A cdg B 44.18 100
34215198 A ddg S 44.19 100
34215198 A edg B 44.10 100
34215198 R adg 100
34215199 R xcg 100
34215199 A fdg B 44.18 100
34215201 R cdg 100
34215201 R zbg 200
34215201 A gdg B 44.16 100
34215202 A hdg B 44.16 200
34215202 R sbg 200
34215202 A idg S 44.19 200
34215203 R tcg 250
34215204 R ycg 250
34215210 R idg 200
34215211 A jdg B 44.14 250
34215212 R jdg 250
34215212 A kdg B 44.14 250
34215215 R kdg 250
34215216 A ldg B 44.15 250
34215222 A mdg S 44.26 100
34215223 R bdg 100
34215229 R edg 100
34215238 R ldg 250
34215240 A ndg B 44.14 250
34215253 A odg S 44.26 100
34215253 R mdg 100
34215259 A pdg B 44.11 100
34215263 R ocg 100
34215264 R ddg 100
34215264 A qdg S 44.22 100
34215279 R ndg 250
34215283 A rdg B 44.14 250
34215284 R rdg 250
34215290 A sdg B 44.14 250
34215292 R sdg 250
34215310 R pdg 100
34215340 A tdg B 44.11 100
34215359 R duf 300
34215361 A udg S 44.20 250
34215362 R qdg 100
34215363 A vdg S 44.19 100
34215369 A wdg S 44.26 100
34215370 R odg 100
34215385 R fdg 100
34215386 A xdg B 44.16 100
34215386 A ydg S 44.19 200
34215387 A zdg B 44.14 250
34215387 R gdg 100
34215388 A aeg B 44.16 100
34215388 R ydg 200
34215388 R xdg 100
34215388 A beg S 44.20 200
34215389 A ceg B 44.17 100
34215390 R beg 200
34215391 R aeg 100
34215391 A deg B 44.17 100
34215392 A eeg S 44.19 200
34215393 R ceg 100
34215393 A feg B 44.17 100
34215394 R eeg 200
34215395 R deg 100
34215395 A geg B 44.17 100
34215399 R vdg 100
34215399 R feg 100
34215399 A heg B 44.16 100
34215399 A ieg S 44.19 200
34215400 A jeg S 44.19 100
34215400 A keg S 44.26 100
34215401 R wdg 100
34215403 A leg S 44.19 100
34215407 R leg 100
34215409 R zdg 250
34215413 A meg B 44.14 250
34215413 A neg S 44.19 100
34215415 A oeg S 44.19 100
34215415 A peg S 44.21 100
34215416 R oeg 100
34215418 R meg 250
34215418 A qeg B 44.14 250
34215419 R udg 250
34215419 A reg S 44.19 250
34215422 R qeg 250
34215422 A seg B 44.15 250
34215426 R seg 250
34215426 R reg 250
34215431 R tdg 100
34215432 A teg B 44.14 250
34215432 A ueg S 44.20 250
34215436 R neg 100
34215439 A veg S 44.19 100
34215440 R ueg 250
34215440 A weg S 44.19 250
34215448 A xeg S 44.26 100
34215448 R keg 100
34215451 R teg 250
34215452 A yeg B 44.15 250
34215461 A zeg B 44.09 100
34215470 A afg B 44.09 100
34215471 R zeg 100
34215483 R veg 100
34215512 R yeg 250
34215515 A bfg B 44.14 250
34215521 R geg 22
34215521 R bfg 250
34215521 A cfg B 44.15 250
34215522 A dfg S 44.19 100
34215533 R jeg 100
34215533 A efg S 44.19 100
34215539 A ffg B 44.14 100
34215542 R hdg 200
34215542 A gfg B 44.15 200
34215542 R dfg 100
34215543 A hfg S 44.19 100
34215544 R peg 100
34215559 A ifg B 44.16 100
34215561 R heg 100
34215561 A jfg B 44.16 100
34215561 R xeg 100
34215566 R cfg 250
34215567 R ifg 100
34215567 A kfg S 44.19 100
34215568 A lfg B 44.14 250
34215571 A mfg B 44.09 100
34215571 R afg 100
34215592 A nfg S 44.26 100
34215605 R hfg 100
34215606 A ofg S 44.19 100
34215622 A pfg S 44.26 100
34215622 R nfg 100
34215652 A qfg S 44.25 100
34215653 R pfg 100
34215729 R lfg 250
34215731 A rfg B 44.13 250
34215737 R rfg 250
34215737 A sfg B 44.14 250
34215766 A tfg S 44.19 300
34215834 R geg 78
34215835 R efg 100
34215835 R ieg 200
34215836 A ufg S 44.19 200
34215836 A vfg S 44.18 100
34215837 R ofg 100
34215837 A wfg S 44.18 100
34215845 R kfg 100
34215846 R vfg 100
34215846 A xfg S 44.18 100
34215857 A yfg S 44.21 100
34215866 R sfg 250
34215868 A zfg B 44.14 250
34215887 R zfg 250
34215888 A agg B 44.14 250
34215889 A bgg S 44.25 100
34215890 R qfg 100
34215910 R wfg 100
34215911 R gfg 200
34215911 R ufg 200
34215911 A cgg S 44.18 100
34215911 A dgg B 44.14 200
34215911 A egg S 44.19 200
34215912 R xfg 100
34215912 A fgg S 44.18 100
34215913 R jfg 100
34215913 A ggg B 44.14 100
34215914 R cgg 100
34215915 A hgg S 44.18 100
34215916 R fgg 100
34215916 A igg S 44.18 100
34215924 R ffg 100
34215925 R yfg 100
34215925 A jgg B 44.15 100
34215925 A kgg B 44.13 100
34215926 R ggg 100
34215926 A lgg B 44.15 100
34215930 R agg 250
34215932 A mgg B 44.14 250
34215939 R jgg 100
34215940 R mgg 250
34215940 A ngg B 44.14 250
34215944 R mfg 100
34215956 R ngg 250
34215958 A ogg B 44.14 250
34215960 R ogg 250
34215960 A pgg B 44.14 250
34215961 A qgg S 44.25 100
34215961 R bgg 100
34215962 R pgg 250
34215965 A rgg B 44.14 250
34215972 R weg 250
34215972 A sgg S 44.18 250
34215973 R egg 200
34215973 A tgg S 44.18 200
34215973 A ugg B 44.08 100
34215980 R hgg 100
34215981 A vgg S 44.18 100
34215992 A wgg S 44.25 100
34215992 R qgg 100
34215993 R py 500
34216023 A xgg S 44.25 100
34216023 R wgg 100
34216028 R rgg 250
34216029 R igg 100
34216029 A ygg S 44.17 100
34216031 A zgg B 44.13 250
34216054 A ahg S 44.25 100
34216054 R xgg 100
34216061 R zgg 250
34216061 A bhg B 44.14 250
34216062 R bhg 250
34216064 A chg B 44.13 250
34216092 A dhg S 44.24 100
34216093 R ahg 100
34216118 R lgg 100
34216118 A ehg B 44.14 100
34216119 R dgg 200
34216119 R vgg 100
34216120 A fhg B 44.13 200
34216120 A ghg S 44.17 100
34216122 A hhg S 44.19 100
34216124 A ihg S 44.24 100
34216124 R dhg 100
34216139 R chg 250
34216140 R ygg 100
34216140 A jhg S 44.17 100
34216141 A khg B 44.12 250
34216155 A lhg S 44.24 100
34216155 R ihg 100
34216164 R ugg 100
34216170 R hhg 100
34216175 A mhg S 44.15 157
34216176 R ghg 100
34216176 A nhg S 44.17 100
34216176 R mhg 157
34216177 R jhg 100
34216178 R nhg 100
34216178 A ohg S 44.17 100
34216178 A phg S 44.18 100
34216180 A qhg S 44.19 100
34216188 R phg 100
34216188 A rhg S 44.17 100
34216190 R khg 250
34216191 R rhg 100
34216191 A shg S 44.18 100
34216191 A thg S 44.24 100
34216192 R lhg 100
34216192 R thg 100
34216193 A uhg B 44.12 250
34216193 R kgg 100
34216194 A vhg B 44.12 100
34216195 A whg B 44.08 100
34216209 R uhg 250
34216209 R ohg 100
34216210 A xhg S 44.18 100
34216211 A yhg B 44.11 250
34216213 R vhg 100
34216213 R shg 100
34216214 R qhg 100
34216214 A zhg S 44.18 100
34216214 A aig S 44.20 100
34216220 R whg 100
34216224 A big S 44.24 100
34216241 R big 100
34216251 A cig B 44.07 100
34216265 R yhg 250
34216265 A dig B 44.12 250
34216266 R xhg 100
34216266 A eig S 44.18 100
34216267 R zhg 100
34216268 A fig S 44.18 100
34216271 A gig S 44.24 100
34216274 A hig S 44.18 100
34216275 R eig 100
34216276 A iig S 44.18 100
34216293 A jig S 44.24 100
34216293 R gig 100
34216301 A kig S 44.15 72
34216302 R fig 100
34216303 A lig S 44.17 100
34216319 R dig 250
34216320 R iig 100
34216320 A mig S 44.17 100
34216322 A nig B 44.11 250
34216323 R lig 100
34216323 A oig S 44.17 100
34216324 A pig S 44.24 100
34216324 R jig 100
34216327 R aig 100
34216334 R mig 100
34216334 A qig S 44.17 100
34216346 R oig 100
34216347 A rig S 44.17 100
34216350 R cig 100
34216355 A sig S 44.24 100
34216356 R pig 100
34216380 A tig B 44.05 100
34216392 A uig B 44.06 100
34216392 R tig 100
34216409 A vig S 44.24 100
34216409 R sig 100
34216423 A wig B 44.06 100
34216423 R uig 100
34216426 R sgg 250
34216426 A xig S 44.18 250
34216427 R qig 100
34216427 A yig S 44.17 100
34216428 R tgg 200
34216428 A zig S 44.18 200
34216429 R rig 100
34216429 A ajg S 44.17 100
34216430 R yig 100
34216430 A bjg S 44.17 100
34216440 A cjg S 44.24 100
34216440 R vig 100
34216450 R fhg 200
34216450 A djg B 44.11 200
34216451 R ajg 100
34216451 A ejg S 44.16 100
34216452 R bjg 100
34216453 A fjg S 44.16 100
34216453 A gjg B 44.06 100
34216454 R wig 100
34216457 R xig 250
34216458 R ejg 100
34216458 A hjg S 44.16 100
34216460 A ijg S 44.18 250
34216461 R fjg 100
34216462 A jjg S 44.16 100
34216471 A kjg S 44.24 100
34216471 R cjg 100
34216502 A ljg S 44.23 100
34216502 R kjg 100
34216537 R ijg 250
34216539 A mjg S 44.18 250
34216790 R mjg 250
34216791 A njg S 44.17 250
34216792 R zig 200
34216793 A ojg S 44.17 200
34216822 A pjg S 44.23 100
34216822 R ljg 100
34216853 A qjg S 44.23 100
34216853 R pjg 100
34216945 R kig 72
34216946 R wnf 66
34216946 A rjg S 44.15 6
34216946 R jjg 100
34216946 A sjg B 44.13 68
34216946 A tjg S 44.17 100
34216947 R hjg 100
34216947 A ujg B 44.13 14
34216947 R ehg 100
34216948 A vjg S 44.16 100
34216949 R tjg 100
34216949 A wjg S 44.16 100
34216951 A xjg S 44.16 100
34216952 R vjg 100
34216952 A yjg S 44.16 100
34216959 A zjg B 44.13 68
34216959 R wjg 100
34216960 A akg S 44.16 100
34216967 R zjg 68
34216968 R yjg 100
34216968 A bkg S 44.16 100
34216976 R njg 250
34216979 A ckg S 44.18 250
34216987 R ckg 250
34216988 A dkg S 44.17 250
34216992 R dkg 250
34216995 A ekg S 44.18 250
34217000 R ekg 250
34217000 A fkg S 44.17 250
34217013 R rjg 6
34217014 R akg 100
34217015 A gkg S 44.15 100
34217017 R fkg 250
34217019 A hkg S 44.17 250
34217021 R qjg 100
34217021 R gjg 100
34217051 A ikg S 44.23 100
34217052 A jkg B 44.06 100
34217079 A kkg S 44.23 100
34217079 R ikg 100
34217110 A lkg S 44.23 100
34217110 R kkg 100
34217186 R gkg 30
34217279 R lkg 100
34217288 A mkg B 44.06 100
34217289 R jkg 100
34217291 R bkg 100
34217292 A nkg S 44.16 100
34217309 A okg S 44.23 100
34217332 A pkg S 44.23 100
34217333 R okg 100
34217333 R gkg 70
34217341 R hkg 250
34217341 R nkg 100
34217342 A qkg S 44.17 100
34217343 A rkg S 44.18 250
34217345 A skg S 44.18 100
34217345 R skg 100
34217352 R rkg 250
34217352 A tkg S 44.17 250
34217360 R nig 250
34217360 A ukg B 44.12 250
34217361 R djg 200
34217361 A vkg B 44.12 200
34217365 A wkg B 44.13 100
34217366 R sjg 68
34217366 A xkg B 44.13 100
34217367 R ujg 14
34217367 A ykg B 44.13 100
34217368 R tkg 250
34217369 R vkg 200
34217369 A zkg B 44.13 200
34217369 R ykg 100
34217370 A alg B 44.13 100
34217370 R xkg 100
34217370 A blg B 44.13 100
34217370 A clg B 44.06 100
34217371 R mkg 100
34217371 R zkg 200
34217371 R pkg 100
34217371 A dlg S 44.18 250
34217371 A elg B 44.13 200
34217372 R alg 100
34217373 A flg B 44.13 100
34217373 R blg 100
34217373 A glg B 44.13 100
34217392 R ukg 250
34217395 A hlg B 44.11 250
34217401 A ilg B 44.06 100
34217402 R clg 100
34217402 A jlg S 44.24 100
34217406 A klg S 44.16 1000
34217407 R elg 200
34217407 R qkg 100
34217407 A llg B 44.11 200
34217407 A mlg S 44.16 100
34217432 A nlg B 44.06 100
34217432 R ilg 100
34217469 A olg B 44.06 100
34217470 R nlg 100
34217470 A plg S 44.24 100
34217471 R jlg 100
34217492 R hlg 250
34217492 A qlg B 44.12 250
34217493 R llg 200
34217493 A rlg B 44.12 200
34217501 A slg B 44.06 100
34217502 R olg 100
34217508 R qlg 250
34217509 R mlg 100
34217510 A tlg S 44.17 100
34217511 A ulg B 44.12 250
34217520 R plg 100
34217533 A vlg B 44.07 100
34217534 R slg 100
34217542 R ulg 250
34217544 A wlg B 44.12 250
34217550 A xlg S 44.24 100
34217556 R wkg 100
34217559 R rlg 200
34217559 A ylg B 44.13 200
34217560 R flg 100
34217561 A zlg B 44.13 100
34217561 R glg 100
34217561 A amg B 44.13 100
34217562 A bmg B 44.13 100
34217564 A cmg B 44.07 100
34217564 R vlg 100
34217569 R ylg 200
34217569 A dmg B 44.12 200
34217576 R bmg 100
34217579 R ojg 200
34217580 A emg S 44.18 200
34217580 A fmg B 44.14 100
34217581 R amg 100
34217581 A gmg B 44.14 100
34217582 R zlg 100
34217582 A hmg B 44.14 100
34217593 R fmg 100
34217596 A img B 44.07 100
34217596 R cmg 100
34217600 A jmg B 44.14 100
34217601 R gmg 100
34217601 A kmg B 44.14 100
34217602 R hmg 100
34217602 A lmg B 44.14 100
34217627 A mmg B 44.07 100
34217627 R img 100
34217641 R dlg 250
34217643 A nmg S 44.18 250
34217671 A omg B 44.07 100
34217671 R mmg 100
34217678 R nmg 250
34217680 A pmg S 44.18 250
34217703 A qmg B 44.07 100
34217703 R omg 100
34217758 R xjg 100
34217758 R klg 100
34217823 A rmg S 46.25 6
34217835 A smg S 44.32 6
34217869 R xlg 100
34217900 A tmg S 44.24 100
34218014 R jmg 100
34218026 A umg B 44.14 100
34218027 R lmg 100
34218027 A vmg B 44.14 100
34218028 R kmg 100
34218028 A wmg B 44.14 100
34218270 R pmg 250
34218270 A xmg S 44.18 250
34218680 R klg 100
34218816 A ymg S 54.24 50
34218988 R wlg 250
34218989 A zmg B 44.12 250
34218997 R klg 800
34218998 R dmg 200
34218999 R tlg 100
34218999 A ang B 44.13 200
34218999 A bng S 44.18 100
34219002 A cng S 44.19 200
34219004 A dng S 44.17 100
34219005 R bng 100
34219005 A eng S 44.17 100
34219006 R hig 100
34219009 R dng 100
34219043 A fng B 44.08 100
34219043 R qmg 100
34219044 A gng S 44.24 100
34219044 R tmg 100
34219061 R xmg 250
34219063 A hng S 44.18 250
34219064 R emg 200
34219065 A ing S 44.19 200
34219065 A jng S 44.18 100
34219065 R eng 100
34219066 R ing 200
34219067 A kng S 44.18 200
34219073 A lng B 44.08 100
34219074 R fng 100
34219080 A mng B 44.13 200
34219081 A nng S 44.17 100
34219081 R umg 100
34219081 R ang 200
34219081 R jng 100
34219082 A ong B 44.14 200
34219082 A png S 44.18 100
34219083 R cng 200
34219087 R nng 100
34219088 A qng B 44.14 100
34219088 R vmg 100
34219088 R wmg 100
34219088 A rng B 44.14 100
34219088 A sng B 44.14 100
34219088 R kng 200
34219089 A tng S 44.19 200
34219089 A ung B 44.15 200
34219089 R ong 200
34219090 R rng 100
34219090 R sng 100
34219090 R mng 200
34219090 A vng B 44.15 100
34219090 A wng B 44.15 100
34219098 A xng S 44.18 100
34219099 R tng 200
34219100 A yng S 44.18 200
34219100 R png 100
34219101 A zng S 44.18 100
34219101 R ung 200
34219101 A aog B 44.15 200
34219101 R yng 200
34219102 A bog S 44.19 200
34219102 R hng 250
34219102 R vng 100
34219102 R wng 100
34219102 A cog B 44.15 100
34219103 A dog B 44.15 100
34219104 A eog B 44.08 100
34219104 A fog S 44.20 200
34219104 R lng 100
34219104 A gog S 44.19 250
34219105 R xng 100
34219109 R zng 100
34219110 A hog S 44.18 100
34219110 R bog 200
34219111 A iog S 44.19 200
34219112 R gng 100
34219114 A jog S 44.18 100
34219115 R hog 100
34219116 A kog S 44.18 100
34219116 R iog 200
34219117 A log S 44.19 200
34219122 R jog 100
34219130 A mog S 44.18 100
34219135 A nog B 44.08 100
34219135 R eog 100
34219137 R zmg 250
34219138 R kog 100
34219138 A oog B 44.13 250
34219139 A pog S 44.18 100
34219141 R aog 200
34219141 A qog B 44.13 200
34219142 A rog S 44.25 100
34219142 R rog 100
34219142 A sog S 44.18 100
34219142 A tog S 44.18 100
34219150 R mog 100
34219156 R tog 100
34219160 R sog 100
34219160 A uog S 44.18 100
34219161 A vog S 44.18 100
34219161 R gog 250
34219162 A wog S 44.18 250
34219166 A xog B 44.08 100
34219166 R nog 100
34219168 R pog 100
34219169 R wog 250
34219169 A yog S 44.18 100
34219169 R log 200
34219170 A zog S 44.19 200
34219171 A apg S 44.18 100
34219171 A bpg S 44.19 250
34219172 A cpg S 44.25 100
34219173 A dpg S 44.25 100
34219174 R cpg 100
34219174 R zog 200
34219178 A epg S 44.19 200
34219184 R qng 100
34219196 A fpg B 44.15 100
34219197 A gpg B 44.08 100
34219197 R xog 100
34219205 A hpg S 44.25 100
34219205 R dpg 100
34219224 R epg 200
34219225 R dog 100
34219225 R cog 100
34219225 A ipg B 44.15 100
34219225 A jpg B 44.15 100
34219227 A kpg B 44.09 100
34219228 R gpg 100
34219270 A lpg S 44.19 200
34219278 R yog 100
34219279 A mpg S 44.18 100
34219279 R bpg 250
34219280 A npg S 44.18 250
34219281 R lpg 200
34219281 A opg S 44.18 200
34219282 A ppg S 44.17 100
34219286 A qpg S 44.17 100
34219289 R vog 100
34219290 R oog 250
34219293 A rpg B 44.12 250
34219298 R mpg 100
34219299 A spg S 44.17 100
34219300 R spg 100
34219300 A tpg B 44.09 100
34219300 R kpg 100
34219300 R rpg 250
34219300 A upg S 44.18 100
34219300 R ppg 100
34219302 A vpg B 44.12 250
34219308 R vpg 250
34219308 A wpg B 44.12 250
34219308 A xpg S 44.23 100
34219309 R hpg 100
34219319 R wpg 250
34219321 A ypg B 44.12 250
34219322 R upg 100
34219322 R opg 200
34219322 R ypg 250
34219323 A zpg B 44.13 250
34219323 A aqg S 44.18 100
34219323 A bqg S 44.19 200
34219330 A cqg B 44.09 100
34219331 R tpg 100
34219332 A dqg S 44.17 100
34219332 R fpg 100
34219332 R fog 200
34219332 R aqg 100
34219332 R cqg 100
34219333 A eqg S 44.18 100
34219333 R dqg 100
34219333 A fqg S 44.19 200
34219334 A gqg B 44.13 100
34219334 R fqg 200
34219334 R eqg 100
34219335 A hqg S 44.18 100
34219335 R gqg 100
34219340 R xpg 100
34219343 R qpg 100
34219348 A iqg S 44.20 100
34219353 A jqg S 44.18 100
34219363 A kqg B 44.09 100
34219370 A lqg S 44.25 100
34219371 R zpg 250
34219371 R bqg 200
34219372 R hqg 100
34219372 A mqg S 44.18 200
34219372 A nqg S 44.18 100
34219373 A oqg B 44.12 250
34219374 R nqg 100
34219374 A pqg S 44.18 100
34219381 R mqg 200
34219381 R pqg 100
34219381 A qqg S 44.19 200
34219381 R oqg 250
34219381 A rqg S 44.18 100
34219382 A sqg B 44.13 250
34219388 R qqg 200
34219389 R rqg 100
34219389 A tqg S 44.18 200
34219390 A uqg S 44.18 100
34219391 R tqg 200
34219392 A vqg S 44.19 200
34219392 R uqg 100
34219392 A wqg S 44.18 100
34219398 A xqg B 44.15 100
34219402 A yqg S 44.25 100
34219403 R lqg 100
34219403 A zqg B 44.09 100
34219404 R kqg 100
34219410 R vqg 200
34219411 R yqg 100
34219411 R wqg 100
34219412 R npg 250
34219412 A arg S 44.18 100
34219412 R ipg 100
34219412 R jpg 100
34219412 A brg B 44.15 100
34219413 A crg B 44.15 100
34219413 A drg S 44.19 200
34219414 A erg S 44.19 250
34219416 A frg B 44.14 100
34219436 A grg B 44.09 100
34219436 R zqg 100
34219442 A hrg S 44.24 100
34219442 R hrg 100
34219466 A irg S 44.18 100
34219468 A jrg B 44.09 100
34219468 R grg 100
34219469 R arg 100
34219470 R drg 200
34219470 A krg S 44.18 100
34219470 R irg 100
34219470 A lrg S 44.19 200
34219470 A mrg S 44.18 100
34219471 R krg 100
34219471 A nrg S 44.19 100
34219472 R lrg 200
34219473 A org S 44.25 100
34219478 R nrg 100
34219478 R mrg 100
34219479 A prg S 44.18 100
34219479 A qrg S 44.18 100
34219479 A rrg S 44.19 200
34219489 R qrg 100
34219489 R rrg 200
34219490 A srg S 44.18 100
34219490 R prg 100
34219491 A trg S 44.18 100
34219491 A urg S 44.19 200
34219491 R erg 250
34219492 A vrg S 44.18 250
34219496 R xqg 100
34219498 R srg 100
34219499 A wrg S 44.18 100
34219502 A xrg B 44.09 100
34219502 R jrg 100
34219512 R xrg 100
34219513 A yrg B 44.16 100
34219514 R crg 100
34219514 A zrg B 44.16 100
34219515 R brg 100
34219515 A asg B 44.16 100
34219519 R wrg 100
34219520 A bsg S 44.18 100
34219521 R vrg 250
34219522 R bsg 100
34219522 A csg S 44.18 100
34219524 A dsg S 44.19 250
34219525 R yrg 100
34219536 A esg B 44.16 100
34219536 R zrg 100
34219537 A fsg B 44.16 100
34219537 R asg 100
34219537 A gsg B 44.16 100
34219543 A hsg B 44.09 100
34219552 A isg B 44.09 100
34219552 R hsg 100
34219560 R dsg 250
34219561 A jsg S 44.18 250
34219562 R sqg 250
34219562 R jsg 250
34219565 A ksg B 44.12 250
34219565 R uog 100
34219565 A lsg S 44.19 250
34219591 A msg B 44.09 100
34219591 R isg 100
34219608 R csg 100
34219608 A nsg S 44.19 100
34219621 A osg B 44.10 100
34219621 R msg 100
34219703 R urg 200
34219703 R trg 100
34219704 A psg S 44.19 100
34219709 R frg 100
34219709 R iqg 100
34219722 R apg 100
34219724 A qsg S 44.19 200
34219724 R nsg 100
34219725 A rsg S 44.19 100
34219725 R qsg 200
34219732 R org 100
34219732 R rsg 100
34219734 A ssg S 44.19 100
34219741 A tsg S 44.19 200
34219744 R esg 100
34219745 R tsg 200
34219745 A usg S 44.18 100
34219752 A vsg B 44.10 100
34219753 R osg 100
34219754 A wsg B 44.16 100
34219755 R fsg 100
34219755 A xsg B 44.16 100
34219755 R gsg 100
34219756 A ysg B 44.16 100
34219758 A zsg S 44.19 200
34219762 A atg S 44.25 100
34219783 A btg B 44.10 100
34219784 R vsg 100
34219810 R ksg 250
34219811 A ctg B 44.13 250
34219950 R psg 100
34219950 R zsg 200
34219950 A dtg S 44.18 200
34219951 A etg S 44.18 100
34219951 R ssg 100
34219951 R lsg 250
34219952 A ftg S 44.18 100
34219952 A gtg S 44.18 250
34219957 R wsg 100
34219957 R ysg 100
34219958 R ftg 100
34219958 A htg B 44.13 100
34219958 A itg S 44.18 100
34219964 R jqg 100
34219975 A jtg S 44.18 100
34219976 R itg 100
34219976 A ktg S 44.17 100
34219981 R btg 100
34219984 R xsg 100
34219985 R etg 100
34219985 A ltg B 44.13 44
34219986 A mtg S 44.17 100
34219987 R ktg 100
34219987 A ntg B 44.13 100
34219987 A otg B 44.11 200
34219987 A ptg S 44.17 100
34219988 R htg 100
34219988 A qtg B 44.13 100
34219988 A rtg B 44.14 100
34219988 R mtg 100
34219989 R ltg 44
34219989 A stg B 44.14 100
34219989 A ttg S 44.17 56
34219992 A utg S 44.25 100
34219992 R atg 100
34219996 R qtg 100
34219996 R qog 200
34219997 A vtg B 44.14 200
34220004 A wtg B 44.14 100
34220005 R stg 100
34220005 R rtg 100
34220005 A xtg B 44.14 100
34220006 A ytg B 44.14 100
34220007 R ntg 100
34220011 A ztg B 44.07 100
34220012 R vtg 200
34220012 A aug B 44.13 200
34220016 R wtg 100
34220022 A bug S 44.17 100
34220023 R gtg 250
34220024 A cug S 44.18 250
34220024 R ptg 100
34220025 A dug S 44.17 100
34220025 R dtg 200
34220026 R ttg 56
34220026 A eug S 44.18 200
34220026 A fug S 44.17 56
34220032 A gug B 44.07 100
34220033 R ztg 100
34220034 A hug S 44.25 100
34220034 R utg 100
34220038 R cug 250
34220040 A iug S 44.18 250
34220063 A jug B 44.07 100
34220063 R gug 100
34220065 A kug S 44.24 100
34220065 R hug 100
34220094 A lug B 44.07 100
34220094 R jug 100
34220134 A mug B 44.07 100
34220134 R lug 100
34220162 R ctg 250
34220163 R iug 250
34220163 A nug B 44.14 250
34220163 A oug S 44.18 250
34220164 R aug 200
34220164 A pug B 44.14 200
34220165 A qug B 44.07 100
34220165 R mug 100
34220181 A rug S 44.17 100
34220187 R oug 250
34220190 A sug S 44.18 250
34220192 R nug 250
34220194 A tug S 44.24 100
34220194 R kug 100
34220195 A uug B 44.13 250
34220197 A vug B 44.07 100
34220197 R qug 100
34220228 A wug B 44.07 100
34220228 R vug 100
34220254 A xug B 44.14 100
34220255 R ytg 100
34220255 A yug B 44.14 100
34220256 R xtg 100
34220256 R dug 100
34220256 A zug B 44.14 100
34220257 A avg S 44.17 100
34220258 A bvg B 44.08 100
34220259 R wug 100
34220262 R xug 100
34220265 R otg 200
34220290 A cvg B 44.08 100
34220290 R bvg 100
34220290 R tug 100
34220295 R rug 100
34220321 A dvg S 44.24 100
34220348 R sug 250
34220349 A evg S 44.18 250
34220424 A fvg S 44.16 500
34220425 R pug 200
34220425 R avg 100
34220425 A gvg B 44.13 200
34220425 A hvg S 44.17 100
34220426 R fug 56
34220426 A ivg S 44.16 56
34220453 A jvg B 44.11 600
34220458 R evg 250
34220460 A kvg S 44.18 250
34220466 R kvg 250
34220466 A lvg S 44.18 250
34220468 A mvg S 44.24 100
34220469 R dvg 100
34220485 A nvg B 43.56 25
34220493 R zug 100
34220493 A ovg B 44.13 100
34220496 A pvg B 44.12 100
34220520 R uug 250
34220522 R cvg 100
34220522 A qvg B 44.12 250
34220534 A rvg S 44.24 100
34220534 R mvg 100
34220549 R qvg 250
34220549 A svg B 44.13 250
34220552 A tvg B 44.07 100
34220570 A uvg S 44.24 100
34220570 R rvg 100
34220777 R usg 100
34221230 R lvg 250
34221230 A vvg S 44.17 250
34221231 R eug 200
34221232 A wvg S 44.17 200
34221261 A xvg S 44.24 100
34221261 R uvg 100
34221852 A yvg S 44.16 200
34221890 A zvg S 44.24 100
34221890 R xvg 100
34222291 R ivg 56
34222401 A awg S 44.16 56
34222446 R svg 250
34222448 A bwg B 44.12 250
34222469 R awg 56
34222499 A cwg S 44.17 100
34222500 R hvg 100
34222500 A dwg S 44.17 100
34222502 R cwg 100
34222502 A ewg S 44.17 100
34222503 R dwg 100
34222503 A fwg S 44.16 100
34222504 R ewg 100
34222504 A gwg S 44.16 100
34222515 R bwg 250
34222516 A hwg B 44.13 250
34222535 A iwg S 44.23 100
34222535 R zvg 100
34223322 A jwg S 44.23 100
34223322 R iwg 100
34223377 A kwg S 44.16 100
34223688 R bug 100
34225505 R hwg 250
34225508 A lwg B 44.12 250
34225579 R yug 100
34225579 R fwg 100
34225579 R gvg 200
34225579 A mwg B 44.13 68
34225579 R vvg 250
34225579 A nwg B 44.13 200
34225580 R gwg 100
34225580 A owg S 44.17 250
34225580 A pwg S 44.16 100
34225580 A qwg S 44.16 100
34225581 R wvg 200
34225581 R nwg 200
34225581 A rwg S 44.16 200
34225583 A swg B 44.11 200
34225584 A twg B 44.13 100
34225585 A uwg S 44.16 100
34225586 R mwg 68
34225586 A vwg B 44.14 68
34225587 A wwg B 44.13 100
34225587 R jtg 100
34225588 R swg 200
34225588 A xwg B 44.13 200
34225592 R lwg 250
34225592 R ovg 100
34225592 A ywg B 44.13 100
34225594 R xwg 200
34225594 R rwg 200
34225594 A zwg S 44.16 200
34225595 A axg B 44.12 250
34225596 R pvg 100
34225597 A bxg S 44.16 100
34225598 R pwg 100
34225599 A cxg S 44.16 100
34225599 R qwg 100
34225599 A dxg S 44.16 100
34225602 A exg B 44.12 200
34225609 R wwg 100
34225609 R bxg 100
34225610 A fxg S 44.22 100
34225610 R jwg 100
34225613 A gxg S 44.16 100
34225614 R cxg 100
34225615 A hxg S 44.15 100
34225616 R dxg 100
34225616 A ixg S 44.16 100
34225616 A jxg S 44.15 100
34225617 R axg 250
34225619 A kxg B 44.11 250
34225622 R gxg 100
34225623 R tvg 100
34225630 A lxg S 44.15 100
34225631 R jxg 100
34225631 A mxg S 44.15 100
34225633 R hxg 100
34225633 R vwg 68
34225633 A nxg B 44.13 68
34225634 A oxg S 44.15 100
34225636 R owg 250
34225636 A pxg S 44.16 250
34225639 A qxg S 44.15 100
34225649 R exg 200
34225650 A rxg B 44.11 200
34225651 R kxg 250
34225651 R twg 100
34225653 A sxg B 44.06 100
34225653 A txg B 44.11 250
34225655 A uxg B 44.11 100
34225660 R ywg 100
34225660 A vxg B 44.12 100
34225664 A wxg B 44.06 100
34225664 R sxg 100
34225665 R uxg 100
34225671 R txg 250
34225673 A xxg S 44.15 100
34225673 A yxg B 44.11 250
34225675 A zxg B 44.10 100
34225679 R wxg 100
34225680 R pxg 250
34225680 A ayg S 44.15 250
34225681 R ayg 250
34225683 A byg S 44.16 250
34225692 A cyg S 44.22 100
34225692 R fxg 100
34225710 A dyg B 44.05 100
34226000 R yxg 250
34226001 A eyg B 44.11 250
34226009 R cyg 100
34226019 A fyg B 44.05 100
34226019 R dyg 100
34226040 A gyg S 44.22 100
34226049 A hyg B 44.06 100
34226049 R fyg 100
34226076 R byg 250
34226077 A iyg S 44.15 250
34226320 A jyg S 44.22 100
34226320 R gyg 100
34226351 R eyg 250
34226353 R zwg 200
34226353 A kyg S 44.15 200
34226353 A lyg B 44.11 250
34226723 R kwg 100
34226966 A myg S 44.14 400
34226968 A nyg S 44.14 100
34226969 A oyg S 44.14 100
34226990 R nyg 100
34226991 R zxg 100
34227017 R jyg 100
34227046 A pyg S 44.22 100
34227262 R uwg 100
34227751 A qyg B 42.66 3
34228073 A ryg B 43.63 400
34228170 R iyg 250
34228173 A syg S 44.16 250
34228342 R lyg 250
34228342 A tyg B 44.12 250
34228368 R tyg 250
34228368 A uyg B 44.13 250
34228369 R nxg 68
34228370 A vyg B 44.13 68
34228370 R kyg 200
34228411 A wyg B 44.06 100
34228412 R hyg 100
34228442 A xyg B 44.06 100
34228442 R wyg 100
34228613 R myg 100
34228645 A yyg S 44.14 100
34228748 R myg 100
34229008 R ixg 100
34229159 R myg 20
34229175 R myg 180
34229514 A zyg B 44.13 100
34229515 A azg B 44.13 100
34229547 A bzg S 44.14 180
34229547 R mxg 100
34229548 A czg S 44.14 100
34229548 R vxg 100
34229549 A dzg B 44.11 100
34229612 A ezg S 44.22 100
34229612 R pyg 100
34229884 R azg 100
34229886 R zyg 100
34229969 A fzg B 44.13 100
34229972 A gzg B 44.13 100
34229974 R gzg 100
34230054 A hzg B 44.13 100
34230058 R bzg 180
34230059 R czg 100
34230059 R dzg 100
34230059 A izg S 44.15 100
34230060 A jzg B 44.13 100
34230060 A kzg S 44.14 100
34230060 R hzg 100
34230062 R fzg 100
34230068 R qxg 100
34230106 R kzg 100
34230126 A lzg S 46.25 33
34230129 R ezg 100
34230161 A mzg S 44.22 100
34230293 A nzg B 44.13 100
34230296 A ozg B 44.13 100
34230348 A pzg S 44.65 400
34230352 R ozg 100
34230354 R nzg 100
34230382 R syg 250
34230385 A qzg S 44.17 250
34230486 R yyg 100
34230487 A rzg S 44.16 200
34230487 A szg S 44.14 100
34230487 R szg 100
34230488 A tzg S 44.15 100
34230489 A uzg S 44.14 100
34230808 R uzg 100
34230913 R qzg 250
34230913 A vzg S 44.16 250
34230933 R vzg 250
34230935 A wzg S 44.17 250
34231032 R wzg 250
34231032 A xzg S 44.16 250
34231134 R xzg 250
34231137 A yzg S 44.17 250
34231158 R xxg 100
34231279 R xyg 100
34231308 A zzg B 44.06 100
34231485 R vyg 68
34231485 R uyg 139
34231488 R oxg 100
34231489 A aah S 44.15 100
34231490 R izg 100
34231491 A bah S 44.15 100
34231491 R aah 100
34231492 A cah S 44.15 100
34231493 R bah 100
34231493 A dah S 44.15 100
34231495 R uyg 111
34231495 R yzg 250
34231495 A eah S 44.17 100
34231495 A fah S 44.16 250
34231496 R jzg 100
34231496 R dah 100
34231496 A gah B 44.11 100
34231496 A hah S 44.14 100
34231497 R cah 100
34231497 A iah S 44.14 100
34231498 R rxg 200
34231499 A jah B 44.11 200
34231510 R iah 100
34231510 A kah S 44.15 100
34231518 R kah 100
34231518 A lah S 44.14 100
34231520 A mah S 44.22 100
34231520 R fah 250
34231520 R mzg 100
34231520 R zzg 100
34231521 A nah S 44.15 250
34231551 A oah B 44.05 100
34231570 R lah 100
34231570 A pah S 44.15 100
34231570 R rzg 200
34231571 A qah S 44.15 200
34231590 R pah 100
34231590 R nah 250
34231591 A rah S 44.15 100
34231592 R rah 100
34231592 A sah S 44.15 100
34231594 A tah S 44.16 250
34231600 R tah 250
34231600 A uah S 44.15 250
34231601 R sah 100
34231601 R gah 100
34231601 A vah B 44.13 100
34231601 A wah B 44.05 100
34231602 R oah 100
34231602 A xah S 44.15 100
34231602 A yah S 44.15 100
34231602 R hah 100
34231603 R xah 100
34231604 A zah S 44.15 100
34231610 R uah 250
34231613 A abh S 44.16 250
34231634 A bbh B 44.05 100
34231634 R wah 100
34231877 R tfg 300
34232035 A cbh S 44.14 100
34232036 R vah 100
34232036 R yah 100
34232036 A dbh B 44.11 100
34232037 A ebh S 44.14 100
34232038 R zah 100
34232038 A fbh S 44.14 100
34232038 R lxg 100
34232040 R eah 100
34232040 A gbh B 44.10 100
34232048 R jah 200
34232050 R abh 250
34232051 A hbh S 44.15 250
34232079 A ibh S 44.21 100
34232079 R mah 100
34232156 A jbh S 44.14 300
34232157 R fbh 100
34232158 A kbh S 44.14 100
34232159 R ebh 100
34232159 A lbh S 44.14 100
34232173 R hbh 250
34232174 A mbh S 44.15 250
34232199 A nbh S 44.21 100
34232200 R ibh 100
34232231 A obh S 44.21 100
34232231 R nbh 100
34232261 A pbh S 44.21 100
34232262 R obh 100
34232270 R tzg 100
34232898 A qbh B 44.11 100
34232898 R kbh 100
34232899 R qah 200
34232899 A rbh S 44.14 100
34232899 A sbh S 44.15 200
34232919 R gbh 100
34232928 R bbh 100
34232959 A tbh B 44.05 100
34233903 R mbh 250
34233906 A ubh S 44.17 250
34233957 A vbh S 44.13 200
34233958 R lbh 100
34233958 R qbh 100
34233958 R rbh 100
34233959 R dbh 100
34233959 A wbh B 44.11 100
34233959 A xbh S 44.14 100
34233959 A ybh S 44.13 100
34233959 A zbh B 44.09 200
34233959 A ach B 44.09 100
34233964 R cbh 100
34233989 R ubh 250
34233990 A bch S 44.17 250
34233999 R tbh 100
34234000 A cch S 44.21 100
34234000 R pbh 100
34234026 R bch 250
34234029 A dch B 44.04 100
34234029 A ech S 44.17 250
34234031 R ofe 100
34234032 R xbh 100
34234032 R wbh 100
34234032 A fch B 44.09 100
34234034 A gch S 44.13 100
34234034 R ach 100
34234035 A hch B 44.09 100
34234036 R fch 100
34234036 A ich B 44.09 100
34234036 A jch B 44.09 100
34234037 R hch 100
34234037 A kch B 44.10 100
34234040 R dch 100
34234058 A lch S 44.20 100
34234058 R cch 100
34234071 A mch B 44.04 100
34234078 R mch 100
34234083 R vbh 100
34234084 R ich 100
34234084 A nch B 44.10 100
34234084 R gch 100
34234084 A och S 44.14 100
34234084 R kch 100
34234085 A pch B 44.10 100
34234085 R nch 100
34234085 A qch B 44.10 100
34234087 R pch 100
34234087 A rch B 44.10 100
34234088 R qch 100
34234088 A sch B 44.10 100
34234088 A tch S 44.20 100
34234089 R rch 100
34234089 R lch 100
34234089 A uch B 44.10 100
34234090 A vch B 44.10 100
34234090 R sch 100
34234091 R uch 100
34234091 A wch B 44.10 100
34234092 R vch 100
34234092 A xch B 44.11 100
34234093 R wch 100
34234093 A ych B 44.11 100
34234094 R xch 100
34234094 A zch B 44.11 100
34234095 R ych 100
34234095 A adh B 44.11 100
34234096 R zch 100
34234096 A bdh B 44.11 100
34234113 A cdh B 44.04 100
34234689 R vbh 100
34234690 R adh 100
34234690 R bdh 100
34234690 A ddh B 44.11 100
34234691 A edh B 44.11 100
34234698 R ybh 100
34234698 A fdh S 44.14 100
34234700 R ech 250
34234702 A gdh S 44.18 250
34234709 R edh 100
34234709 A hdh B 44.11 100
34234710 R och 100
34234710 A idh S 44.14 100
34234710 R ddh 100
34234711 A jdh B 44.12 100
34234711 R fdh 100
34234712 A kdh S 44.14 100
34234729 A ldh B 44.04 100
34234729 R cdh 100
34234729 R tch 100
34234730 R hdh 100
34234730 A mdh B 44.11 100
34234745 A ndh S 44.13 1000
34234746 R mdh 100
34234746 R idh 100
34234746 R jdh 100
34234746 R kdh 100
34234746 A odh B 44.09 100
34234746 A pdh B 44.09 100
34234747 A qdh S 44.13 100
34234747 A rdh S 44.13 100
34234747 R zbh 200
34234748 A sdh B 44.10 200
34234749 R odh 100
34234749 A tdh B 44.10 100
34234749 R pdh 100
34234749 A udh B 44.10 100
34234750 R sdh 200
34234750 A vdh B 44.10 200
34234751 R tdh 100
34234751 A wdh B 44.10 100
34234752 R udh 100
34234752 A xdh B 44.10 100
34234753 R vdh 200
34234753 A ydh B 44.10 200
34234754 R wdh 100
34234754 A zdh B 44.10 100
34234754 R gdh 250
34234754 R xdh 100
34234755 A aeh B 44.10 100
34234755 A beh S 44.17 250
34234760 R beh 250
34234761 A ceh S 44.21 100
34234762 A deh S 44.17 250
34234763 R deh 250
34234764 A eeh S 44.17 250
34234766 R eeh 250
34234768 A feh S 44.17 250
34234789 R ldh 100
34234789 A geh S 44.21 100
34234790 R ceh 100
34234819 A heh B 44.04 100
34234821 A ieh S 44.20 100
34234821 R geh 100
34234851 A jeh S 44.20 100
34234852 R ieh 100
34234943 R ndh 100
34235027 A keh S 44.14 100
34235334 A leh S 44.20 100
34235334 R jeh 100
34235382 A meh S 44.15 200
34235400 R feh 250
34235406 A neh S 44.15 250
34235480 R neh 250
34235483 A oeh S 44.16 250
34235788 R jvg 600
34235794 A peh B 44.11 400
34235796 A qeh B 44.10 100
34235797 R aeh 100
34235797 A reh B 44.11 100
34235798 R zdh 100
34235798 A seh B 44.10 100
34235799 R peh 400
34236071 R keh 100
34236154 A teh S 44.14 100
34236298 R oeh 250
34236825 A ueh S 44.16 250
34236918 R ndh 900
34236922 A veh S 44.13 100
34236923 A weh S 44.13 200
34236924 R rdh 100
34236924 A xeh S 44.13 100
34236925 R weh 200
34236929 R ueh 250
34236931 A yeh S 44.17 250
34237843 R teh 100
34238113 R yeh 250
34238113 A zeh S 44.16 250
34238130 A afh B 44.11 300
34238840 A bfh S 44.13 100
34238845 A cfh B 44.12 200
34238846 R seh 100
34238846 R xeh 100
34238846 R qdh 100
34238846 A dfh S 44.14 100
34238846 A efh B 44.11 100
34238846 A ffh S 44.13 100
34238848 R bfh 100
34238849 R reh 100
34238849 A gfh B 44.11 100
34238850 A hfh S 44.13 100
34238850 R jch 100
34238860 R zeh 250
34238860 A ifh S 44.15 250
34238866 R cfh 100
34238890 A jfh B 44.04 100
34238890 R heh 100
34238914 R ifh 250
34238916 A kfh S 44.16 250
34238963 A lfh B 44.13 100
34238964 R ffh 100
34238964 R efh 100
34238964 A mfh B 44.11 100
34238964 A nfh S 44.14 100
34238965 R gfh 100
34238965 A ofh B 44.11 100
34238966 R dfh 100
34238966 A pfh S 44.14 100
34238967 R mfh 100
34238967 A qfh B 44.11 100
34238968 R ofh 100
34238968 A rfh B 44.12 100
34238969 R ydh 200
34238970 A sfh B 44.11 200
34238980 R nfh 100
34238980 A tfh S 44.14 100
34238990 R kfh 250
34238990 A ufh S 44.15 250
34239010 A vfh B 44.05 100
34239011 R jfh 100
34239019 R pfh 100
34239020 A wfh S 44.14 100
34239040 A xfh B 44.05 100
34239040 R vfh 100
34239072 A yfh B 44.05 100
34239073 R xfh 100
34239143 R hfh 100
34239145 R sbh 200
34239202 R meh 200
34239206 R veh 100
34239206 R qfh 100
34239207 A zfh B 44.12 100
34239207 R tfh 100
34239207 A agh S 44.14 100
34239208 A bgh S 44.15 200
34239208 A cgh B 44.12 100
34239208 R rfh 100
34239230 R leh 100
34239261 A dgh S 44.21 100
34239262 A egh S 44.14 100
34239334 R egh 100
34239483 A fgh S 44.14 100
34239737 R fgh 100
34239799 R lfh 100
34239799 R cfh 100
34239799 A ggh S 44.12 800
34239800 R sfh 200
34239800 R zfh 100
34239800 A hgh B 44.11 100
34239800 R agh 100
34239800 R wfh 100
34239800 R cgh 100
34239800 A igh B 44.11 100
34239801 A jgh S 44.13 100
34239801 A kgh S 44.13 100
34239802 R hgh 100
34239802 A lgh B 44.10 100
34239804 A mgh B 44.10 100
34239805 R qeh 100
34239806 A ngh B 44.09 200
34239810 R ufh 250
34239810 A ogh S 44.15 250
34239811 R bgh 200
34239812 A pgh S 44.15 200
34239812 A qgh B 44.11 100
34239814 A rgh B 44.11 100
34239823 R igh 100
34239823 A sgh B 44.10 100
34239826 R mgh 100
34239827 R qgh 100
34239837 R ggh 800
34239838 R kgh 100
34239838 R lgh 100
34239838 A tgh S 44.14 100
34239838 A ugh B 44.11 100
34239839 A vgh S 44.13 100
34239842 A wgh S 44.21 100
34239842 R dgh 100
34239842 R yfh 100
34239846 R ogh 250
34239846 A xgh S 44.14 250
34239852 R sgh 100
34239852 R jgh 100
34239853 A ygh B 44.11 100
34239853 R rgh 100
34239853 R tgh 100
34239853 A zgh S 44.14 100
34239853 A ahh S 44.14 100
34239854 R zgh 100
34239855 A bhh S 44.14 100
34239858 R bhh 100
34239859 A chh S 44.13 100
34239861 R vgh 100
34239864 A dhh S 44.13 100
34239870 R chh 100
34239871 A ehh S 44.14 100
34239873 A fhh B 44.04 100
34239875 R xgh 250
34239881 A ghh S 44.15 250
34239891 R ehh 100
34239891 R ugh 100
34239891 R ahh 100
34239891 A hhh B 44.09 100
34239891 A ihh B 44.09 100
34239891 A jhh S 44.20 100
34239891 A khh S 44.13 100
34239891 R wgh 100
34239892 A lhh B 44.04 100
34239892 A mhh S 44.13 100
34239892 R ygh 100
34239892 R ngh 200
34239892 R fhh 100
34239892 A nhh B 44.09 200
34239893 R ihh 100
34239894 R dhh 100
34239894 A ohh B 44.09 100
34239894 A phh B 44.09 100
34239894 R hhh 100
34239895 R nhh 200
34239895 A qhh S 44.13 100
34239896 A rhh B 44.10 200
34239896 R pgh 200
34239897 A shh S 44.13 200
34239897 R phh 100
34239898 R ohh 100
34239898 A thh B 44.10 100
34239898 A uhh B 44.10 100
34239899 A vhh S 44.13 100
34239899 R jhh 100
34239899 R rhh 200
34239899 A whh B 44.10 200
34239900 R mhh 100
34239900 R khh 100
34239900 A xhh S 44.13 100
34239900 R uhh 100
34239900 R shh 200
34239901 A yhh B 44.10 100
34239901 R thh 100
34239901 A zhh S 44.13 100
34239901 A aih B 44.10 100
34239901 R qhh 100
34239901 A bih S 44.14 200
34239901 R ghh 250
34239902 A cih B 44.09 200
34239902 R whh 200
34239902 A dih S 44.14 250
34239903 R bih 200
34239903 A eih S 44.13 200
34239903 A fih S 44.13 100
34239912 R vhh 100
34239919 A gih S 44.13 100
34239920 R lhh 100
34239921 R fih 100
34239922 R zhh 100
34239922 A hih S 44.13 100
34239923 A iih S 44.13 100
34239923 R xhh 100
34239924 A jih S 44.13 100
34239924 R iih 100
34239925 A kih S 44.12 200
34239926 R gih 100
34239927 R hih 100
34239927 A lih S 44.12 100
34239928 A mih S 44.13 100
34239928 R mih 100
34239941 R kih 200
34239942 R jih 100
34239942 A nih S 44.13 100
34239943 A oih S 44.19 100
34239950 A pih B 44.03 100
34239950 R eih 200
34239950 R lih 100
34239950 A qih B 44.10 200
34239951 A rih S 44.14 200
34239951 A sih S 44.13 100
34239951 R cih 200
34239951 R aih 100
34239951 R yhh 100
34239951 A tih B 44.11 100
34239951 A uih B 44.10 100
34239955 A vih S 44.15 100
34239962 A wih B 44.11 100
34239964 A xih S 44.13 100
34239972 R vih 100
34239973 A yih S 44.19 100
34239973 A zih S 44.12 200
34239973 R oih 100
34239974 R qih 200
34239974 R tih 100
34239974 R rih 200
34239974 A ajh B 44.10 100
34239975 R xih 100
34239975 A bjh B 44.09 200
34239977 A cjh S 44.13 200
34239979 R uih 100
34239979 A djh B 44.10 100
34239980 R dih 250
34239981 A ejh S 44.14 250
34239981 R ajh 100
34239981 A fjh B 44.10 100
34239982 R pih 100
34239982 R yih 100
34239987 R ejh 250
34239989 R djh 100
34239990 A gjh B 44.09 100
34239990 A hjh S 44.14 250
34239992 R hjh 250
34239993 A ijh S 44.14 250
34239995 R zih 200
34239996 R gjh 100
34239996 R cjh 200
34239996 R fjh 100
34239997 A jjh B 44.11 100
34239997 A kjh B 44.11 100
34239997 A ljh S 44.16 200
34239998 R ijh 250
34240002 A mjh S 44.14 250
34240003 R jjh 100
34240003 A njh B 44.11 100
34240011 R mjh 250
34240012 A ojh S 44.13 100
34240013 A pjh B 44.04 100
34240014 A qjh S 44.20 100
34240015 A rjh S 44.14 250
34240015 R sih 100
34240016 A sjh S 44.13 100
34240016 R ljh 200
34240017 A tjh S 44.14 200
34240022 A ujh S 44.20 100
34240023 R qjh 100
34240027 R rjh 250
34240027 A vjh S 44.14 250
34240033 R wih 100
34240038 A wjh S 44.13 100
34240040 R wjh 100
34240040 R njh 100
34240040 R sjh 100
34240041 A xjh B 44.11 100
34240041 R nih 100
34240041 A yjh S 44.13 100
34240041 R kjh 100
34240041 A zjh S 44.13 100
34240041 A akh B 44.09 100
34240042 R xjh 100
34240042 A bkh B 44.09 100
34240042 A ckh S 44.13 100
34240043 R bjh 200
34240043 A dkh B 44.09 200
34240043 R tjh 200
34240044 A ekh S 44.13 200
34240044 R ckh 100
34240044 R bkh 100
34240044 A fkh B 44.09 100
34240045 R akh 100
34240045 A gkh B 44.09 100
34240045 R ekh 200
34240046 R dkh 200
34240046 A hkh B 44.10 200
34240047 R gkh 100
34240047 A ikh B 44.10 100
34240048 R fkh 100
34240048 A jkh B 44.10 100
34240048 R vjh 250
34240049 R hkh 200
34240049 A kkh B 44.10 200
34240050 R jkh 100
34240050 A lkh B 44.10 100
34240051 R ikh 100
34240051 A mkh B 44.10 100
34240053 A nkh S 44.20 100
34240054 R ujh 100
34240054 A okh S 44.14 250
34240055 A pkh S 44.14 200
34240059 R kkh 200
34240060 A qkh B 44.10 200
34240060 R lkh 100
34240061 A rkh B 44.10 100
34240061 R mkh 100
34240061 A skh B 44.10 100
34240069 R pjh 100
34240080 R okh 250
34240081 A tkh S 44.14 250
34240084 A ukh S 44.13 100
34240085 R qkh 200
34240085 A vkh B 44.09 200
34240094 A wkh S 44.12 200
34240095 R pkh 200
34240095 A xkh S 44.13 200
34240096 R ukh 100
34240099 A ykh B 44.03 100
34240151 R skh 100
34240151 A zkh B 44.09 100
34240152 R yjh 100
34240152 A alh S 44.13 100
34240184 A blh S 44.19 100
34240184 R nkh 100
34240184 R ykh 100
34240215 A clh S 44.19 100
34240216 R blh 100
34240217 A dlh B 44.03 100
34240231 A elh B 44.03 100
34240232 R dlh 100
34240588 R afh 63
34240589 R zjh 100
34240589 A flh S 44.12 100
34240589 R tkh 250
34240590 A glh S 44.13 250
34240591 R wkh 200
34240592 R flh 100
34240592 R alh 100
34240592 A hlh S 44.13 100
34240592 A ilh S 44.13 100
34240593 A jlh S 44.12 100
34240593 R zkh 100
34240593 A klh B 44.10 100
34240594 R rkh 100
34240595 A llh B 44.10 100
34240595 R jlh 100
34240595 A mlh S 44.13 100
34240597 R mlh 100
34240597 A nlh S 44.12 100
34240599 R nlh 100
34240607 R afh 39
34240644 R afh 198
34240644 R glh 250
34240644 R klh 100
34240644 R hlh 100
34240644 R xkh 200
34240644 A olh S 44.13 100
34240645 A plh S 44.14 200
34240645 A qlh S 44.13 100
34240646 A rlh B 44.10 100
34240646 A slh B 44.09 100
34240646 R llh 100
34240646 R ilh 100
34240647 A tlh S 44.13 200
34240647 R plh 200
34240647 A ulh S 44.13 100
