28800538 A b S 44.26 100
28800562 A c B 44.10 100
28800744 R b 100
28800758 A d B 44.18 157
28800773 A e S 44.38 100
28800796 R d 157
28800812 A f B 44.18 157
28800974 A g S 44.27 100
28800975 R e 100
28812071 R f 157
28813129 A h B 43.68 50
28813830 A i S 44.18 100
28814087 A j S 44.18 1000
28814834 R c 100
28814864 A k B 44.09 100
28815774 R k 100
28815804 A l B 44.07 100
28815937 R j 1000
28816244 R l 100
28816245 A m S 44.22 100
28816245 R g 100
28816273 A n B 44.03 100
28817570 A o S 44.14 170
28822172 R o 20
28823984 A p B 44.04 100
28823984 R n 100
28824454 R p 100
28824484 A q B 44.03 100
28826314 R q 100
28826343 A r B 43.89 100
28826384 R r 100
28826414 A s B 43.78 100
28826424 R s 100
28826454 A t B 43.75 100
28826455 R t 100
28826485 A u B 43.72 100
28835564 A v B 43.85 100
28835565 R u 100
28838797 A w S 44.15 500
28841307 A x S 44.40 100
28845097 A y S 44.10 500
28845547 R i 100
28845606 A z S 44.13 100
28854850 R w 500
28855165 A ab B 43.91 100
28855165 R v 100
28860037 A bb S 44.16 2000
28861264 A cb S 44.17 100
28861264 R m 100
28864794 A db S 44.11 100
28864794 R cb 100
28864870 A eb S 44.14 500
28865273 A fb S 44.10 100
28867484 R db 100
28867513 A gb S 44.17 100
28869845 A hb B 43.92 100
28873954 A ib S 44.11 100
28873954 R gb 100
28874354 R ab 100
28874384 A jb B 43.78 100
28875094 A kb S 44.11 100
28875094 R ib 100
28875613 R fb 100
28876376 R hb 100
28876444 R jb 100
28876474 A lb B 43.72 100
28876679 A mb B 43.85 400
28877234 A nb S 44.16 500
28882205 A ob B 43.73 100
28882205 R lb 100
28887878 R mb 400
28888674 R kb 100
28888703 A pb S 44.11 100
28890455 A qb B 43.73 100
28890455 R ob 100
28893420 A rb S 44.04 100
28893682 A sb B 43.86 100
28900102 R rb 100
28900102 A tb B 44.04 400
28900174 A ub B 43.90 100
28900175 R qb 100
28901422 R tb 200
28902467 R tb 200
28902514 A vb S 44.05 100
28902515 R pb 100
28902534 R ub 100
28902571 A wb B 43.79 100
28903189 A xb B 43.92 100
28903190 A yb S 44.05 100
28903191 R xb 100
28903191 R yb 100
28903215 A zb B 43.92 100
28903217 A ac S 44.05 100
28903224 A bc B 43.85 100
28903224 R wb 100
28903234 R bc 100
28903281 A cc B 43.85 100
28903874 R vb 100
28903903 A dc S 44.11 100
28904189 R zb 100
28904189 R ac 100
28904224 R cc 100
28904253 A ec B 43.79 100
28906024 A fc B 43.85 100
28906024 R ec 100
28910721 A gc S 44.04 81
28910722 R gc 81
28910723 A hc S 44.04 81
28910744 A ic S 44.05 100
28910744 R dc 100
28910934 A jc B 43.85 100
28910934 R fc 100
28911618 R y 500
28912942 R eb 500
28912943 R hc 81
28912944 A kc S 43.98 81
28917479 R kc 5
28917481 A lc B 43.93 100
28917481 A mc S 44.04 100
28917483 R lc 100
28917483 R mc 100
28917524 A nc B 43.86 100
28917525 R jc 100
28917525 R nc 100
28917531 A oc B 43.93 100
28917539 A pc S 44.04 100
28917581 A qc B 43.86 100
28918102 A rc B 43.92 100
28918103 R pc 100
28918132 A sc S 44.04 100
28918662 R oc 100
28918687 A tc B 43.92 100
28918703 R qc 100
28918733 A uc B 43.85 100
28919172 R kc 76
28919173 R tc 100
28919173 R sc 100
28919173 A vc S 43.98 76
28919248 A wc B 43.91 100
28919260 A xc S 44.03 100
28919822 R vc 76
28919823 A yc S 43.98 76
28922492 R wc 100
28922492 R xc 100
28923035 R yc 76
28923083 R ic 100
28923113 A zc S 44.11 100
28923389 A ad B 43.93 60
28923389 A bd S 44.04 81
28923390 R ad 60
28923390 R bd 81
28923391 A cd B 43.93 60
28923391 A dd S 44.04 81
28923830 A ed B 43.93 100
28923831 R ed 100
28923832 A fd B 43.93 100
28924703 R bb 2000
28924704 R cd 60
28924704 R dd 81
28924704 R fd 100
28924705 A gd S 44.04 81
28924706 A hd B 43.93 60
28924706 A id B 43.93 100
28925782 R gd 81
28925782 R id 100
28925782 R hd 60
28925783 A jd S 44.04 81
28925784 A kd B 43.93 60
28925784 A ld B 43.93 100
28927133 R jd 81
28927133 R kd 60
28927134 A md S 44.04 81
28927135 A nd B 43.93 60
28928212 R nd 60
28928212 R md 81
28928213 A od B 43.93 60
28928213 A pd S 44.04 81
28929118 R pd 50
28929120 A qd B 43.93 100
28929120 A rd S 44.04 100
28929121 R ld 100 
28929121 R pd 31
28929121 R qd 100
28929121 R rd 100
28929122 R od 60
28929122 A sd B 43.93 100
28929123 A td S 44.05 31
28929123 A ud B 43.93 60
28929128 A vd S 44.04 100
28929146 A wd B 43.93 100
28929155 A xd B 43.86 100
28929155 R uc 100
28929155 A yd S 44.11 100
28929156 R zc 100
28929164 R xd 100
28929164 R yd 100
28929214 A zd B 43.86 100
28929214 A ae S 44.11 100
28929949 R vd 100
28929949 R wd 100
28929954 A be B 43.86 100
28929955 R zd 100
28929980 R ud 60
28929981 R td 31
28929984 R ae 100
28930015 A ce S 44.11 100
28933055 A de B 43.94 400
28933056 R sd 100
28933058 A ee B 43.95 100
28933092 R ee 100
28933093 A fe B 43.95 100
28937566 A ge S 44.04 50
28937567 R fe 100
28937568 A he B 43.97 100
28937974 R he 100
28937976 A ie B 43.97 100
28938015 R ie 100
28938016 A je B 43.97 100
28939184 R h 50
28939185 R je 100
28939187 A ke B 43.97 100
28939244 A le B 43.86 50
28941591 R ke 100
28941592 A me B 43.98 100
28948444 A ne B 43.86 100
28948445 R be 100
28952850 R me 100
28953184 A oe S 44.05 100
28953185 R ce 100
28955224 R ne 100
28955254 A pe B 43.86 100
28956124 R oe 100
28956154 A qe S 44.11 100
28957556 R de 200
28974593 R de 150
28976148 R de 50
28981445 A re B 43.86 100
28981445 R pe 100
28982578 A se B 43.94 300
28983065 A te S 44.09 100
28983065 R qe 100
28987148 A ue B 43.94 100
28990475 A ve B 43.95 100
29005959 A we B 43.50 100
29013204 R ve 100
29013204 A xe S 43.95 400
29015549 R xe 400
29019177 R se 300
29019435 R ue 100
29024925 A ye B 43.88 100
29024925 R re 100
29026323 A ze S 44.04 100
29029845 A af B 43.88 100
29029845 R ye 100
29045384 A bf B 43.91 100
29045385 R af 100
29049454 R te 100
29049484 A cf S 44.11 100
29060700 R ze 100
29062694 A df B 43.92 100
29062695 R bf 100
29063604 R ge 50
29065594 R cf 100
29065624 A ef S 44.22 100
29066524 A ff B 43.92 100
29066525 R df 100
29067445 A gf B 43.92 100
29067445 R ff 100
29067603 A hf B 44.00 100
29067714 A if B 43.92 100
29067715 R gf 100
29067928 A jf B 44.00 100
29067985 A kf B 43.93 100
29067985 R if 100
29069573 A lf B 44.01 400
29070543 R hf 100
29070543 R jf 100
29070584 R kf 100
29070614 A mf B 43.92 100
29071194 A nf S 44.20 100
29071195 R ef 100
29078429 R sb 100
29078945 A of B 43.94 100
29078945 R mf 100
29083415 R nf 100
29083444 A pf S 44.22 100
29084145 A qf S 44.20 100
29084145 R pf 100
29088664 R qf 100
29088694 A rf S 44.22 100
29090034 A sf B 43.98 100
29090034 R of 100
29090062 R o 150
29091138 R lf 400
29098404 A tf S 44.20 100
29098404 R rf 100
29099784 A uf S 44.20 100
29099784 R tf 100
29104225 A vf S 44.19 100
29104225 R uf 100
29109165 A wf S 44.12 150
29116414 A xf S 44.12 500
29117069 A yf S 44.04 100
29117070 R yf 100
29117135 A zf S 44.18 100
29117135 R vf 100
29117174 R zf 100
29117204 A ag S 44.19 100
29126335 A bg S 44.19 100
29126335 R ag 100
29133152 A cg S 44.30 500
29136274 R bg 100
29136303 A dg S 44.19 100
29136445 A eg S 44.18 100
29136445 R dg 100
29140244 R eg 100
29140273 A fg S 44.19 100
29141555 A gg S 44.19 100
29141555 R fg 100
29144384 R gg 100
29144414 A hg S 44.19 100
29147554 A ig S 45.84 300
29155635 A jg S 44.19 100
29155635 R hg 100
29179978 A kg B 41.04 2
29190750 A lg B 41.04 2
29206262 R wf 150
29219025 A mg S 44.19 100
29219025 R jg 100
29221124 R mg 100
29221154 A ng S 44.19 100
29224214 R ng 100
29224244 A og S 44.19 100
29225758 A pg S 44.12 150
29226149 R pg 100
29226939 A qg B 44.05 300
29232295 A rg B 43.99 100
29232295 R sf 100
29236024 A sg S 49.44 2
29236995 A tg B 42.24 80
29238859 A ug S 49.44 2
29240461 A vg B 43.80 15
29241255 A wg S 44.12 100
29241921 A xg S 44.12 60
29256301 A yg B 44.06 100
29259595 A zg S 44.19 100
29259595 R og 100
29262844 R rg 100
29262874 A ah B 43.98 100
29263514 A bh B 43.99 100
29263515 R ah 100
29271045 A ch S 44.17 100
29271045 R zg 100
29272061 R wg 100
29272114 R bh 100
29272143 A dh B 43.98 100
29272625 A eh S 44.17 100
29272625 R ch 100
29272774 A fh S 44.17 100
29272775 R eh 100
29273935 A gh S 44.17 100
29273935 R fh 100
29278024 R yg 100
29278034 A hh B 44.05 100
29281492 A ih B 44.07 100
29282634 A jh S 44.17 100
29282634 R gh 100
29283205 A kh S 44.17 100
29283205 R jh 100
29284714 A lh S 44.16 100
29284715 R kh 100
29285355 A mh S 44.16 100
29285355 R lh 100
29286785 A nh S 44.16 100
29286786 R mh 100
29287644 A oh S 44.16 100
29287644 R nh 100
29288754 A ph S 44.16 100
29288755 R oh 100
29289475 A qh S 44.16 100
29289475 R ph 100
29290764 A rh S 44.16 100
29290765 R qh 100
29291334 A sh S 44.16 100
29291334 R rh 100
29293884 R ih 50
29293884 R ih 50
29296024 A th S 44.16 100
29296025 R sh 100
29302574 R th 100
29302603 A uh S 44.16 100
29303335 A vh S 44.16 100
29303335 R uh 100
29304904 R vh 100
29304934 A wh S 44.16 100
29305665 A xh S 44.16 100
29305665 R wh 100
29307345 A yh S 44.15 100
29307346 R xh 100
29308352 R hh 100
29308377 A zh B 44.08 100
29308394 R yh 100
29308424 A ai S 44.17 100
29309396 R zh 100
29309408 A bi B 44.08 100
29314590 R bi 100
29314601 A ci B 44.05 100
29318624 R qg 200
29322365 A di S 44.16 100
29322365 R ai 100
29323737 A ei S 44.09 50
29324648 R ei 50
29326854 A fi S 44.16 100
29326854 R di 100
29328094 R fi 100
29328124 A gi S 44.16 100
29328735 A hi B 43.98 100
29328735 R dh 100
29337321 R ci 100
29337368 A ii B 44.09 100
29337383 R gi 100
29337413 A ji S 44.17 100
29338284 R hi 100
29338314 A ki B 43.98 100
29341959 A li B 44.09 100
29343924 R ii 100
29343934 A mi B 44.05 100
29346427 R li 100
29350454 A ni B 43.99 100
29350455 R ki 100
29351884 A oi B 43.99 100
29351884 R ni 100
29353141 A pi B 44.06 100
29354031 R pi 100
29354094 R oi 100
29354124 A qi B 43.99 100
29354724 A ri B 43.99 100
29354724 R qi 100
29354780 A si B 44.06 100
29356556 R si 100
29357468 A ti B 44.06 100
29358874 R ri 100
29358904 A ui B 43.99 100
29359844 A vi S 44.17 100
29359845 R ji 100
29363904 R vi 100
29363934 A wi S 44.17 100
29365434 A xi B 43.99 100
29365435 R ui 100
29366928 R ti 100
29367565 R xi 100
29367594 A yi B 43.99 100
29368365 A zi S 44.17 100
29368365 R wi 100
29369897 A aj B 44.07 100
29371172 R aj 100
29373350 R mi 100
29373360 A bj B 44.04 100
29375576 A cj S 44.21 100
29384543 R bj 100
29384548 A dj B 44.03 100
29388641 R dj 100
29388647 A ej B 43.97 100
29392557 A fj S 44.10 50
29394874 R yi 100
29394904 A gj B 43.98 100
29397274 A hj B 43.20 100
29399803 R fj 50
29399844 R zi 100
29399874 A ij S 44.17 100
29400645 A jj S 44.17 100
29400645 R ij 100
29401924 R jj 100
29401954 A kj S 44.17 100
29402065 A lj B 43.99 100
29402065 R gj 100
29407806 A mj S 44.17 100
29407806 R kj 100
29409974 R mj 100
29410005 A nj S 44.17 100
29410625 A oj B 43.99 100
29410625 R lj 100
29411364 R oj 100
29411394 A pj B 43.99 100
29412025 A qj S 44.17 100
29412025 R nj 100
29416894 R pj 100
29416923 A rj B 43.98 100
29416966 A sj S 44.37 100
29421845 A tj S 44.17 100
29421845 R qj 100
29422934 A uj S 44.17 100
29422935 R tj 100
29426695 A vj S 44.12 150
29429655 A wj S 44.16 100
29429655 R uj 100
29435750 A xj B 43.68 100
29436397 R qg 100
29437344 R rj 100
29437374 A yj B 43.97 100
29437874 R yj 100
29437904 A zj B 43.91 100
29441385 A ak S 44.13 100
29441385 R wj 100
29444334 R ak 100
29444364 A bk S 44.16 100
29445475 A ck S 44.13 100
29445475 R bk 100
29454849 R ej 100
29454855 A dk B 43.98 100
29455544 A ek B 43.92 100
29455545 R zj 100
29456635 A fk B 43.92 100
29456635 R ek 100
29463988 A gk S 44.04 75
29465031 A hk B 43.98 200
29469726 A ik S 44.11 33
29471086 R dk 100
29471095 A jk B 43.99 100
29472354 R ck 100
29472354 R fk 100
29472384 A kk S 44.17 100
29472385 A lk B 43.92 100
29473515 A mk S 44.11 100
29473515 R kk 100
29473934 R mk 100
29473964 A nk S 44.17 100
29474605 A ok B 43.92 100
29474605 R lk 100
29475914 R ok 100
29475944 A pk B 43.92 100
29476374 A qk B 43.94 100
29476375 R pk 100
29477737 R gk 75
29478615 A rk B 43.94 100
29478615 R qk 100
29492046 R x 100
29492106 A sk S 44.10 100
29495145 R rk 100
29495175 A tk B 43.94 100
29497034 A uk S 44.11 100
29497035 R nk 100
29497133 R pg 50
29497254 A vk B 43.94 100
29497255 R tk 100
29497984 R vk 100
29498015 A wk B 43.94 100
29498634 R wk 100
29498664 A xk B 43.92 100
29499715 A yk S 44.04 100
29499815 A zk S 44.11 100
29499815 R uk 100
29504428 R jk 100
29504474 R zk 100
29504479 R yk 100
29504480 A al S 44.04 100
29504492 R al 100
29504504 A bl S 44.11 100
29504554 R bl 100
29504583 A cl S 44.17 100
29508304 A dl B 43.93 100
29508305 R xk 100
29508865 A el B 43.93 100
29508865 R dl 100
29517026 A fl S 44.13 75
29523425 R el 100
29523454 A gl B 43.91 100
29526295 A hl B 43.92 100
29526295 R gl 100
29536772 A il S 44.03 100
29539105 A jl B 43.94 100
29539105 R hl 100
29541004 R jl 100
29541033 A kl B 43.92 100
29541474 A ll S 44.04 50
29545655 A ml S 44.11 100
29545655 R cl 100
29548360 R sk 100
29548420 A nl S 44.40 100
29553541 A ol S 44.04 40
29556917 R il 100
29557006 A pl B 43.99 1000
29567865 A ql B 44.00 100
29572151 R ql 100
29572675 A rl B 43.92 100
29572675 R kl 100
29576385 A sl B 43.91 100
29596424 R rl 100
29596455 A tl B 43.92 100
29603659 A ul B 43.80 200
29610229 R ll 50
29610264 R ml 100
29610294 A vl S 44.17 100
29610445 A wl B 43.97 100
29610445 R tl 100
29614426 R wl 100
29614456 A xl B 43.92 100
29624627 R ol 40
29625176 A yl B 43.97 100
29625176 R xl 100
29640243 A zl B 44.04 100
29641037 A am B 44.01 100
29654777 A bm B 43.92 200
29662924 R yl 100
29662954 A cm B 43.91 100
29663688 R pl 1000
29666995 A dm S 44.11 100
29666995 R vl 100
29667275 R dm 100
29667305 A em S 44.17 100
29677686 A fm B 43.20 150
29677756 R xf 500
29709325 A gm B 43.92 100
29709325 R cm 100
29711906 R am 100
29719371 A hm B 44.04 100
29729844 R em 100
29729874 A im S 44.17 100
29730065 A jm B 44.03 100
29730065 R gm 100
29733515 R jm 100
29733544 A km B 43.92 100
29733677 A lm S 44.17 100
29733677 R im 100
29733746 A mm B 44.04 100
29733746 A nm S 44.11 100
29733747 R nm 100
29733748 R mm 100
29733781 A om S 44.11 100
29733785 A pm B 43.97 100
29733785 R km 100
29733786 R pm 100
29733786 A qm B 44.04 100
29733817 A rm B 43.92 100
29733825 A sm B 43.97 100
29733825 R rm 100
29734123 R qm 100
29734123 R om 100
29734164 R sm 100
29734194 A tm B 43.92 100
29734475 R le 50
29734543 A um B 44.00 50
29735634 R lm 100
29735664 A vm S 44.17 100
29737185 A wm B 43.97 100
29737185 R tm 100
29760052 R zl 100
29760264 A xm B 44.04 100
29776911 R wm 100
29777383 R vm 100
29792133 A ym B 44.07 1000
29798038 R ym 1000
29798297 A zm B 44.09 100
29800648 A an B 44.07 200
29822073 R zm 100
29839382 A bn B 44.05 200
29839530 R an 200
29847386 A cn S 44.11 100
29864954 A dn S 44.11 100
29874343 A en B 44.07 200
29929249 A fn B 44.05 200
29964740 R en 200
29965088 R hm 100
30015010 A gn S 44.06 50
30023709 R bn 200
30024257 R gn 50
30027876 A hn S 44.06 50
30028024 A in B 43.97 100
30030672 A jn S 44.16 100
30030975 A kn S 44.15 100
30030975 R jn 100
30045029 R hn 50
30045116 A ln S 44.15 100
30045116 R kn 100
30052384 R ln 100
30052414 A mn S 44.15 100
30052945 A nn B 43.98 100
30052945 R in 100
30060644 R nn 100
30060674 A on B 43.97 100
30060845 A pn S 44.15 100
30060845 R mn 100
30062333 A qn B 44.05 100
30063555 A rn B 43.98 100
30063555 R on 100
30074752 R cn 100
30074758 A sn S 44.08 100
30077822 R qn 100
30079135 A tn B 43.98 100
30079135 R rn 100
30081154 R tn 100
30081184 A un B 43.97 100
30081305 A vn B 43.98 100
30081306 R un 100
30086992 A wn B 44.06 100
30088196 A xn B 43.98 100
30088196 R vn 100
30088435 R sn 100
30088549 R wn 100
30088584 R xn 100
30088614 A yn B 43.97 100
30146355 A zn B 44.01 100
30146355 R yn 100
30148205 R zn 100
30148235 A ao B 43.97 100
30148885 A bo B 43.98 100
30148885 R ao 100
30150685 R bo 100
30150714 A co B 43.97 100
30154487 A do S 44.07 50
30156052 R do 50
30163115 A eo B 43.99 100
30163115 R co 100
30165315 A fo B 43.99 100
30165315 R eo 100
30171175 A go B 43.99 100
30171175 R fo 100
30186345 A ho B 43.99 100
30186345 R go 100
30187354 R ho 100
30187384 A io B 43.99 100
30187856 A jo B 44.04 100
30193146 A ko B 43.99 100
30193146 R io 100
30219505 R ko 100
30219534 A lo B 43.99 100
30220886 A mo B 43.99 100
30220886 R lo 100
30226196 A no B 43.99 100
30226196 R mo 100
30244365 A oo B 44.06 25
30246242 R fn 200
30246301 A po B 44.06 200
30248135 R pn 100
30248165 A qo S 44.16 100
30248925 R no 100
30248955 A ro B 43.99 100
30268785 R qo 100
30268814 A so S 44.17 100
30269005 A to B 44.02 100
30269005 R ro 100
30275405 R so 100
30275435 A uo S 44.18 100
30282645 A vo S 44.17 100
30282645 R uo 100
30286325 R vo 100
30286355 A wo S 44.18 100
30294998 A xo B 43.80 50
30299174 A yo S 44.13 100
30309855 A zo B 44.03 100
30309855 R to 100
30311623 R dn 100
30326474 R wo 100
30326504 A ap S 44.22 100
30326525 A bp S 44.20 100
30326525 R ap 100
30326525 R bp 100
30326582 A cp S 44.22 100
30327852 R ik 33
30336205 A dp S 44.21 100
30336205 R cp 100
30339174 R dp 100
30339204 A ep S 44.22 100
30342296 A fp S 44.20 100
30342296 R ep 100
30344079 R yo 100
30346445 R fp 100
30346475 A gp S 44.21 100
30349823 R vj 150
30356595 A hp S 44.21 100
30356595 R gp 100
30359374 A ip B 44.10 1200
30360647 A jp B 44.10 100
30361623 A kp B 44.10 100
30361906 A lp S 44.20 100
30361906 R hp 100
30365915 R xg 60
30365955 R lp 100
30365985 A mp S 44.21 100
30366891 R jp 100
30366925 R mp 100
30366955 A np S 44.21 100
30367966 R kp 100
30368861 A op B 44.10 100
30368925 A pp B 44.03 100
30368925 R zo 100
30373365 A qp S 44.20 100
30373366 R np 100
30376561 R op 100
30376595 R pp 100
30376595 R qp 100
30376624 A rp B 44.03 100
30376625 A sp S 44.21 100
30377455 A tp B 44.03 100
30377455 R rp 100
30377705 A up S 44.20 100
30377706 R sp 100
30378195 R up 100
30378225 A vp S 44.21 100
30378836 R ip 1200
30378895 A wp S 44.20 100
30378895 R vp 100
30379865 A xp B 44.03 100
30379866 R tp 100
30380625 R wp 100
30380655 A yp S 44.21 100
30381854 R xp 100
30381884 A zp B 44.03 100
30382630 A aq S 45.60 600
30382655 A bq S 44.20 100
30382655 R yp 100
30383391 A cq S 44.13 100
30384350 A dq B 44.10 1200
30385024 R bq 100
30385054 A eq S 44.21 100
30385435 A fq B 44.03 100
30385435 A gq B 44.11 100
30385435 R zp 100
30385475 R fq 100
30385505 A hq B 44.03 100
30385545 A iq B 44.04 100
30385545 R hq 100
30385855 R gq 100
30385924 R iq 100
30385954 A jq B 44.03 100
30386785 R z 100
30386785 R fl 75
30386785 R cq 100
30386787 A kq S 44.13 100
30387006 R kq 100
30387008 A lq S 44.13 100
30387287 R lq 100
30388925 R eq 100
30388954 A mq S 44.27 100
30389565 A nq B 44.07 100
30389566 R jq 100
30391325 R nb 500
30391516 A oq B 44.09 100
30391516 R nq 100
30392095 A pq S 44.26 100
30392096 R mq 100
30394495 R oq 100
30394525 A qq B 44.03 100
30395687 A rq S 44.16 100
30398156 A sq B 44.04 100
30398156 R qq 100
30399215 A tq S 44.23 100
30399216 R pq 100
30402678 A uq B 44.10 100
30407006 R uq 100
30407008 A vq B 44.10 200
30407035 A wq B 44.04 100
30407035 R sq 100
30409575 R tq 100
30409605 A xq S 44.26 100
30411436 R vq 200
30411438 A yq B 44.12 300
30411465 A zq B 44.05 100
30411465 R wq 100
30412337 R yq 300
30412365 A ar B 44.07 100
30412366 R zq 100
30414054 A br B 44.14 400
30419350 R rq 100
30419375 A cr B 44.09 100
30419375 R ar 100
30419385 A dr S 44.19 100
30419505 R cr 100
30419534 A er B 44.07 100
30419635 A fr B 44.09 100
30419636 R er 100
30419672 A gr B 44.14 100
30420067 R dr 100
30420085 R xq 100
30420114 A hr S 44.27 100
30422845 R br 400
30426753 R gr 100
30426759 A ir S 44.35 4000
30428287 A jr S 44.22 100
30431804 A kr S 44.20 100
30433666 A lr S 44.20 100
30441489 R kr 100
30444979 A mr S 44.20 100
30445434 A nr B 43.20 50
30448870 A or B 44.09 100
30450760 R mr 100
30451439 A pr S 44.20 100
30451455 A qr S 44.27 100
30451455 R hr 100
30452055 A rr S 44.24 700
30455329 A sr S 44.22 100
30465393 R sr 100
30465526 A tr B 44.17 400
30467426 R pr 100
30467455 R qr 100
30467485 A ur S 44.27 100
30472026 A vr B 44.17 100
30475557 R vr 100
30484429 A wr S 44.19 100
30491596 A xr B 44.11 100
30491596 R fr 100
30491597 R wr 100
30499620 R jr 100
30501815 R tr 400
30501836 R dq 1200
30501837 A yr S 44.19 100
30501866 R xr 100
30501866 A zr S 44.26 100
30501866 R ur 100
30501895 A as B 44.09 100
30502116 R yr 100
30502145 R zr 100
30502176 A bs S 44.27 100
30505956 R aq 600
30505962 A cs S 45.60 600
30506308 A ds S 44.23 100
30509828 A es B 44.13 100
30509978 A fs B 44.16 100
30513385 R bs 100
30513415 A gs S 44.35 100
30513962 R lr 100
30514675 A hs B 44.19 100
30514677 R fs 100
30519385 A is S 44.27 100
30519386 R gs 100
30520807 R hs 100
30520809 A js B 44.16 100
30521515 R js 100
30523872 R oo 25
30525567 A ks B 44.16 100
30529205 A ls S 44.27 100
30529206 R is 100
30529935 R ls 100
30529964 A ms S 44.27 100
30530685 A ns S 44.27 100
30530685 R ms 100
30530704 R ns 100
30530741 A os S 44.27 100
30531906 R ks 100
30531909 A ps B 44.16 100
30531935 A qs B 44.10 100
30531935 R as 100
30532705 A rs B 44.16 200
30536935 R um 50
30537145 A ss S 44.27 100
30537146 R os 100
30537165 R ss 100
30537194 A ts S 44.27 100
30541262 R ds 100
30547835 R ts 100
30547865 A us S 44.35 100
30547875 R us 100
30547904 A vs S 44.35 100
30550646 R ps 100
30550675 A ws B 44.12 100
30550676 R qs 100
30552477 R cj 100
30552545 R vs 100
30552574 A xs S 44.35 100
30554665 R ws 100
30554695 A ys B 44.09 100
30554714 R ys 100
30554744 A zs B 44.09 100
30555095 A at S 44.28 100
30557195 A bt S 44.30 100
30557196 R xs 100
30558137 A ct S 44.24 100
30558592 A dt B 44.17 200
30559055 A et B 44.09 100
30559055 R zs 100
30559397 R et 100
30559845 R bt 100
30565980 R dt 200
30565982 A ft B 44.16 100
30566336 R ft 100
30568785 A gt B 44.17 200
30571107 A ht S 44.27 200
30571226 A it S 44.23 100
30571380 R ct 100
30571380 A jt S 44.23 100
30572105 A kt S 44.23 100
30572276 A lt B 44.17 1100
30574859 R lt 1100
30577797 R it 100
30577798 R kt 100
30578103 A mt S 44.23 100
30578244 R jt 100
30589788 A nt S 44.22 100
30592194 A ot B 44.18 1100
30597834 A pt S 44.22 200
30598481 R mt 100
30603241 A qt B 44.18 100
30603447 R qt 100
30614305 A rt B 44.19 100
30615238 R rt 100
30630340 A st S 44.22 100
30630350 R st 100
30639640 A tt S 44.22 100
30639658 R tt 100
30659102 A ut B 44.18 100
